Workbook

Sheet (FA) IQ
A1: Custody Acc # | B1: Account | C1: AD | D1: Total Cash USD | E1: Foreign Currency | F1: SWEEP | G1: Collateral & MD | H1: Variation Margin | I1: Unrl Loss On FFX | J1: TR Swaps Sheet | K1: Net Cash | L1: Equity MV | M1: Market Value | N1: Percent Cash | O1: 15% Illiquidity Test | Q1: SWAP WEIGHT | S1: % Custody Cash (USD) | T1: % Custody Cash (CCY) | V1: ='(Custody) IQ'!I1 | Y1: ='(Custody) IQ'!L1
A2: 139473 | B2: IQSI | C2: NYLI Candriam International Equity ETF | D2: =VLOOKUP(A2,'BNY FA Cash'!$C$27:$Y$1048576,23,0) | E2: =VLOOKUP(A2,'BNY FA Cash'!$C$27:$F$634,4,0) | F2: =VLOOKUP(A2,'BNY FA Cash'!$C$27:$H$1048576,6,0) | G2: =VLOOKUP(A2,'BNY FA Cash'!$C$27:$I$1048576,7,0) | H2: =VLOOKUP(A2,'BNY FA Cash'!$C$27:$J$1048576,8,0) | I2: =VLOOKUP(A2,'BNY FA Cash'!$C$27:$N$1048576,12,0)+VLOOKUP(A2,'BNY FA Cash'!$C$27:$T$1048576,18,0) | J2: =VLOOKUP(A2,'BNY FA Cash'!$C$27:$AA$1048576,25,0) | K2: =SUM(D2:J2) | L2: =M2-K2 | M2: =VLOOKUP(A2,'BNY FA Cash'!$C$27:$Z$1048576,24,0) | N2: =K2/M2 | O2: =ABS(J2)/M2 | S2: ='(Custody) IQ'!F2 | T2: ='(Custody) IQ'!G2 | V2: ='(Custody) IQ'!I2 | W2: ='(Custody) IQ'!J2 | X2: ='(Custody) IQ'!K2 | Y2: ='(Custody) IQ'!L2 | Z2: ='(Custody) IQ'!M2
A3: 139522 | B3: IQSU | C3: NYLI Candriam U.S. Large Cap Equity ETF | D3: =VLOOKUP(A3,'BNY FA Cash'!$C$27:$Y$1048576,23,0) | E3: =VLOOKUP(A3,'BNY FA Cash'!$C$27:$F$634,4,0) | F3: =VLOOKUP(A3,'BNY FA Cash'!$C$27:$H$1048576,6,0) | G3: =VLOOKUP(A3,'BNY FA Cash'!$C$27:$I$1048576,7,0) | H3: =VLOOKUP(A3,'BNY FA Cash'!$C$27:$J$1048576,8,0) | I3: =VLOOKUP(A3,'BNY FA Cash'!$C$27:$N$1048576,12,0)+VLOOKUP(A3,'BNY FA Cash'!$C$27:$T$1048576,18,0) | J3: =VLOOKUP(A3,'BNY FA Cash'!$C$27:$AA$1048576,25,0) | K3: =SUM(D3:J3) | L3: =M3-K3 | M3: =VLOOKUP(A3,'BNY FA Cash'!$C$27:$Z$1048576,24,0) | N3: =K3/M3 | O3: =ABS(J3)/M3 | S3: ='(Custody) IQ'!F3 | T3: ='(Custody) IQ'!G3 | V3: ='(Custody) IQ'!I3 | W3: ='(Custody) IQ'!J3 | Z3: ='(Custody) IQ'!M3
A4: 156481 | B4: HART | C4: NYLI Healthy Hearts ETF | D4: =VLOOKUP(A4,'BNY FA Cash'!$C$27:$Y$1048576,23,0) | E4: =VLOOKUP(A4,'BNY FA Cash'!$C$27:$F$634,4,0) | F4: =VLOOKUP(A4,'BNY FA Cash'!$C$27:$H$1048576,6,0) | G4: =VLOOKUP(A4,'BNY FA Cash'!$C$27:$I$1048576,7,0) | H4: =VLOOKUP(A4,'BNY FA Cash'!$C$27:$J$1048576,8,0) | I4: =VLOOKUP(A4,'BNY FA Cash'!$C$27:$N$1048576,12,0)+VLOOKUP(A4,'BNY FA Cash'!$C$27:$T$1048576,18,0) | J4: =VLOOKUP(A4,'BNY FA Cash'!$C$27:$AA$1048576,25,0) | K4: =SUM(D4:J4) | L4: =M4-K4 | M4: =VLOOKUP(A4,'BNY FA Cash'!$C$27:$Z$1048576,24,0) | N4: =K4/M4 | O4: =ABS(J4)/M4 | S4: ='(Custody) IQ'!F4 | T4: ='(Custody) IQ'!G4 | V4: ='(Custody) IQ'!I4 | W4: ='(Custody) IQ'!J4 | X4: ='(Custody) IQ'!K4 | Y4: ='(Custody) IQ'!L4 | Z4: ='(Custody) IQ'!M4
A5: 212156 | B5: MNA | C5: NYLI Merger Arbitrage ETF | D5: =VLOOKUP(A5,'BNY FA Cash'!$C$27:$Y$1048576,23,0) | E5: =VLOOKUP(A5,'BNY FA Cash'!$C$27:$F$634,4,0) | F5: =VLOOKUP(A5,'BNY FA Cash'!$C$27:$H$1048576,6,0) | G5: =VLOOKUP(A5,'BNY FA Cash'!$C$27:$I$1048576,7,0) | H5: =VLOOKUP(A5,'BNY FA Cash'!$C$27:$J$1048576,8,0) | I5: =VLOOKUP(A5,'BNY FA Cash'!$C$27:$N$1048576,12,0)+VLOOKUP(A5,'BNY FA Cash'!$C$27:$T$1048576,18,0) | J5: =VLOOKUP(A5,'BNY FA Cash'!$C$27:$AA$1048576,25,0) | K5: =SUM(D5:J5) | L5: =M5-K5 | M5: =VLOOKUP(A5,'BNY FA Cash'!$C$27:$Z$1048576,24,0) | N5: =K5/M5 | O5: =ABS(J5)/M5 | S5: ='(Custody) IQ'!F5 | T5: ='(Custody) IQ'!G5 | V5: ='(Custody) IQ'!I5 | W5: ='(Custody) IQ'!J5 | X5: ='(Custody) IQ'!K5 | Y5: ='(Custody) IQ'!L5 | Z5: ='(Custody) IQ'!M5
A6: 222959 | B6: LRND | C6: NYLI U.S. Large Cap R&D Leaders ETF | D6: =VLOOKUP(A6,'BNY FA Cash'!$C$27:$Y$1048576,23,0) | E6: =VLOOKUP(A6,'BNY FA Cash'!$C$27:$F$634,4,0) | F6: =VLOOKUP(A6,'BNY FA Cash'!$C$27:$H$1048576,6,0) | G6: =VLOOKUP(A6,'BNY FA Cash'!$C$27:$I$1048576,7,0) | H6: =VLOOKUP(A6,'BNY FA Cash'!$C$27:$J$1048576,8,0) | I6: =VLOOKUP(A6,'BNY FA Cash'!$C$27:$N$1048576,12,0)+VLOOKUP(A6,'BNY FA Cash'!$C$27:$T$1048576,18,0) | J6: =VLOOKUP(A6,'BNY FA Cash'!$C$27:$AA$1048576,25,0) | K6: =SUM(D6:J6) | L6: =M6-K6 | M6: =VLOOKUP(A6,'BNY FA Cash'!$C$27:$Z$1048576,24,0) | N6: =K6/M6 | O6: =ABS(J6)/M6 | S6: ='(Custody) IQ'!F6 | T6: ='(Custody) IQ'!G6 | V6: ='(Custody) IQ'!I6 | W6: ='(Custody) IQ'!J6 | Z6: ='(Custody) IQ'!M6
A7: 222963 | B7: WRND | C7: NYLI Global Equity R&D Leaders ETF | D7: =VLOOKUP(A7,'BNY FA Cash'!$C$27:$Y$1048576,23,0) | E7: =VLOOKUP(A7,'BNY FA Cash'!$C$27:$F$634,4,0) | F7: =VLOOKUP(A7,'BNY FA Cash'!$C$27:$H$1048576,6,0) | G7: =VLOOKUP(A7,'BNY FA Cash'!$C$27:$I$1048576,7,0) | H7: =VLOOKUP(A7,'BNY FA Cash'!$C$27:$J$1048576,8,0) | I7: =VLOOKUP(A7,'BNY FA Cash'!$C$27:$N$1048576,12,0)+VLOOKUP(A7,'BNY FA Cash'!$C$27:$T$1048576,18,0) | J7: =VLOOKUP(A7,'BNY FA Cash'!$C$27:$AA$1048576,25,0) | K7: =SUM(D7:J7) | L7: =M7-K7 | M7: =VLOOKUP(A7,'BNY FA Cash'!$C$27:$Z$1048576,24,0) | N7: =K7/M7 | O7: =ABS(J7)/M7 | S7: ='(Custody) IQ'!F7 | T7: ='(Custody) IQ'!G7 | V7: ='(Custody) IQ'!I7 | W7: ='(Custody) IQ'!J7 | X7: ='(Custody) IQ'!K7 | Y7: ='(Custody) IQ'!L7 | Z7: ='(Custody) IQ'!M7
A8: 240413 | B8: IQSM | C8: NYLI Candriam U.S. Mid Cap Equity ETF | D8: =VLOOKUP(A8,'BNY FA Cash'!$C$27:$Y$1048576,23,0) | E8: =VLOOKUP(A8,'BNY FA Cash'!$C$27:$F$634,4,0) | F8: =VLOOKUP(A8,'BNY FA Cash'!$C$27:$H$1048576,6,0) | G8: =VLOOKUP(A8,'BNY FA Cash'!$C$27:$I$1048576,7,0) | H8: =VLOOKUP(A8,'BNY FA Cash'!$C$27:$J$1048576,8,0) | I8: =VLOOKUP(A8,'BNY FA Cash'!$C$27:$N$1048576,12,0)+VLOOKUP(A8,'BNY FA Cash'!$C$27:$T$1048576,18,0) | J8: =VLOOKUP(A8,'BNY FA Cash'!$C$27:$AA$1048576,25,0) | K8: =SUM(D8:J8) | L8: =M8-K8 | M8: =VLOOKUP(A8,'BNY FA Cash'!$C$27:$Z$1048576,24,0) | N8: =K8/M8 | O8: =ABS(J8)/M8 | S8: ='(Custody) IQ'!F8 | T8: ='(Custody) IQ'!G8 | V8: ='(Custody) IQ'!I8 | W8: ='(Custody) IQ'!J8 | Z8: ='(Custody) IQ'!M8
A9: 263076 | B9: QAI | C9: NYLI Hedge Multi-Strategy Tracker ETF | D9: =VLOOKUP(A9,'BNY FA Cash'!$C$27:$Y$1048576,23,0) | E9: =VLOOKUP(A9,'BNY FA Cash'!$C$27:$F$634,4,0) | F9: =VLOOKUP(A9,'BNY FA Cash'!$C$27:$H$1048576,6,0) | G9: =VLOOKUP(A9,'BNY FA Cash'!$C$27:$I$1048576,7,0) | H9: =VLOOKUP(A9,'BNY FA Cash'!$C$27:$J$1048576,8,0) | I9: =VLOOKUP(A9,'BNY FA Cash'!$C$27:$N$1048576,12,0)+VLOOKUP(A9,'BNY FA Cash'!$C$27:$T$1048576,18,0) | J9: =VLOOKUP(A9,'BNY FA Cash'!$C$27:$AA$1048576,25,0) | K9: =SUM(D9:J9) | L9: =M9-K9 | M9: =VLOOKUP(A9,'BNY FA Cash'!$C$27:$Z$1048576,24,0) | N9: =K9/M9 | O9: =ABS(J9)/M9 | S9: ='(Custody) IQ'!F9 | T9: ='(Custody) IQ'!G9 | V9: ='(Custody) IQ'!I9 | W9: ='(Custody) IQ'!J9 | Z9: ='(Custody) IQ'!M9
A10: 447594 | B10: HFXI | C10: NYLI FTSE International Equity Currency Neutral ETF | D10: =VLOOKUP(A10,'BNY FA Cash'!$C$27:$Y$1048576,23,0) | E10: =VLOOKUP(A10,'BNY FA Cash'!$C$27:$F$634,4,0) | F10: =VLOOKUP(A10,'BNY FA Cash'!$C$27:$H$1048576,6,0) | G10: =VLOOKUP(A10,'BNY FA Cash'!$C$27:$I$1048576,7,0) | H10: =VLOOKUP(A10,'BNY FA Cash'!$C$27:$J$1048576,8,0) | I10: =VLOOKUP(A10,'BNY FA Cash'!$C$27:$AD$54,28,0) | J10: =VLOOKUP(A10,'BNY FA Cash'!$C$27:$AA$1048576,25,0) | K10: =SUM(D10:J10) | L10: =M10-K10 | M10: =VLOOKUP(A10,'BNY FA Cash'!$C$27:$Z$1048576,24,0) | N10: =K10/M10 | O10: =ABS(J10)/M10 | S10: ='(Custody) IQ'!F10 | T10: ='(Custody) IQ'!G10 | V10: ='(Custody) IQ'!I10 | W10: ='(Custody) IQ'!J10 | X10: ='(Custody) IQ'!K10 | Y10: ='(Custody) IQ'!L10 | Z10: ='(Custody) IQ'!M10
A11: G 26785 | B11: VP Mutual Fund | C11: NYLI VP Hedge Multi-Strategy Portfolio | D11: =M11-L11-J11-F11 | E11: 0 | F11: =IFERROR(VLOOKUP("CASH EQUIVALENTS-SHORT-TERM INVEST FUNDS",'VP FA Holdings'!G:U,15,0),0) | G11: =SUMIFS('VP FA Holdings'!K:K,'VP FA Holdings'!C:C,"ITX1",'VP FA Holdings'!F:F,"US DOLLAR") | H11: 0 | I11: 0 | J11: =SUMIF('VP FA Holdings'!G:G,"DERIVATIVES-OTC EXPOSURE",'VP FA Holdings'!V:V) | K11: =SUM(D11:J11) | L11: =SUMIF('VP FA Holdings'!G:G,"INVESTMENT COMPANIES-EXCHANGE TRADED FUN",'VP FA Holdings'!U:U) | M11: =SUM('VP FA Holdings'!AG:AG) | N11: =K11/M11 | O11: =ABS(J11)/M11
C14: symbol | D14: portCd | E14: custCd | F14: position | G14: shares | H14: localGrossCost | I14: localSodprice | J14: strategy1 | K14: strategy2
C15: LOOKFWD_CASH | D15: MNA | E15: Index | F15: 1 | G15: =VLOOKUP(D15,$B$1:$K$11,10,0)+E23 | H15: 1 | I15: 1
C16: LOOKFWD_CASH | D16: QAI | E16: Index | F16: 1 | G16: =VLOOKUP(D16,$B$1:$K$13,10,0)+E24 | H16: 1 | I16: 1
C17: LOOKFWD_CASH | D17: HFXI | E17: Index | F17: 1 | G17: =VLOOKUP(D17,$B$1:$K$13,10,0)+E21 | H17: 1 | I17: 1
D19: HFXI P&L
D20: HFXI TRADES
E21: =SUM(E19:E20)
D23: MNA TRADES
D24: QAI TRADES

Sheet (Custody) IQ
A1: Custody Acc # | B1: Account | C1: AD | D1: USD Cash | E1: Foreign CCY Cash | F1: % Custody Cash (USD) | G1: % Custody Cash (CCY) | I1: Largest Local Balances (USD) | L1: Smallest Local Balances (USD)
A2: 139473 | B2: IQSI | C2: NYLI Candriam International Equity ETF | D2: =SUMIFS('BNY Daily Settled Cash Balance'!F:F,'BNY Daily Settled Cash Balance'!A:A,'(Custody) IQ'!A2,'BNY Daily Settled Cash Balance'!C:C,"USD") | E2: =SUMIFS('BNY Daily Settled Cash Balance'!F:F,'BNY Daily Settled Cash Balance'!A:A,'(Custody) IQ'!A2,'BNY Daily Settled Cash Balance'!C:C,"<>USD") | F2: =D2/'(FA) IQ'!M2 | G2: =E2/'(FA) IQ'!M2 | I2: =_xlfn.MAXIFS('BNY Daily Settled Cash Balance'!F:F, 'BNY Daily Settled Cash Balance'!A:A, '(Custody) IQ'!A2, 'BNY Daily Settled Cash Balance'!C:C, "<>USD") | J2: =I2/VLOOKUP(A2,'(FA) IQ'!$A$2:$M$11,13,0) | K2: {=INDEX( _xlfn._xlws.FILTER('BNY Daily Settled Cash Balance'!C:C, ('BNY Daily Settled Cash Balance'!A:A='(Custody) IQ'!A2) * ('BNY Daily Settled Cash Balance'!C:C<>"USD")), MATCH( _xlfn.MAXIFS('BNY Daily Settled Cash Balance'!F:F, 'BNY Daily Settled Cash Balance'!A:A, '(Custody) IQ'!A2, 'BNY Daily Settled Cash Balance'!C:C, "<>USD"), _xlfn._xlws.FILTER('BNY Daily Settled Cash Balance'!F:F, ('BNY Daily Settled Cash Balance'!A:A='(Custody) IQ'!A2) * ('BNY Daily Settled Cash Balance'!C:C<>"USD")), 0) )} | L2: =_xlfn.MINIFS('BNY Daily Settled Cash Balance'!F:F, 'BNY Daily Settled Cash Balance'!A:A, '(Custody) IQ'!A2, 'BNY Daily Settled Cash Balance'!C:C, "<>USD") | M2: =L2/VLOOKUP(A2,'(FA) IQ'!$A$2:$M$11,13,0) | N2: {=INDEX( _xlfn._xlws.FILTER('BNY Daily Settled Cash Balance'!C:C, ('BNY Daily Settled Cash Balance'!A:A='(Custody) IQ'!A2) * ('BNY Daily Settled Cash Balance'!C:C<>"USD")), MATCH( _xlfn.MINIFS('BNY Daily Settled Cash Balance'!F:F, 'BNY Daily Settled Cash Balance'!A:A, '(Custody) IQ'!A2, 'BNY Daily Settled Cash Balance'!C:C, "<>USD"), _xlfn._xlws.FILTER('BNY Daily Settled Cash Balance'!F:F, ('BNY Daily Settled Cash Balance'!A:A='(Custody) IQ'!A2) * ('BNY Daily Settled Cash Balance'!C:C<>"USD")), 0) )}
A3: 139522 | B3: IQSU | C3: NYLI Candriam U.S. Large Cap Equity ETF | D3: =SUMIFS('BNY Daily Settled Cash Balance'!F:F,'BNY Daily Settled Cash Balance'!A:A,'(Custody) IQ'!A3,'BNY Daily Settled Cash Balance'!C:C,"USD") | E3: =SUMIFS('BNY Daily Settled Cash Balance'!F:F,'BNY Daily Settled Cash Balance'!A:A,'(Custody) IQ'!A3,'BNY Daily Settled Cash Balance'!C:C,"<>USD") | F3: =D3/'(FA) IQ'!M3 | G3: =E3/'(FA) IQ'!M3
A4: 156481 | B4: HART | C4: NYLI Healthy Hearts ETF | D4: =SUMIFS('BNY Daily Settled Cash Balance'!F:F,'BNY Daily Settled Cash Balance'!A:A,'(Custody) IQ'!A4,'BNY Daily Settled Cash Balance'!C:C,"USD") | E4: =SUMIFS('BNY Daily Settled Cash Balance'!F:F,'BNY Daily Settled Cash Balance'!A:A,'(Custody) IQ'!A4,'BNY Daily Settled Cash Balance'!C:C,"<>USD") | F4: =D4/'(FA) IQ'!M4 | G4: =E4/'(FA) IQ'!M4 | I4: =_xlfn.MAXIFS('BNY Daily Settled Cash Balance'!F:F, 'BNY Daily Settled Cash Balance'!A:A, '(Custody) IQ'!A4, 'BNY Daily Settled Cash Balance'!C:C, "<>USD") | J4: =I4/VLOOKUP(A4,'(FA) IQ'!$A$2:$M$11,13,0) | K4: {=INDEX( _xlfn._xlws.FILTER('BNY Daily Settled Cash Balance'!C:C, ('BNY Daily Settled Cash Balance'!A:A='(Custody) IQ'!A4) * ('BNY Daily Settled Cash Balance'!C:C<>"USD")), MATCH( _xlfn.MAXIFS('BNY Daily Settled Cash Balance'!F:F, 'BNY Daily Settled Cash Balance'!A:A, '(Custody) IQ'!A4, 'BNY Daily Settled Cash Balance'!C:C, "<>USD"), _xlfn._xlws.FILTER('BNY Daily Settled Cash Balance'!F:F, ('BNY Daily Settled Cash Balance'!A:A='(Custody) IQ'!A4) * ('BNY Daily Settled Cash Balance'!C:C<>"USD")), 0) )} | L4: =_xlfn.MINIFS('BNY Daily Settled Cash Balance'!F:F, 'BNY Daily Settled Cash Balance'!A:A, '(Custody) IQ'!A4, 'BNY Daily Settled Cash Balance'!C:C, "<>USD") | M4: =L4/VLOOKUP(A4,'(FA) IQ'!$A$2:$M$11,13,0) | N4: {=INDEX( _xlfn._xlws.FILTER('BNY Daily Settled Cash Balance'!C:C, ('BNY Daily Settled Cash Balance'!A:A='(Custody) IQ'!A4) * ('BNY Daily Settled Cash Balance'!C:C<>"USD")), MATCH( _xlfn.MINIFS('BNY Daily Settled Cash Balance'!F:F, 'BNY Daily Settled Cash Balance'!A:A, '(Custody) IQ'!A4, 'BNY Daily Settled Cash Balance'!C:C, "<>USD"), _xlfn._xlws.FILTER('BNY Daily Settled Cash Balance'!F:F, ('BNY Daily Settled Cash Balance'!A:A='(Custody) IQ'!A4) * ('BNY Daily Settled Cash Balance'!C:C<>"USD")), 0) )}
A5: 212156 | B5: MNA | C5: NYLI Merger Arbitrage ETF | D5: =SUMIFS('BNY Daily Settled Cash Balance'!F:F,'BNY Daily Settled Cash Balance'!A:A,'(Custody) IQ'!A5,'BNY Daily Settled Cash Balance'!C:C,"USD") | E5: =SUMIFS('BNY Daily Settled Cash Balance'!F:F,'BNY Daily Settled Cash Balance'!A:A,'(Custody) IQ'!A5,'BNY Daily Settled Cash Balance'!C:C,"<>USD") | F5: =D5/'(FA) IQ'!M5 | G5: =E5/'(FA) IQ'!M5 | I5: =_xlfn.MAXIFS('BNY Daily Settled Cash Balance'!F:F, 'BNY Daily Settled Cash Balance'!A:A, '(Custody) IQ'!A5, 'BNY Daily Settled Cash Balance'!C:C, "<>USD") | J5: =I5/VLOOKUP(A5,'(FA) IQ'!$A$2:$M$11,13,0) | K5: {=INDEX( _xlfn._xlws.FILTER('BNY Daily Settled Cash Balance'!C:C, ('BNY Daily Settled Cash Balance'!A:A='(Custody) IQ'!A5) * ('BNY Daily Settled Cash Balance'!C:C<>"USD")), MATCH( _xlfn.MAXIFS('BNY Daily Settled Cash Balance'!F:F, 'BNY Daily Settled Cash Balance'!A:A, '(Custody) IQ'!A5, 'BNY Daily Settled Cash Balance'!C:C, "<>USD"), _xlfn._xlws.FILTER('BNY Daily Settled Cash Balance'!F:F, ('BNY Daily Settled Cash Balance'!A:A='(Custody) IQ'!A5) * ('BNY Daily Settled Cash Balance'!C:C<>"USD")), 0) )} | L5: =_xlfn.MINIFS('BNY Daily Settled Cash Balance'!F:F, 'BNY Daily Settled Cash Balance'!A:A, '(Custody) IQ'!A5, 'BNY Daily Settled Cash Balance'!C:C, "<>USD") | M5: =L5/VLOOKUP(A5,'(FA) IQ'!$A$2:$M$11,13,0) | N5: {=INDEX( _xlfn._xlws.FILTER('BNY Daily Settled Cash Balance'!C:C, ('BNY Daily Settled Cash Balance'!A:A='(Custody) IQ'!A5) * ('BNY Daily Settled Cash Balance'!C:C<>"USD")), MATCH( _xlfn.MINIFS('BNY Daily Settled Cash Balance'!F:F, 'BNY Daily Settled Cash Balance'!A:A, '(Custody) IQ'!A5, 'BNY Daily Settled Cash Balance'!C:C, "<>USD"), _xlfn._xlws.FILTER('BNY Daily Settled Cash Balance'!F:F, ('BNY Daily Settled Cash Balance'!A:A='(Custody) IQ'!A5) * ('BNY Daily Settled Cash Balance'!C:C<>"USD")), 0) )}
A6: 222959 | B6: LRND | C6: NYLI U.S. Large Cap R&D Leaders ETF | D6: =SUMIFS('BNY Daily Settled Cash Balance'!F:F,'BNY Daily Settled Cash Balance'!A:A,'(Custody) IQ'!A6,'BNY Daily Settled Cash Balance'!C:C,"USD") | E6: =SUMIFS('BNY Daily Settled Cash Balance'!F:F,'BNY Daily Settled Cash Balance'!A:A,'(Custody) IQ'!A6,'BNY Daily Settled Cash Balance'!C:C,"<>USD") | F6: =D6/'(FA) IQ'!M6 | G6: =E6/'(FA) IQ'!M6
A7: 222963 | B7: WRND | C7: NYLI Global Equity R&D Leaders ETF | D7: =SUMIFS('BNY Daily Settled Cash Balance'!F:F,'BNY Daily Settled Cash Balance'!A:A,'(Custody) IQ'!A7,'BNY Daily Settled Cash Balance'!C:C,"USD") | E7: =SUMIFS('BNY Daily Settled Cash Balance'!F:F,'BNY Daily Settled Cash Balance'!A:A,'(Custody) IQ'!A7,'BNY Daily Settled Cash Balance'!C:C,"<>USD") | F7: =D7/'(FA) IQ'!M7 | G7: =E7/'(FA) IQ'!M7 | I7: =_xlfn.MAXIFS('BNY Daily Settled Cash Balance'!F:F, 'BNY Daily Settled Cash Balance'!A:A, '(Custody) IQ'!A7, 'BNY Daily Settled Cash Balance'!C:C, "<>USD") | J7: =I7/VLOOKUP(A7,'(FA) IQ'!$A$2:$M$11,13,0) | K7: {=INDEX( _xlfn._xlws.FILTER('BNY Daily Settled Cash Balance'!C:C, ('BNY Daily Settled Cash Balance'!A:A='(Custody) IQ'!A7) * ('BNY Daily Settled Cash Balance'!C:C<>"USD")), MATCH( _xlfn.MAXIFS('BNY Daily Settled Cash Balance'!F:F, 'BNY Daily Settled Cash Balance'!A:A, '(Custody) IQ'!A7, 'BNY Daily Settled Cash Balance'!C:C, "<>USD"), _xlfn._xlws.FILTER('BNY Daily Settled Cash Balance'!F:F, ('BNY Daily Settled Cash Balance'!A:A='(Custody) IQ'!A7) * ('BNY Daily Settled Cash Balance'!C:C<>"USD")), 0) )} | L7: =_xlfn.MINIFS('BNY Daily Settled Cash Balance'!F:F, 'BNY Daily Settled Cash Balance'!A:A, '(Custody) IQ'!A7, 'BNY Daily Settled Cash Balance'!C:C, "<>USD") | M7: =L7/VLOOKUP(A7,'(FA) IQ'!$A$2:$M$11,13,0) | N7: {=INDEX( _xlfn._xlws.FILTER('BNY Daily Settled Cash Balance'!C:C, ('BNY Daily Settled Cash Balance'!A:A='(Custody) IQ'!A7) * ('BNY Daily Settled Cash Balance'!C:C<>"USD")), MATCH( _xlfn.MINIFS('BNY Daily Settled Cash Balance'!F:F, 'BNY Daily Settled Cash Balance'!A:A, '(Custody) IQ'!A7, 'BNY Daily Settled Cash Balance'!C:C, "<>USD"), _xlfn._xlws.FILTER('BNY Daily Settled Cash Balance'!F:F, ('BNY Daily Settled Cash Balance'!A:A='(Custody) IQ'!A7) * ('BNY Daily Settled Cash Balance'!C:C<>"USD")), 0) )}
A8: 240413 | B8: IQSM | C8: NYLI Candriam U.S. Mid Cap Equity ETF | D8: =SUMIFS('BNY Daily Settled Cash Balance'!F:F,'BNY Daily Settled Cash Balance'!A:A,'(Custody) IQ'!A8,'BNY Daily Settled Cash Balance'!C:C,"USD") | E8: =SUMIFS('BNY Daily Settled Cash Balance'!F:F,'BNY Daily Settled Cash Balance'!A:A,'(Custody) IQ'!A8,'BNY Daily Settled Cash Balance'!C:C,"<>USD") | F8: =D8/'(FA) IQ'!M8 | G8: =E8/'(FA) IQ'!M8
A9: 263076 | B9: QAI | C9: NYLI Hedge Multi-Strategy Tracker ETF | D9: =SUMIFS('BNY Daily Settled Cash Balance'!F:F,'BNY Daily Settled Cash Balance'!A:A,'(Custody) IQ'!A9,'BNY Daily Settled Cash Balance'!C:C,"USD") | E9: =SUMIFS('BNY Daily Settled Cash Balance'!F:F,'BNY Daily Settled Cash Balance'!A:A,'(Custody) IQ'!A9,'BNY Daily Settled Cash Balance'!C:C,"<>USD") | F9: =D9/'(FA) IQ'!M9 | G9: =E9/'(FA) IQ'!M9
A10: 447594 | B10: HFXI | C10: NYLI FTSE International Equity Currency Neutral ETF | D10: =SUMIFS('BNY Daily Settled Cash Balance'!F:F,'BNY Daily Settled Cash Balance'!A:A,'(Custody) IQ'!A10,'BNY Daily Settled Cash Balance'!C:C,"USD") | E10: =SUMIFS('BNY Daily Settled Cash Balance'!F:F,'BNY Daily Settled Cash Balance'!A:A,'(Custody) IQ'!A10,'BNY Daily Settled Cash Balance'!C:C,"<>USD") | F10: =D10/'(FA) IQ'!M10 | G10: =E10/'(FA) IQ'!M10 | I10: =_xlfn.MAXIFS('BNY Daily Settled Cash Balance'!F:F, 'BNY Daily Settled Cash Balance'!A:A, '(Custody) IQ'!A10, 'BNY Daily Settled Cash Balance'!C:C, "<>USD") | J10: =I10/VLOOKUP(A10,'(FA) IQ'!$A$2:$M$11,13,0) | K10: {=INDEX( _xlfn._xlws.FILTER('BNY Daily Settled Cash Balance'!C:C, ('BNY Daily Settled Cash Balance'!A:A='(Custody) IQ'!A10) * ('BNY Daily Settled Cash Balance'!C:C<>"USD")), MATCH( _xlfn.MAXIFS('BNY Daily Settled Cash Balance'!F:F, 'BNY Daily Settled Cash Balance'!A:A, '(Custody) IQ'!A10, 'BNY Daily Settled Cash Balance'!C:C, "<>USD"), _xlfn._xlws.FILTER('BNY Daily Settled Cash Balance'!F:F, ('BNY Daily Settled Cash Balance'!A:A='(Custody) IQ'!A10) * ('BNY Daily Settled Cash Balance'!C:C<>"USD")), 0) )} | L10: =_xlfn.MINIFS('BNY Daily Settled Cash Balance'!F:F, 'BNY Daily Settled Cash Balance'!A:A, '(Custody) IQ'!A10, 'BNY Daily Settled Cash Balance'!C:C, "<>USD") | M10: =L10/VLOOKUP(A10,'(FA) IQ'!$A$2:$M$11,13,0) | N10: {=INDEX( _xlfn._xlws.FILTER('BNY Daily Settled Cash Balance'!C:C, ('BNY Daily Settled Cash Balance'!A:A='(Custody) IQ'!A10) * ('BNY Daily Settled Cash Balance'!C:C<>"USD")), MATCH( _xlfn.MINIFS('BNY Daily Settled Cash Balance'!F:F, 'BNY Daily Settled Cash Balance'!A:A, '(Custody) IQ'!A10, 'BNY Daily Settled Cash Balance'!C:C, "<>USD"), _xlfn._xlws.FILTER('BNY Daily Settled Cash Balance'!F:F, ('BNY Daily Settled Cash Balance'!A:A='(Custody) IQ'!A10) * ('BNY Daily Settled Cash Balance'!C:C<>"USD")), 0) )}
D14: Overdraft $ | E14: =SUMIF(E2:E10, "<0") | L14: =SUMIF(L2:L10, "<0") | M14: Overdraft $
C15: OD Fee Annaul | D15: 0.05 | E15: =E14*D15 | L15: =L14*M15 | M15: 0.05 | N15: OD Fee Annaul
C16: OD Fee Daily | E16: =E15/365 | L16: =L15/365 | N16: OD Fee Daily

Sheet (FA - Income) IQ 
A1: Custody Acc # | B1: Account | C1: AD | D1: Accrued Income | E1: Reclaim Rec | G1: AUM | H1: AI % | I1: RC% | J1: Total | L1: FA CASH % | N1: FA CASH
A2: 139473 | B2: IQSI | C2: NYLI Candriam International Equity ETF | D2: =VLOOKUP(A2,'BNY FA Cash'!$C$27:$K$1048576,9,0) | E2: =VLOOKUP(A2,'BNY FA Cash'!$C$27:$O$1048576,13,0) | G2: =VLOOKUP(B2,'(FA) IQ'!$B$2:$M$11,12,0) | H2: =D2/G2 | I2: =E2/G2 | J2: =H2+I2 | L2: =N2/G2 | N2: {=SUM(VLOOKUP(B2, '(FA) IQ'!$B$2:$F$11, {3,4,5}, FALSE))}
A3: 139522 | B3: IQSU | C3: NYLI Candriam U.S. Large Cap Equity ETF | D3: =VLOOKUP(A3,'BNY FA Cash'!$C$27:$K$1048576,9,0) | E3: =VLOOKUP(A3,'BNY FA Cash'!$C$27:$O$1048576,13,0) | G3: =VLOOKUP(B3,'(FA) IQ'!$B$2:$M$11,12,0) | H3: =D3/G3 | I3: =E3/G3 | J3: =H3+I3 | L3: =N3/G3 | N3: {=SUM(VLOOKUP(B3, '(FA) IQ'!$B$2:$F$11, {3,4,5}, FALSE))}
A4: 156481 | B4: HART | C4: NYLI Healthy Hearts ETF | D4: =VLOOKUP(A4,'BNY FA Cash'!$C$27:$K$1048576,9,0) | E4: =VLOOKUP(A4,'BNY FA Cash'!$C$27:$O$1048576,13,0) | G4: =VLOOKUP(B4,'(FA) IQ'!$B$2:$M$11,12,0) | H4: =D4/G4 | I4: =E4/G4 | J4: =H4+I4 | L4: =N4/G4 | N4: {=SUM(VLOOKUP(B4, '(FA) IQ'!$B$2:$F$11, {3,4,5}, FALSE))}
A5: 212156 | B5: MNA | C5: NYLI Merger Arbitrage ETF | D5: =VLOOKUP(A5,'BNY FA Cash'!$C$27:$K$1048576,9,0) | E5: =VLOOKUP(A5,'BNY FA Cash'!$C$27:$O$1048576,13,0) | G5: =VLOOKUP(B5,'(FA) IQ'!$B$2:$M$11,12,0) | H5: =D5/G5 | I5: =E5/G5 | J5: =H5+I5 | L5: =N5/G5 | N5: {=SUM(VLOOKUP(B5, '(FA) IQ'!$B$2:$F$11, {3,4,5}, FALSE))}
A6: 222959 | B6: LRND | C6: NYLI U.S. Large Cap R&D Leaders ETF | D6: =VLOOKUP(A6,'BNY FA Cash'!$C$27:$K$1048576,9,0) | E6: =VLOOKUP(A6,'BNY FA Cash'!$C$27:$O$1048576,13,0) | G6: =VLOOKUP(B6,'(FA) IQ'!$B$2:$M$11,12,0) | H6: =D6/G6 | I6: =E6/G6 | J6: =H6+I6 | L6: =N6/G6 | N6: {=SUM(VLOOKUP(B6, '(FA) IQ'!$B$2:$F$11, {3,4,5}, FALSE))}
A7: 222963 | B7: WRND | C7: NYLI Global Equity R&D Leaders ETF | D7: =VLOOKUP(A7,'BNY FA Cash'!$C$27:$K$1048576,9,0) | E7: =VLOOKUP(A7,'BNY FA Cash'!$C$27:$O$1048576,13,0) | G7: =VLOOKUP(B7,'(FA) IQ'!$B$2:$M$11,12,0) | H7: =D7/G7 | I7: =E7/G7 | J7: =H7+I7 | L7: =N7/G7 | N7: {=SUM(VLOOKUP(B7, '(FA) IQ'!$B$2:$F$11, {3,4,5}, FALSE))}
A8: 240413 | B8: IQSM | C8: NYLI Candriam U.S. Mid Cap Equity ETF | D8: =VLOOKUP(A8,'BNY FA Cash'!$C$27:$K$1048576,9,0) | E8: =VLOOKUP(A8,'BNY FA Cash'!$C$27:$O$1048576,13,0) | G8: =VLOOKUP(B8,'(FA) IQ'!$B$2:$M$11,12,0) | H8: =D8/G8 | I8: =E8/G8 | J8: =H8+I8 | L8: =N8/G8 | N8: {=SUM(VLOOKUP(B8, '(FA) IQ'!$B$2:$F$11, {3,4,5}, FALSE))}
A9: 263076 | B9: QAI | C9: NYLI Hedge Multi-Strategy Tracker ETF | D9: =VLOOKUP(A9,'BNY FA Cash'!$C$27:$K$1048576,9,0) | E9: =VLOOKUP(A9,'BNY FA Cash'!$C$27:$O$1048576,13,0) | G9: =VLOOKUP(B9,'(FA) IQ'!$B$2:$M$11,12,0) | H9: =D9/G9 | I9: =E9/G9 | J9: =H9+I9 | L9: =N9/G9 | N9: {=SUM(VLOOKUP(B9, '(FA) IQ'!$B$2:$F$11, {3,4,5}, FALSE))}
A10: 447594 | B10: HFXI | C10: NYLI FTSE International Equity Currency Neutral ETF | D10: =VLOOKUP(A10,'BNY FA Cash'!$C$27:$K$1048576,9,0) | E10: =VLOOKUP(A10,'BNY FA Cash'!$C$27:$O$1048576,13,0) | G10: =VLOOKUP(B10,'(FA) IQ'!$B$2:$M$11,12,0) | H10: =D10/G10 | I10: =E10/G10 | J10: =H10+I10 | L10: =N10/G10 | N10: {=SUM(VLOOKUP(B10, '(FA) IQ'!$B$2:$F$11, {3,4,5}, FALSE))}

Sheet Pending Failed Trade Matrix
A1: PENDING | C1: =VLOOKUP(C2,'Currency Rates'!$A$3:$C$32,3,0) | D1: =VLOOKUP(D2,'Currency Rates'!$A$3:$C$32,3,0) | E1: =VLOOKUP(E2,'Currency Rates'!$A$3:$C$32,3,0) | F1: =VLOOKUP(F2,'Currency Rates'!$A$3:$C$32,3,0) | G1: =VLOOKUP(G2,'Currency Rates'!$A$3:$C$32,3,0) | H1: =VLOOKUP(H2,'Currency Rates'!$A$3:$C$32,3,0) | I1: =VLOOKUP(I2,'Currency Rates'!$A$3:$C$32,3,0) | J1: =VLOOKUP(J2,'Currency Rates'!$A$3:$C$32,3,0) | ... AE1: =VLOOKUP(AE2,'Currency Rates'!$A$3:$C$32,3,0)
B2: Fund | C2: AUD | D2: BRL | E2: CAD | F2: CHF | G2: CLP | H2: COP | I2: CZK | J2: DKK | K2: EUR | L2: GBP | M2: HKD | N2: HUF | O2: IDR | P2: ILS | Q2: INR | R2: JPY | S2: KRW | T2: MXN | U2: MYR | V2: NOK | W2: NZD | X2: PHP | Y2: PLN | Z2: SEK | AA2: SGD | AB2: THB | AC2: TWD | AD2: ZAR | AE2: TRY | AF2: USD | AG2: TOTAL AMOUNT USD
A3: 139473 | B3: =VLOOKUP(A3,'IQ Equitizer'!$A$3:$B$12,2,0) | C3: =SUMIFS('BNY Unsettled Trades'!$AS:$AS,'BNY Unsettled Trades'!$N:$N,'Pending Failed Trade Matrix'!C$2,'BNY Unsettled Trades'!$X:$X,"Pending",'BNY Unsettled Trades'!$A:$A,'Pending Failed Trade Matrix'!$A3) | D3: =SUMIFS('BNY Unsettled Trades'!$AS:$AS,'BNY Unsettled Trades'!$N:$N,'Pending Failed Trade Matrix'!D$2,'BNY Unsettled Trades'!$X:$X,"Pending",'BNY Unsettled Trades'!$A:$A,'Pending Failed Trade Matrix'!$A3) | E3: =SUMIFS('BNY Unsettled Trades'!$AS:$AS,'BNY Unsettled Trades'!$N:$N,'Pending Failed Trade Matrix'!E$2,'BNY Unsettled Trades'!$X:$X,"Pending",'BNY Unsettled Trades'!$A:$A,'Pending Failed Trade Matrix'!$A3) | F3: =SUMIFS('BNY Unsettled Trades'!$AS:$AS,'BNY Unsettled Trades'!$N:$N,'Pending Failed Trade Matrix'!F$2,'BNY Unsettled Trades'!$X:$X,"Pending",'BNY Unsettled Trades'!$A:$A,'Pending Failed Trade Matrix'!$A3) | G3: =SUMIFS('BNY Unsettled Trades'!$AS:$AS,'BNY Unsettled Trades'!$N:$N,'Pending Failed Trade Matrix'!G$2,'BNY Unsettled Trades'!$X:$X,"Pending",'BNY Unsettled Trades'!$A:$A,'Pending Failed Trade Matrix'!$A3) | H3: =SUMIFS('BNY Unsettled Trades'!$AS:$AS,'BNY Unsettled Trades'!$N:$N,'Pending Failed Trade Matrix'!H$2,'BNY Unsettled Trades'!$X:$X,"Pending",'BNY Unsettled Trades'!$A:$A,'Pending Failed Trade Matrix'!$A3) | I3: =SUMIFS('BNY Unsettled Trades'!$AS:$AS,'BNY Unsettled Trades'!$N:$N,'Pending Failed Trade Matrix'!I$2,'BNY Unsettled Trades'!$X:$X,"Pending",'BNY Unsettled Trades'!$A:$A,'Pending Failed Trade Matrix'!$A3) | J3: =SUMIFS('BNY Unsettled Trades'!$AS:$AS,'BNY Unsettled Trades'!$N:$N,'Pending Failed Trade Matrix'!J$2,'BNY Unsettled Trades'!$X:$X,"Pending",'BNY Unsettled Trades'!$A:$A,'Pending Failed Trade Matrix'!$A3) | ... AF3: =SUMIFS('BNY Unsettled Trades'!$AS:$AS,'BNY Unsettled Trades'!$N:$N,'Pending Failed Trade Matrix'!AF$2,'BNY Unsettled Trades'!$X:$X,"Pending",'BNY Unsettled Trades'!$A:$A,'Pending Failed Trade Matrix'!$A3) | AG3: =AF3+SUM(C3/$C$1,D3/$D$1,E3/$E$1,F3/$F$1,G3/$G$1,H3/$H$1,I3/$I$1,J3/$J$1,K3/$K$1,L3/$L$1,M3/$M$1,N3/$N$1,O3/$O$1,P3/$P$1,Q3/$Q$1,R3/$R$1,S3/$S$1,T3/$T$1,U3/$U$1,V3/$V$1,W3/$W$1,X3/$X$1,Y3/$Y$1,Z3/$Z$1,AA3/$AA$1,AB3/$AB$1,AC3/$AC$1,AD3/$AD$1,AE3/$AE$1)
A4: 139522 | B4: =VLOOKUP(A4,'IQ Equitizer'!$A$3:$B$12,2,0) | C4: =SUMIFS('BNY Unsettled Trades'!$AS:$AS,'BNY Unsettled Trades'!$N:$N,'Pending Failed Trade Matrix'!C$2,'BNY Unsettled Trades'!$X:$X,"Pending",'BNY Unsettled Trades'!$A:$A,'Pending Failed Trade Matrix'!$A4) | D4: =SUMIFS('BNY Unsettled Trades'!$AS:$AS,'BNY Unsettled Trades'!$N:$N,'Pending Failed Trade Matrix'!D$2,'BNY Unsettled Trades'!$X:$X,"Pending",'BNY Unsettled Trades'!$A:$A,'Pending Failed Trade Matrix'!$A4) | E4: =SUMIFS('BNY Unsettled Trades'!$AS:$AS,'BNY Unsettled Trades'!$N:$N,'Pending Failed Trade Matrix'!E$2,'BNY Unsettled Trades'!$X:$X,"Pending",'BNY Unsettled Trades'!$A:$A,'Pending Failed Trade Matrix'!$A4) | F4: =SUMIFS('BNY Unsettled Trades'!$AS:$AS,'BNY Unsettled Trades'!$N:$N,'Pending Failed Trade Matrix'!F$2,'BNY Unsettled Trades'!$X:$X,"Pending",'BNY Unsettled Trades'!$A:$A,'Pending Failed Trade Matrix'!$A4) | G4: =SUMIFS('BNY Unsettled Trades'!$AS:$AS,'BNY Unsettled Trades'!$N:$N,'Pending Failed Trade Matrix'!G$2,'BNY Unsettled Trades'!$X:$X,"Pending",'BNY Unsettled Trades'!$A:$A,'Pending Failed Trade Matrix'!$A4) | H4: =SUMIFS('BNY Unsettled Trades'!$AS:$AS,'BNY Unsettled Trades'!$N:$N,'Pending Failed Trade Matrix'!H$2,'BNY Unsettled Trades'!$X:$X,"Pending",'BNY Unsettled Trades'!$A:$A,'Pending Failed Trade Matrix'!$A4) | I4: =SUMIFS('BNY Unsettled Trades'!$AS:$AS,'BNY Unsettled Trades'!$N:$N,'Pending Failed Trade Matrix'!I$2,'BNY Unsettled Trades'!$X:$X,"Pending",'BNY Unsettled Trades'!$A:$A,'Pending Failed Trade Matrix'!$A4) | J4: =SUMIFS('BNY Unsettled Trades'!$AS:$AS,'BNY Unsettled Trades'!$N:$N,'Pending Failed Trade Matrix'!J$2,'BNY Unsettled Trades'!$X:$X,"Pending",'BNY Unsettled Trades'!$A:$A,'Pending Failed Trade Matrix'!$A4) | ... AF4: =SUMIFS('BNY Unsettled Trades'!$AS:$AS,'BNY Unsettled Trades'!$N:$N,'Pending Failed Trade Matrix'!AF$2,'BNY Unsettled Trades'!$X:$X,"Pending",'BNY Unsettled Trades'!$A:$A,'Pending Failed Trade Matrix'!$A4) | AG4: =AF4+SUM(C4/$C$1,D4/$D$1,E4/$E$1,F4/$F$1,G4/$G$1,H4/$H$1,I4/$I$1,J4/$J$1,K4/$K$1,L4/$L$1,M4/$M$1,N4/$N$1,O4/$O$1,P4/$P$1,Q4/$Q$1,R4/$R$1,S4/$S$1,T4/$T$1,U4/$U$1,V4/$V$1,W4/$W$1,X4/$X$1,Y4/$Y$1,Z4/$Z$1,AA4/$AA$1,AB4/$AB$1,AC4/$AC$1,AD4/$AD$1,AE4/$AE$1)
A5: 156481 | B5: =VLOOKUP(A5,'IQ Equitizer'!$A$3:$B$12,2,0) | C5: =SUMIFS('BNY Unsettled Trades'!$AS:$AS,'BNY Unsettled Trades'!$N:$N,'Pending Failed Trade Matrix'!C$2,'BNY Unsettled Trades'!$X:$X,"Pending",'BNY Unsettled Trades'!$A:$A,'Pending Failed Trade Matrix'!$A5) | D5: =SUMIFS('BNY Unsettled Trades'!$AS:$AS,'BNY Unsettled Trades'!$N:$N,'Pending Failed Trade Matrix'!D$2,'BNY Unsettled Trades'!$X:$X,"Pending",'BNY Unsettled Trades'!$A:$A,'Pending Failed Trade Matrix'!$A5) | E5: =SUMIFS('BNY Unsettled Trades'!$AS:$AS,'BNY Unsettled Trades'!$N:$N,'Pending Failed Trade Matrix'!E$2,'BNY Unsettled Trades'!$X:$X,"Pending",'BNY Unsettled Trades'!$A:$A,'Pending Failed Trade Matrix'!$A5) | F5: =SUMIFS('BNY Unsettled Trades'!$AS:$AS,'BNY Unsettled Trades'!$N:$N,'Pending Failed Trade Matrix'!F$2,'BNY Unsettled Trades'!$X:$X,"Pending",'BNY Unsettled Trades'!$A:$A,'Pending Failed Trade Matrix'!$A5) | G5: =SUMIFS('BNY Unsettled Trades'!$AS:$AS,'BNY Unsettled Trades'!$N:$N,'Pending Failed Trade Matrix'!G$2,'BNY Unsettled Trades'!$X:$X,"Pending",'BNY Unsettled Trades'!$A:$A,'Pending Failed Trade Matrix'!$A5) | H5: =SUMIFS('BNY Unsettled Trades'!$AS:$AS,'BNY Unsettled Trades'!$N:$N,'Pending Failed Trade Matrix'!H$2,'BNY Unsettled Trades'!$X:$X,"Pending",'BNY Unsettled Trades'!$A:$A,'Pending Failed Trade Matrix'!$A5) | I5: =SUMIFS('BNY Unsettled Trades'!$AS:$AS,'BNY Unsettled Trades'!$N:$N,'Pending Failed Trade Matrix'!I$2,'BNY Unsettled Trades'!$X:$X,"Pending",'BNY Unsettled Trades'!$A:$A,'Pending Failed Trade Matrix'!$A5) | J5: =SUMIFS('BNY Unsettled Trades'!$AS:$AS,'BNY Unsettled Trades'!$N:$N,'Pending Failed Trade Matrix'!J$2,'BNY Unsettled Trades'!$X:$X,"Pending",'BNY Unsettled Trades'!$A:$A,'Pending Failed Trade Matrix'!$A5) | ... AF5: =SUMIFS('BNY Unsettled Trades'!$AS:$AS,'BNY Unsettled Trades'!$N:$N,'Pending Failed Trade Matrix'!AF$2,'BNY Unsettled Trades'!$X:$X,"Pending",'BNY Unsettled Trades'!$A:$A,'Pending Failed Trade Matrix'!$A5) | AG5: =AF5+SUM(C5/$C$1,D5/$D$1,E5/$E$1,F5/$F$1,G5/$G$1,H5/$H$1,I5/$I$1,J5/$J$1,K5/$K$1,L5/$L$1,M5/$M$1,N5/$N$1,O5/$O$1,P5/$P$1,Q5/$Q$1,R5/$R$1,S5/$S$1,T5/$T$1,U5/$U$1,V5/$V$1,W5/$W$1,X5/$X$1,Y5/$Y$1,Z5/$Z$1,AA5/$AA$1,AB5/$AB$1,AC5/$AC$1,AD5/$AD$1,AE5/$AE$1)
A6: 212156 | B6: =VLOOKUP(A6,'IQ Equitizer'!$A$3:$B$12,2,0) | C6: =SUMIFS('BNY Unsettled Trades'!$AS:$AS,'BNY Unsettled Trades'!$N:$N,'Pending Failed Trade Matrix'!C$2,'BNY Unsettled Trades'!$X:$X,"Pending",'BNY Unsettled Trades'!$A:$A,'Pending Failed Trade Matrix'!$A6) | D6: =SUMIFS('BNY Unsettled Trades'!$AS:$AS,'BNY Unsettled Trades'!$N:$N,'Pending Failed Trade Matrix'!D$2,'BNY Unsettled Trades'!$X:$X,"Pending",'BNY Unsettled Trades'!$A:$A,'Pending Failed Trade Matrix'!$A6) | E6: =SUMIFS('BNY Unsettled Trades'!$AS:$AS,'BNY Unsettled Trades'!$N:$N,'Pending Failed Trade Matrix'!E$2,'BNY Unsettled Trades'!$X:$X,"Pending",'BNY Unsettled Trades'!$A:$A,'Pending Failed Trade Matrix'!$A6) | F6: =SUMIFS('BNY Unsettled Trades'!$AS:$AS,'BNY Unsettled Trades'!$N:$N,'Pending Failed Trade Matrix'!F$2,'BNY Unsettled Trades'!$X:$X,"Pending",'BNY Unsettled Trades'!$A:$A,'Pending Failed Trade Matrix'!$A6) | G6: =SUMIFS('BNY Unsettled Trades'!$AS:$AS,'BNY Unsettled Trades'!$N:$N,'Pending Failed Trade Matrix'!G$2,'BNY Unsettled Trades'!$X:$X,"Pending",'BNY Unsettled Trades'!$A:$A,'Pending Failed Trade Matrix'!$A6) | H6: =SUMIFS('BNY Unsettled Trades'!$AS:$AS,'BNY Unsettled Trades'!$N:$N,'Pending Failed Trade Matrix'!H$2,'BNY Unsettled Trades'!$X:$X,"Pending",'BNY Unsettled Trades'!$A:$A,'Pending Failed Trade Matrix'!$A6) | I6: =SUMIFS('BNY Unsettled Trades'!$AS:$AS,'BNY Unsettled Trades'!$N:$N,'Pending Failed Trade Matrix'!I$2,'BNY Unsettled Trades'!$X:$X,"Pending",'BNY Unsettled Trades'!$A:$A,'Pending Failed Trade Matrix'!$A6) | J6: =SUMIFS('BNY Unsettled Trades'!$AS:$AS,'BNY Unsettled Trades'!$N:$N,'Pending Failed Trade Matrix'!J$2,'BNY Unsettled Trades'!$X:$X,"Pending",'BNY Unsettled Trades'!$A:$A,'Pending Failed Trade Matrix'!$A6) | ... AF6: =SUMIFS('BNY Unsettled Trades'!$AS:$AS,'BNY Unsettled Trades'!$N:$N,'Pending Failed Trade Matrix'!AF$2,'BNY Unsettled Trades'!$X:$X,"Pending",'BNY Unsettled Trades'!$A:$A,'Pending Failed Trade Matrix'!$A6) | AG6: =AF6+SUM(C6/$C$1,D6/$D$1,E6/$E$1,F6/$F$1,G6/$G$1,H6/$H$1,I6/$I$1,J6/$J$1,K6/$K$1,L6/$L$1,M6/$M$1,N6/$N$1,O6/$O$1,P6/$P$1,Q6/$Q$1,R6/$R$1,S6/$S$1,T6/$T$1,U6/$U$1,V6/$V$1,W6/$W$1,X6/$X$1,Y6/$Y$1,Z6/$Z$1,AA6/$AA$1,AB6/$AB$1,AC6/$AC$1,AD6/$AD$1,AE6/$AE$1)
A7: 222959 | B7: =VLOOKUP(A7,'IQ Equitizer'!$A$3:$B$12,2,0) | C7: =SUMIFS('BNY Unsettled Trades'!$AS:$AS,'BNY Unsettled Trades'!$N:$N,'Pending Failed Trade Matrix'!C$2,'BNY Unsettled Trades'!$X:$X,"Pending",'BNY Unsettled Trades'!$A:$A,'Pending Failed Trade Matrix'!$A7) | D7: =SUMIFS('BNY Unsettled Trades'!$AS:$AS,'BNY Unsettled Trades'!$N:$N,'Pending Failed Trade Matrix'!D$2,'BNY Unsettled Trades'!$X:$X,"Pending",'BNY Unsettled Trades'!$A:$A,'Pending Failed Trade Matrix'!$A7) | E7: =SUMIFS('BNY Unsettled Trades'!$AS:$AS,'BNY Unsettled Trades'!$N:$N,'Pending Failed Trade Matrix'!E$2,'BNY Unsettled Trades'!$X:$X,"Pending",'BNY Unsettled Trades'!$A:$A,'Pending Failed Trade Matrix'!$A7) | F7: =SUMIFS('BNY Unsettled Trades'!$AS:$AS,'BNY Unsettled Trades'!$N:$N,'Pending Failed Trade Matrix'!F$2,'BNY Unsettled Trades'!$X:$X,"Pending",'BNY Unsettled Trades'!$A:$A,'Pending Failed Trade Matrix'!$A7) | G7: =SUMIFS('BNY Unsettled Trades'!$AS:$AS,'BNY Unsettled Trades'!$N:$N,'Pending Failed Trade Matrix'!G$2,'BNY Unsettled Trades'!$X:$X,"Pending",'BNY Unsettled Trades'!$A:$A,'Pending Failed Trade Matrix'!$A7) | H7: =SUMIFS('BNY Unsettled Trades'!$AS:$AS,'BNY Unsettled Trades'!$N:$N,'Pending Failed Trade Matrix'!H$2,'BNY Unsettled Trades'!$X:$X,"Pending",'BNY Unsettled Trades'!$A:$A,'Pending Failed Trade Matrix'!$A7) | I7: =SUMIFS('BNY Unsettled Trades'!$AS:$AS,'BNY Unsettled Trades'!$N:$N,'Pending Failed Trade Matrix'!I$2,'BNY Unsettled Trades'!$X:$X,"Pending",'BNY Unsettled Trades'!$A:$A,'Pending Failed Trade Matrix'!$A7) | J7: =SUMIFS('BNY Unsettled Trades'!$AS:$AS,'BNY Unsettled Trades'!$N:$N,'Pending Failed Trade Matrix'!J$2,'BNY Unsettled Trades'!$X:$X,"Pending",'BNY Unsettled Trades'!$A:$A,'Pending Failed Trade Matrix'!$A7) | ... AF7: =SUMIFS('BNY Unsettled Trades'!$AS:$AS,'BNY Unsettled Trades'!$N:$N,'Pending Failed Trade Matrix'!AF$2,'BNY Unsettled Trades'!$X:$X,"Pending",'BNY Unsettled Trades'!$A:$A,'Pending Failed Trade Matrix'!$A7) | AG7: =AF7+SUM(C7/$C$1,D7/$D$1,E7/$E$1,F7/$F$1,G7/$G$1,H7/$H$1,I7/$I$1,J7/$J$1,K7/$K$1,L7/$L$1,M7/$M$1,N7/$N$1,O7/$O$1,P7/$P$1,Q7/$Q$1,R7/$R$1,S7/$S$1,T7/$T$1,U7/$U$1,V7/$V$1,W7/$W$1,X7/$X$1,Y7/$Y$1,Z7/$Z$1,AA7/$AA$1,AB7/$AB$1,AC7/$AC$1,AD7/$AD$1,AE7/$AE$1)
A8: 222963 | B8: =VLOOKUP(A8,'IQ Equitizer'!$A$3:$B$12,2,0) | C8: =SUMIFS('BNY Unsettled Trades'!$AS:$AS,'BNY Unsettled Trades'!$N:$N,'Pending Failed Trade Matrix'!C$2,'BNY Unsettled Trades'!$X:$X,"Pending",'BNY Unsettled Trades'!$A:$A,'Pending Failed Trade Matrix'!$A8) | D8: =SUMIFS('BNY Unsettled Trades'!$AS:$AS,'BNY Unsettled Trades'!$N:$N,'Pending Failed Trade Matrix'!D$2,'BNY Unsettled Trades'!$X:$X,"Pending",'BNY Unsettled Trades'!$A:$A,'Pending Failed Trade Matrix'!$A8) | E8: =SUMIFS('BNY Unsettled Trades'!$AS:$AS,'BNY Unsettled Trades'!$N:$N,'Pending Failed Trade Matrix'!E$2,'BNY Unsettled Trades'!$X:$X,"Pending",'BNY Unsettled Trades'!$A:$A,'Pending Failed Trade Matrix'!$A8) | F8: =SUMIFS('BNY Unsettled Trades'!$AS:$AS,'BNY Unsettled Trades'!$N:$N,'Pending Failed Trade Matrix'!F$2,'BNY Unsettled Trades'!$X:$X,"Pending",'BNY Unsettled Trades'!$A:$A,'Pending Failed Trade Matrix'!$A8) | G8: =SUMIFS('BNY Unsettled Trades'!$AS:$AS,'BNY Unsettled Trades'!$N:$N,'Pending Failed Trade Matrix'!G$2,'BNY Unsettled Trades'!$X:$X,"Pending",'BNY Unsettled Trades'!$A:$A,'Pending Failed Trade Matrix'!$A8) | H8: =SUMIFS('BNY Unsettled Trades'!$AS:$AS,'BNY Unsettled Trades'!$N:$N,'Pending Failed Trade Matrix'!H$2,'BNY Unsettled Trades'!$X:$X,"Pending",'BNY Unsettled Trades'!$A:$A,'Pending Failed Trade Matrix'!$A8) | I8: =SUMIFS('BNY Unsettled Trades'!$AS:$AS,'BNY Unsettled Trades'!$N:$N,'Pending Failed Trade Matrix'!I$2,'BNY Unsettled Trades'!$X:$X,"Pending",'BNY Unsettled Trades'!$A:$A,'Pending Failed Trade Matrix'!$A8) | J8: =SUMIFS('BNY Unsettled Trades'!$AS:$AS,'BNY Unsettled Trades'!$N:$N,'Pending Failed Trade Matrix'!J$2,'BNY Unsettled Trades'!$X:$X,"Pending",'BNY Unsettled Trades'!$A:$A,'Pending Failed Trade Matrix'!$A8) | ... AF8: =SUMIFS('BNY Unsettled Trades'!$AS:$AS,'BNY Unsettled Trades'!$N:$N,'Pending Failed Trade Matrix'!AF$2,'BNY Unsettled Trades'!$X:$X,"Pending",'BNY Unsettled Trades'!$A:$A,'Pending Failed Trade Matrix'!$A8) | AG8: =AF8+SUM(C8/$C$1,D8/$D$1,E8/$E$1,F8/$F$1,G8/$G$1,H8/$H$1,I8/$I$1,J8/$J$1,K8/$K$1,L8/$L$1,M8/$M$1,N8/$N$1,O8/$O$1,P8/$P$1,Q8/$Q$1,R8/$R$1,S8/$S$1,T8/$T$1,U8/$U$1,V8/$V$1,W8/$W$1,X8/$X$1,Y8/$Y$1,Z8/$Z$1,AA8/$AA$1,AB8/$AB$1,AC8/$AC$1,AD8/$AD$1,AE8/$AE$1)
A9: 240413 | B9: =VLOOKUP(A9,'IQ Equitizer'!$A$3:$B$12,2,0) | C9: =SUMIFS('BNY Unsettled Trades'!$AS:$AS,'BNY Unsettled Trades'!$N:$N,'Pending Failed Trade Matrix'!C$2,'BNY Unsettled Trades'!$X:$X,"Pending",'BNY Unsettled Trades'!$A:$A,'Pending Failed Trade Matrix'!$A9) | D9: =SUMIFS('BNY Unsettled Trades'!$AS:$AS,'BNY Unsettled Trades'!$N:$N,'Pending Failed Trade Matrix'!D$2,'BNY Unsettled Trades'!$X:$X,"Pending",'BNY Unsettled Trades'!$A:$A,'Pending Failed Trade Matrix'!$A9) | E9: =SUMIFS('BNY Unsettled Trades'!$AS:$AS,'BNY Unsettled Trades'!$N:$N,'Pending Failed Trade Matrix'!E$2,'BNY Unsettled Trades'!$X:$X,"Pending",'BNY Unsettled Trades'!$A:$A,'Pending Failed Trade Matrix'!$A9) | F9: =SUMIFS('BNY Unsettled Trades'!$AS:$AS,'BNY Unsettled Trades'!$N:$N,'Pending Failed Trade Matrix'!F$2,'BNY Unsettled Trades'!$X:$X,"Pending",'BNY Unsettled Trades'!$A:$A,'Pending Failed Trade Matrix'!$A9) | G9: =SUMIFS('BNY Unsettled Trades'!$AS:$AS,'BNY Unsettled Trades'!$N:$N,'Pending Failed Trade Matrix'!G$2,'BNY Unsettled Trades'!$X:$X,"Pending",'BNY Unsettled Trades'!$A:$A,'Pending Failed Trade Matrix'!$A9) | H9: =SUMIFS('BNY Unsettled Trades'!$AS:$AS,'BNY Unsettled Trades'!$N:$N,'Pending Failed Trade Matrix'!H$2,'BNY Unsettled Trades'!$X:$X,"Pending",'BNY Unsettled Trades'!$A:$A,'Pending Failed Trade Matrix'!$A9) | I9: =SUMIFS('BNY Unsettled Trades'!$AS:$AS,'BNY Unsettled Trades'!$N:$N,'Pending Failed Trade Matrix'!I$2,'BNY Unsettled Trades'!$X:$X,"Pending",'BNY Unsettled Trades'!$A:$A,'Pending Failed Trade Matrix'!$A9) | J9: =SUMIFS('BNY Unsettled Trades'!$AS:$AS,'BNY Unsettled Trades'!$N:$N,'Pending Failed Trade Matrix'!J$2,'BNY Unsettled Trades'!$X:$X,"Pending",'BNY Unsettled Trades'!$A:$A,'Pending Failed Trade Matrix'!$A9) | ... AF9: =SUMIFS('BNY Unsettled Trades'!$AS:$AS,'BNY Unsettled Trades'!$N:$N,'Pending Failed Trade Matrix'!AF$2,'BNY Unsettled Trades'!$X:$X,"Pending",'BNY Unsettled Trades'!$A:$A,'Pending Failed Trade Matrix'!$A9) | AG9: =AF9+SUM(C9/$C$1,D9/$D$1,E9/$E$1,F9/$F$1,G9/$G$1,H9/$H$1,I9/$I$1,J9/$J$1,K9/$K$1,L9/$L$1,M9/$M$1,N9/$N$1,O9/$O$1,P9/$P$1,Q9/$Q$1,R9/$R$1,S9/$S$1,T9/$T$1,U9/$U$1,V9/$V$1,W9/$W$1,X9/$X$1,Y9/$Y$1,Z9/$Z$1,AA9/$AA$1,AB9/$AB$1,AC9/$AC$1,AD9/$AD$1,AE9/$AE$1)
A10: 263076 | B10: =VLOOKUP(A10,'IQ Equitizer'!$A$3:$B$12,2,0) | C10: =SUMIFS('BNY Unsettled Trades'!$AS:$AS,'BNY Unsettled Trades'!$N:$N,'Pending Failed Trade Matrix'!C$2,'BNY Unsettled Trades'!$X:$X,"Pending",'BNY Unsettled Trades'!$A:$A,'Pending Failed Trade Matrix'!$A10) | D10: =SUMIFS('BNY Unsettled Trades'!$AS:$AS,'BNY Unsettled Trades'!$N:$N,'Pending Failed Trade Matrix'!D$2,'BNY Unsettled Trades'!$X:$X,"Pending",'BNY Unsettled Trades'!$A:$A,'Pending Failed Trade Matrix'!$A10) | E10: =SUMIFS('BNY Unsettled Trades'!$AS:$AS,'BNY Unsettled Trades'!$N:$N,'Pending Failed Trade Matrix'!E$2,'BNY Unsettled Trades'!$X:$X,"Pending",'BNY Unsettled Trades'!$A:$A,'Pending Failed Trade Matrix'!$A10) | F10: =SUMIFS('BNY Unsettled Trades'!$AS:$AS,'BNY Unsettled Trades'!$N:$N,'Pending Failed Trade Matrix'!F$2,'BNY Unsettled Trades'!$X:$X,"Pending",'BNY Unsettled Trades'!$A:$A,'Pending Failed Trade Matrix'!$A10) | G10: =SUMIFS('BNY Unsettled Trades'!$AS:$AS,'BNY Unsettled Trades'!$N:$N,'Pending Failed Trade Matrix'!G$2,'BNY Unsettled Trades'!$X:$X,"Pending",'BNY Unsettled Trades'!$A:$A,'Pending Failed Trade Matrix'!$A10) | H10: =SUMIFS('BNY Unsettled Trades'!$AS:$AS,'BNY Unsettled Trades'!$N:$N,'Pending Failed Trade Matrix'!H$2,'BNY Unsettled Trades'!$X:$X,"Pending",'BNY Unsettled Trades'!$A:$A,'Pending Failed Trade Matrix'!$A10) | I10: =SUMIFS('BNY Unsettled Trades'!$AS:$AS,'BNY Unsettled Trades'!$N:$N,'Pending Failed Trade Matrix'!I$2,'BNY Unsettled Trades'!$X:$X,"Pending",'BNY Unsettled Trades'!$A:$A,'Pending Failed Trade Matrix'!$A10) | J10: =SUMIFS('BNY Unsettled Trades'!$AS:$AS,'BNY Unsettled Trades'!$N:$N,'Pending Failed Trade Matrix'!J$2,'BNY Unsettled Trades'!$X:$X,"Pending",'BNY Unsettled Trades'!$A:$A,'Pending Failed Trade Matrix'!$A10) | ... AF10: =SUMIFS('BNY Unsettled Trades'!$AS:$AS,'BNY Unsettled Trades'!$N:$N,'Pending Failed Trade Matrix'!AF$2,'BNY Unsettled Trades'!$X:$X,"Pending",'BNY Unsettled Trades'!$A:$A,'Pending Failed Trade Matrix'!$A10) | AG10: =AF10+SUM(C10/$C$1,D10/$D$1,E10/$E$1,F10/$F$1,G10/$G$1,H10/$H$1,I10/$I$1,J10/$J$1,K10/$K$1,L10/$L$1,M10/$M$1,N10/$N$1,O10/$O$1,P10/$P$1,Q10/$Q$1,R10/$R$1,S10/$S$1,T10/$T$1,U10/$U$1,V10/$V$1,W10/$W$1,X10/$X$1,Y10/$Y$1,Z10/$Z$1,AA10/$AA$1,AB10/$AB$1,AC10/$AC$1,AD10/$AD$1,AE10/$AE$1)
A11: 447594 | B11: =VLOOKUP(A11,'IQ Equitizer'!$A$3:$B$12,2,0) | C11: =SUMIFS('BNY Unsettled Trades'!$AS:$AS,'BNY Unsettled Trades'!$N:$N,'Pending Failed Trade Matrix'!C$2,'BNY Unsettled Trades'!$X:$X,"Pending",'BNY Unsettled Trades'!$A:$A,'Pending Failed Trade Matrix'!$A11) | D11: =SUMIFS('BNY Unsettled Trades'!$AS:$AS,'BNY Unsettled Trades'!$N:$N,'Pending Failed Trade Matrix'!D$2,'BNY Unsettled Trades'!$X:$X,"Pending",'BNY Unsettled Trades'!$A:$A,'Pending Failed Trade Matrix'!$A11) | E11: =SUMIFS('BNY Unsettled Trades'!$AS:$AS,'BNY Unsettled Trades'!$N:$N,'Pending Failed Trade Matrix'!E$2,'BNY Unsettled Trades'!$X:$X,"Pending",'BNY Unsettled Trades'!$A:$A,'Pending Failed Trade Matrix'!$A11) | F11: =SUMIFS('BNY Unsettled Trades'!$AS:$AS,'BNY Unsettled Trades'!$N:$N,'Pending Failed Trade Matrix'!F$2,'BNY Unsettled Trades'!$X:$X,"Pending",'BNY Unsettled Trades'!$A:$A,'Pending Failed Trade Matrix'!$A11) | G11: =SUMIFS('BNY Unsettled Trades'!$AS:$AS,'BNY Unsettled Trades'!$N:$N,'Pending Failed Trade Matrix'!G$2,'BNY Unsettled Trades'!$X:$X,"Pending",'BNY Unsettled Trades'!$A:$A,'Pending Failed Trade Matrix'!$A11) | H11: =SUMIFS('BNY Unsettled Trades'!$AS:$AS,'BNY Unsettled Trades'!$N:$N,'Pending Failed Trade Matrix'!H$2,'BNY Unsettled Trades'!$X:$X,"Pending",'BNY Unsettled Trades'!$A:$A,'Pending Failed Trade Matrix'!$A11) | I11: =SUMIFS('BNY Unsettled Trades'!$AS:$AS,'BNY Unsettled Trades'!$N:$N,'Pending Failed Trade Matrix'!I$2,'BNY Unsettled Trades'!$X:$X,"Pending",'BNY Unsettled Trades'!$A:$A,'Pending Failed Trade Matrix'!$A11) | J11: =SUMIFS('BNY Unsettled Trades'!$AS:$AS,'BNY Unsettled Trades'!$N:$N,'Pending Failed Trade Matrix'!J$2,'BNY Unsettled Trades'!$X:$X,"Pending",'BNY Unsettled Trades'!$A:$A,'Pending Failed Trade Matrix'!$A11) | ... AF11: =SUMIFS('BNY Unsettled Trades'!$AS:$AS,'BNY Unsettled Trades'!$N:$N,'Pending Failed Trade Matrix'!AF$2,'BNY Unsettled Trades'!$X:$X,"Pending",'BNY Unsettled Trades'!$A:$A,'Pending Failed Trade Matrix'!$A11) | AG11: =AF11+SUM(C11/$C$1,D11/$D$1,E11/$E$1,F11/$F$1,G11/$G$1,H11/$H$1,I11/$I$1,J11/$J$1,K11/$K$1,L11/$L$1,M11/$M$1,N11/$N$1,O11/$O$1,P11/$P$1,Q11/$Q$1,R11/$R$1,S11/$S$1,T11/$T$1,U11/$U$1,V11/$V$1,W11/$W$1,X11/$X$1,Y11/$Y$1,Z11/$Z$1,AA11/$AA$1,AB11/$AB$1,AC11/$AC$1,AD11/$AD$1,AE11/$AE$1)
A12: G 26785 | B12: VP Mutual Fund | C12: 0 | D12: 0 | E12: 0 | F12: 0 | G12: 0 | H12: 0 | I12: 0 | J12: 0 | K12: 0 | L12: 0 | M12: 0 | N12: 0 | O12: 0 | P12: 0 | Q12: 0 | R12: 0 | S12: 0 | T12: 0 | U12: 0 | V12: 0 | W12: 0 | X12: 0 | Y12: 0 | Z12: 0 | AA12: 0 | AB12: 0 | AC12: 0 | AD12: 0 | AE12: 0 | AF12: =SUMIF('VP Proj Cash Statement (8am)'!C:C,A12,'VP Proj Cash Statement (8am)'!L:L)+SUMIF('VP Proj Cash Statement (8am)'!C:C,A12,'VP Proj Cash Statement (8am)'!M:M)+SUMIF('VP Proj Cash Statement (8am)'!C:C,A12,'VP Proj Cash Statement (8am)'!Y:Y)+SUMIF('VP Proj Cash Statement (8am)'!C:C,A12,'VP Proj Cash Statement (8am)'!Z:Z)-((SUMIFS('VP Proj Cash Statement (8am)'!$AK$5:$AK$65525,'VP Proj Cash Detail (10am)'!$I$5:$I$65525,A12,'VP Proj Cash Detail (10am)'!$Y$5:$Y$65525,"JPMORGAN SHORT TERM INVESTMENT FUNDS",'VP Proj Cash Detail (10am)'!$C$5:$C$65525,"PURCHASES")+SUMIFS('VP Proj Cash Detail (10am)'!$AK$5:$AK$65525,'VP Proj Cash Detail (10am)'!$I$5:$I$65525,A12,'VP Proj Cash Detail (10am)'!$AE$5:$AE$65525,"MUSXX",'VP Proj Cash Detail (10am)'!$C$5:$C$65525,"PURCHASES"))+SUMIFS('VP Proj Cash Detail (10am)'!$AK$5:$AK$65525,'VP Proj Cash Detail (10am)'!$I$5:$I$65525,A12,'VP Proj Cash Detail (10am)'!$Y$5:$Y$65525,"JPMORGAN SHORT TERM INVESTMENT FUNDS",'VP Proj Cash Detail (10am)'!$C$5:$C$65525,"Sales")+SUMIFS('VP Proj Cash Detail (10am)'!$AK$5:$AK$65525,'VP Proj Cash Detail (10am)'!$I$5:$I$65525,A12,'VP Proj Cash Detail (10am)'!$AE$5:$AE$65525,"MUSXX",'VP Proj Cash Detail (10am)'!$C$5:$C$65525,"Sales")) | AG12: =AF12+SUM(C12/$C$1,D12/$D$1,E12/$E$1,F12/$F$1,G12/$G$1,H12/$H$1,I12/$I$1,J12/$J$1,K12/$K$1,L12/$L$1,M12/$M$1,N12/$N$1,O12/$O$1,P12/$P$1,Q12/$Q$1,R12/$R$1,S12/$S$1,T12/$T$1,U12/$U$1,V12/$V$1,W12/$W$1,X12/$X$1,Y12/$Y$1,Z12/$Z$1,AA12/$AA$1,AB12/$AB$1,AC12/$AC$1,AD12/$AD$1,AE12/$AE$1)
A15: Failing
B16: Fund | C16: AUD | D16: BRL | E16: CAD | F16: CHF | G16: CLP | H16: COP | I16: CZK | J16: DKK | K16: EUR | L16: GBP | M16: HKD | N16: HUF | O16: IDR | P16: ILS | Q16: INR | R16: JPY | S16: KRW | T16: MXN | U16: MYR | V16: NOK | W16: NZD | X16: PHP | Y16: PLN | Z16: SEK | AA16: SGD | AB16: THB | AC16: TWD | AD16: ZAR | AE16: TRY | AF16: USD | AG16: TOTAL AMOUNT USD
A17: 139473 | B17: =VLOOKUP(A17,'IQ Equitizer'!$A$3:$B$12,2,0) | C17: =SUMIFS('BNY Unsettled Trades'!$AS:$AS,'BNY Unsettled Trades'!$N:$N,'Pending Failed Trade Matrix'!C$16,'BNY Unsettled Trades'!$X:$X,"Failing",'BNY Unsettled Trades'!$A:$A,'Pending Failed Trade Matrix'!$A17) | D17: =SUMIFS('BNY Unsettled Trades'!$AS:$AS,'BNY Unsettled Trades'!$N:$N,'Pending Failed Trade Matrix'!D$16,'BNY Unsettled Trades'!$X:$X,"Failing",'BNY Unsettled Trades'!$A:$A,'Pending Failed Trade Matrix'!$A17) | E17: =SUMIFS('BNY Unsettled Trades'!$AS:$AS,'BNY Unsettled Trades'!$N:$N,'Pending Failed Trade Matrix'!E$16,'BNY Unsettled Trades'!$X:$X,"Failing",'BNY Unsettled Trades'!$A:$A,'Pending Failed Trade Matrix'!$A17) | F17: =SUMIFS('BNY Unsettled Trades'!$AS:$AS,'BNY Unsettled Trades'!$N:$N,'Pending Failed Trade Matrix'!F$16,'BNY Unsettled Trades'!$X:$X,"Failing",'BNY Unsettled Trades'!$A:$A,'Pending Failed Trade Matrix'!$A17) | G17: =SUMIFS('BNY Unsettled Trades'!$AS:$AS,'BNY Unsettled Trades'!$N:$N,'Pending Failed Trade Matrix'!G$16,'BNY Unsettled Trades'!$X:$X,"Failing",'BNY Unsettled Trades'!$A:$A,'Pending Failed Trade Matrix'!$A17) | H17: =SUMIFS('BNY Unsettled Trades'!$AS:$AS,'BNY Unsettled Trades'!$N:$N,'Pending Failed Trade Matrix'!H$16,'BNY Unsettled Trades'!$X:$X,"Failing",'BNY Unsettled Trades'!$A:$A,'Pending Failed Trade Matrix'!$A17) | I17: =SUMIFS('BNY Unsettled Trades'!$AS:$AS,'BNY Unsettled Trades'!$N:$N,'Pending Failed Trade Matrix'!I$16,'BNY Unsettled Trades'!$X:$X,"Failing",'BNY Unsettled Trades'!$A:$A,'Pending Failed Trade Matrix'!$A17) | J17: =SUMIFS('BNY Unsettled Trades'!$AS:$AS,'BNY Unsettled Trades'!$N:$N,'Pending Failed Trade Matrix'!J$16,'BNY Unsettled Trades'!$X:$X,"Failing",'BNY Unsettled Trades'!$A:$A,'Pending Failed Trade Matrix'!$A17) | ... AF17: =SUMIFS('BNY Unsettled Trades'!$AS:$AS,'BNY Unsettled Trades'!$N:$N,'Pending Failed Trade Matrix'!AF$16,'BNY Unsettled Trades'!$X:$X,"Failing",'BNY Unsettled Trades'!$A:$A,'Pending Failed Trade Matrix'!$A17) | AG17: =AF17+SUM(C17/$C$1,D17/$D$1,E17/$E$1,F17/$F$1,G17/$G$1,H17/$H$1,I17/$I$1,J17/$J$1,K17/$K$1,L17/$L$1,M17/$M$1,N17/$N$1,O17/$O$1,P17/$P$1,Q17/$Q$1,R17/$R$1,S17/$S$1,T17/$T$1,U17/$U$1,V17/$V$1,W17/$W$1,X17/$X$1,Y17/$Y$1,Z17/$Z$1,AA17/$AA$1,AB17/$AB$1,AC17/$AC$1,AD17/$AD$1,AE17/$AE$1)
A18: 139522 | B18: =VLOOKUP(A18,'IQ Equitizer'!$A$3:$B$12,2,0) | C18: =SUMIFS('BNY Unsettled Trades'!$AS:$AS,'BNY Unsettled Trades'!$N:$N,'Pending Failed Trade Matrix'!C$16,'BNY Unsettled Trades'!$X:$X,"Failing",'BNY Unsettled Trades'!$A:$A,'Pending Failed Trade Matrix'!$A18) | D18: =SUMIFS('BNY Unsettled Trades'!$AS:$AS,'BNY Unsettled Trades'!$N:$N,'Pending Failed Trade Matrix'!D$16,'BNY Unsettled Trades'!$X:$X,"Failing",'BNY Unsettled Trades'!$A:$A,'Pending Failed Trade Matrix'!$A18) | E18: =SUMIFS('BNY Unsettled Trades'!$AS:$AS,'BNY Unsettled Trades'!$N:$N,'Pending Failed Trade Matrix'!E$16,'BNY Unsettled Trades'!$X:$X,"Failing",'BNY Unsettled Trades'!$A:$A,'Pending Failed Trade Matrix'!$A18) | F18: =SUMIFS('BNY Unsettled Trades'!$AS:$AS,'BNY Unsettled Trades'!$N:$N,'Pending Failed Trade Matrix'!F$16,'BNY Unsettled Trades'!$X:$X,"Failing",'BNY Unsettled Trades'!$A:$A,'Pending Failed Trade Matrix'!$A18) | G18: =SUMIFS('BNY Unsettled Trades'!$AS:$AS,'BNY Unsettled Trades'!$N:$N,'Pending Failed Trade Matrix'!G$16,'BNY Unsettled Trades'!$X:$X,"Failing",'BNY Unsettled Trades'!$A:$A,'Pending Failed Trade Matrix'!$A18) | H18: =SUMIFS('BNY Unsettled Trades'!$AS:$AS,'BNY Unsettled Trades'!$N:$N,'Pending Failed Trade Matrix'!H$16,'BNY Unsettled Trades'!$X:$X,"Failing",'BNY Unsettled Trades'!$A:$A,'Pending Failed Trade Matrix'!$A18) | I18: =SUMIFS('BNY Unsettled Trades'!$AS:$AS,'BNY Unsettled Trades'!$N:$N,'Pending Failed Trade Matrix'!I$16,'BNY Unsettled Trades'!$X:$X,"Failing",'BNY Unsettled Trades'!$A:$A,'Pending Failed Trade Matrix'!$A18) | J18: =SUMIFS('BNY Unsettled Trades'!$AS:$AS,'BNY Unsettled Trades'!$N:$N,'Pending Failed Trade Matrix'!J$16,'BNY Unsettled Trades'!$X:$X,"Failing",'BNY Unsettled Trades'!$A:$A,'Pending Failed Trade Matrix'!$A18) | ... AF18: =SUMIFS('BNY Unsettled Trades'!$AS:$AS,'BNY Unsettled Trades'!$N:$N,'Pending Failed Trade Matrix'!AF$16,'BNY Unsettled Trades'!$X:$X,"Failing",'BNY Unsettled Trades'!$A:$A,'Pending Failed Trade Matrix'!$A18) | AG18: =AF18+SUM(C18/$C$1,D18/$D$1,E18/$E$1,F18/$F$1,G18/$G$1,H18/$H$1,I18/$I$1,J18/$J$1,K18/$K$1,L18/$L$1,M18/$M$1,N18/$N$1,O18/$O$1,P18/$P$1,Q18/$Q$1,R18/$R$1,S18/$S$1,T18/$T$1,U18/$U$1,V18/$V$1,W18/$W$1,X18/$X$1,Y18/$Y$1,Z18/$Z$1,AA18/$AA$1,AB18/$AB$1,AC18/$AC$1,AD18/$AD$1,AE18/$AE$1)
A19: 156481 | B19: =VLOOKUP(A19,'IQ Equitizer'!$A$3:$B$12,2,0) | C19: =SUMIFS('BNY Unsettled Trades'!$AS:$AS,'BNY Unsettled Trades'!$N:$N,'Pending Failed Trade Matrix'!C$16,'BNY Unsettled Trades'!$X:$X,"Failing",'BNY Unsettled Trades'!$A:$A,'Pending Failed Trade Matrix'!$A19) | D19: =SUMIFS('BNY Unsettled Trades'!$AS:$AS,'BNY Unsettled Trades'!$N:$N,'Pending Failed Trade Matrix'!D$16,'BNY Unsettled Trades'!$X:$X,"Failing",'BNY Unsettled Trades'!$A:$A,'Pending Failed Trade Matrix'!$A19) | E19: =SUMIFS('BNY Unsettled Trades'!$AS:$AS,'BNY Unsettled Trades'!$N:$N,'Pending Failed Trade Matrix'!E$16,'BNY Unsettled Trades'!$X:$X,"Failing",'BNY Unsettled Trades'!$A:$A,'Pending Failed Trade Matrix'!$A19) | F19: =SUMIFS('BNY Unsettled Trades'!$AS:$AS,'BNY Unsettled Trades'!$N:$N,'Pending Failed Trade Matrix'!F$16,'BNY Unsettled Trades'!$X:$X,"Failing",'BNY Unsettled Trades'!$A:$A,'Pending Failed Trade Matrix'!$A19) | G19: =SUMIFS('BNY Unsettled Trades'!$AS:$AS,'BNY Unsettled Trades'!$N:$N,'Pending Failed Trade Matrix'!G$16,'BNY Unsettled Trades'!$X:$X,"Failing",'BNY Unsettled Trades'!$A:$A,'Pending Failed Trade Matrix'!$A19) | H19: =SUMIFS('BNY Unsettled Trades'!$AS:$AS,'BNY Unsettled Trades'!$N:$N,'Pending Failed Trade Matrix'!H$16,'BNY Unsettled Trades'!$X:$X,"Failing",'BNY Unsettled Trades'!$A:$A,'Pending Failed Trade Matrix'!$A19) | I19: =SUMIFS('BNY Unsettled Trades'!$AS:$AS,'BNY Unsettled Trades'!$N:$N,'Pending Failed Trade Matrix'!I$16,'BNY Unsettled Trades'!$X:$X,"Failing",'BNY Unsettled Trades'!$A:$A,'Pending Failed Trade Matrix'!$A19) | J19: =SUMIFS('BNY Unsettled Trades'!$AS:$AS,'BNY Unsettled Trades'!$N:$N,'Pending Failed Trade Matrix'!J$16,'BNY Unsettled Trades'!$X:$X,"Failing",'BNY Unsettled Trades'!$A:$A,'Pending Failed Trade Matrix'!$A19) | ... AF19: =SUMIFS('BNY Unsettled Trades'!$AS:$AS,'BNY Unsettled Trades'!$N:$N,'Pending Failed Trade Matrix'!AF$16,'BNY Unsettled Trades'!$X:$X,"Failing",'BNY Unsettled Trades'!$A:$A,'Pending Failed Trade Matrix'!$A19) | AG19: =AF19+SUM(C19/$C$1,D19/$D$1,E19/$E$1,F19/$F$1,G19/$G$1,H19/$H$1,I19/$I$1,J19/$J$1,K19/$K$1,L19/$L$1,M19/$M$1,N19/$N$1,O19/$O$1,P19/$P$1,Q19/$Q$1,R19/$R$1,S19/$S$1,T19/$T$1,U19/$U$1,V19/$V$1,W19/$W$1,X19/$X$1,Y19/$Y$1,Z19/$Z$1,AA19/$AA$1,AB19/$AB$1,AC19/$AC$1,AD19/$AD$1,AE19/$AE$1)
A20: 212156 | B20: =VLOOKUP(A20,'IQ Equitizer'!$A$3:$B$12,2,0) | C20: =SUMIFS('BNY Unsettled Trades'!$AS:$AS,'BNY Unsettled Trades'!$N:$N,'Pending Failed Trade Matrix'!C$16,'BNY Unsettled Trades'!$X:$X,"Failing",'BNY Unsettled Trades'!$A:$A,'Pending Failed Trade Matrix'!$A20) | D20: =SUMIFS('BNY Unsettled Trades'!$AS:$AS,'BNY Unsettled Trades'!$N:$N,'Pending Failed Trade Matrix'!D$16,'BNY Unsettled Trades'!$X:$X,"Failing",'BNY Unsettled Trades'!$A:$A,'Pending Failed Trade Matrix'!$A20) | E20: =SUMIFS('BNY Unsettled Trades'!$AS:$AS,'BNY Unsettled Trades'!$N:$N,'Pending Failed Trade Matrix'!E$16,'BNY Unsettled Trades'!$X:$X,"Failing",'BNY Unsettled Trades'!$A:$A,'Pending Failed Trade Matrix'!$A20) | F20: =SUMIFS('BNY Unsettled Trades'!$AS:$AS,'BNY Unsettled Trades'!$N:$N,'Pending Failed Trade Matrix'!F$16,'BNY Unsettled Trades'!$X:$X,"Failing",'BNY Unsettled Trades'!$A:$A,'Pending Failed Trade Matrix'!$A20) | G20: =SUMIFS('BNY Unsettled Trades'!$AS:$AS,'BNY Unsettled Trades'!$N:$N,'Pending Failed Trade Matrix'!G$16,'BNY Unsettled Trades'!$X:$X,"Failing",'BNY Unsettled Trades'!$A:$A,'Pending Failed Trade Matrix'!$A20) | H20: =SUMIFS('BNY Unsettled Trades'!$AS:$AS,'BNY Unsettled Trades'!$N:$N,'Pending Failed Trade Matrix'!H$16,'BNY Unsettled Trades'!$X:$X,"Failing",'BNY Unsettled Trades'!$A:$A,'Pending Failed Trade Matrix'!$A20) | I20: =SUMIFS('BNY Unsettled Trades'!$AS:$AS,'BNY Unsettled Trades'!$N:$N,'Pending Failed Trade Matrix'!I$16,'BNY Unsettled Trades'!$X:$X,"Failing",'BNY Unsettled Trades'!$A:$A,'Pending Failed Trade Matrix'!$A20) | J20: =SUMIFS('BNY Unsettled Trades'!$AS:$AS,'BNY Unsettled Trades'!$N:$N,'Pending Failed Trade Matrix'!J$16,'BNY Unsettled Trades'!$X:$X,"Failing",'BNY Unsettled Trades'!$A:$A,'Pending Failed Trade Matrix'!$A20) | ... AF20: =SUMIFS('BNY Unsettled Trades'!$AS:$AS,'BNY Unsettled Trades'!$N:$N,'Pending Failed Trade Matrix'!AF$16,'BNY Unsettled Trades'!$X:$X,"Failing",'BNY Unsettled Trades'!$A:$A,'Pending Failed Trade Matrix'!$A20) | AG20: =AF20+SUM(C20/$C$1,D20/$D$1,E20/$E$1,F20/$F$1,G20/$G$1,H20/$H$1,I20/$I$1,J20/$J$1,K20/$K$1,L20/$L$1,M20/$M$1,N20/$N$1,O20/$O$1,P20/$P$1,Q20/$Q$1,R20/$R$1,S20/$S$1,T20/$T$1,U20/$U$1,V20/$V$1,W20/$W$1,X20/$X$1,Y20/$Y$1,Z20/$Z$1,AA20/$AA$1,AB20/$AB$1,AC20/$AC$1,AD20/$AD$1,AE20/$AE$1)
A21: 222959 | B21: =VLOOKUP(A21,'IQ Equitizer'!$A$3:$B$12,2,0) | C21: =SUMIFS('BNY Unsettled Trades'!$AS:$AS,'BNY Unsettled Trades'!$N:$N,'Pending Failed Trade Matrix'!C$16,'BNY Unsettled Trades'!$X:$X,"Failing",'BNY Unsettled Trades'!$A:$A,'Pending Failed Trade Matrix'!$A21) | D21: =SUMIFS('BNY Unsettled Trades'!$AS:$AS,'BNY Unsettled Trades'!$N:$N,'Pending Failed Trade Matrix'!D$16,'BNY Unsettled Trades'!$X:$X,"Failing",'BNY Unsettled Trades'!$A:$A,'Pending Failed Trade Matrix'!$A21) | E21: =SUMIFS('BNY Unsettled Trades'!$AS:$AS,'BNY Unsettled Trades'!$N:$N,'Pending Failed Trade Matrix'!E$16,'BNY Unsettled Trades'!$X:$X,"Failing",'BNY Unsettled Trades'!$A:$A,'Pending Failed Trade Matrix'!$A21) | F21: =SUMIFS('BNY Unsettled Trades'!$AS:$AS,'BNY Unsettled Trades'!$N:$N,'Pending Failed Trade Matrix'!F$16,'BNY Unsettled Trades'!$X:$X,"Failing",'BNY Unsettled Trades'!$A:$A,'Pending Failed Trade Matrix'!$A21) | G21: =SUMIFS('BNY Unsettled Trades'!$AS:$AS,'BNY Unsettled Trades'!$N:$N,'Pending Failed Trade Matrix'!G$16,'BNY Unsettled Trades'!$X:$X,"Failing",'BNY Unsettled Trades'!$A:$A,'Pending Failed Trade Matrix'!$A21) | H21: =SUMIFS('BNY Unsettled Trades'!$AS:$AS,'BNY Unsettled Trades'!$N:$N,'Pending Failed Trade Matrix'!H$16,'BNY Unsettled Trades'!$X:$X,"Failing",'BNY Unsettled Trades'!$A:$A,'Pending Failed Trade Matrix'!$A21) | I21: =SUMIFS('BNY Unsettled Trades'!$AS:$AS,'BNY Unsettled Trades'!$N:$N,'Pending Failed Trade Matrix'!I$16,'BNY Unsettled Trades'!$X:$X,"Failing",'BNY Unsettled Trades'!$A:$A,'Pending Failed Trade Matrix'!$A21) | J21: =SUMIFS('BNY Unsettled Trades'!$AS:$AS,'BNY Unsettled Trades'!$N:$N,'Pending Failed Trade Matrix'!J$16,'BNY Unsettled Trades'!$X:$X,"Failing",'BNY Unsettled Trades'!$A:$A,'Pending Failed Trade Matrix'!$A21) | ... AF21: =SUMIFS('BNY Unsettled Trades'!$AS:$AS,'BNY Unsettled Trades'!$N:$N,'Pending Failed Trade Matrix'!AF$16,'BNY Unsettled Trades'!$X:$X,"Failing",'BNY Unsettled Trades'!$A:$A,'Pending Failed Trade Matrix'!$A21) | AG21: =AF21+SUM(C21/$C$1,D21/$D$1,E21/$E$1,F21/$F$1,G21/$G$1,H21/$H$1,I21/$I$1,J21/$J$1,K21/$K$1,L21/$L$1,M21/$M$1,N21/$N$1,O21/$O$1,P21/$P$1,Q21/$Q$1,R21/$R$1,S21/$S$1,T21/$T$1,U21/$U$1,V21/$V$1,W21/$W$1,X21/$X$1,Y21/$Y$1,Z21/$Z$1,AA21/$AA$1,AB21/$AB$1,AC21/$AC$1,AD21/$AD$1,AE21/$AE$1)
A22: 222963 | B22: =VLOOKUP(A22,'IQ Equitizer'!$A$3:$B$12,2,0) | C22: =SUMIFS('BNY Unsettled Trades'!$AS:$AS,'BNY Unsettled Trades'!$N:$N,'Pending Failed Trade Matrix'!C$16,'BNY Unsettled Trades'!$X:$X,"Failing",'BNY Unsettled Trades'!$A:$A,'Pending Failed Trade Matrix'!$A22) | D22: =SUMIFS('BNY Unsettled Trades'!$AS:$AS,'BNY Unsettled Trades'!$N:$N,'Pending Failed Trade Matrix'!D$16,'BNY Unsettled Trades'!$X:$X,"Failing",'BNY Unsettled Trades'!$A:$A,'Pending Failed Trade Matrix'!$A22) | E22: =SUMIFS('BNY Unsettled Trades'!$AS:$AS,'BNY Unsettled Trades'!$N:$N,'Pending Failed Trade Matrix'!E$16,'BNY Unsettled Trades'!$X:$X,"Failing",'BNY Unsettled Trades'!$A:$A,'Pending Failed Trade Matrix'!$A22) | F22: =SUMIFS('BNY Unsettled Trades'!$AS:$AS,'BNY Unsettled Trades'!$N:$N,'Pending Failed Trade Matrix'!F$16,'BNY Unsettled Trades'!$X:$X,"Failing",'BNY Unsettled Trades'!$A:$A,'Pending Failed Trade Matrix'!$A22) | G22: =SUMIFS('BNY Unsettled Trades'!$AS:$AS,'BNY Unsettled Trades'!$N:$N,'Pending Failed Trade Matrix'!G$16,'BNY Unsettled Trades'!$X:$X,"Failing",'BNY Unsettled Trades'!$A:$A,'Pending Failed Trade Matrix'!$A22) | H22: =SUMIFS('BNY Unsettled Trades'!$AS:$AS,'BNY Unsettled Trades'!$N:$N,'Pending Failed Trade Matrix'!H$16,'BNY Unsettled Trades'!$X:$X,"Failing",'BNY Unsettled Trades'!$A:$A,'Pending Failed Trade Matrix'!$A22) | I22: =SUMIFS('BNY Unsettled Trades'!$AS:$AS,'BNY Unsettled Trades'!$N:$N,'Pending Failed Trade Matrix'!I$16,'BNY Unsettled Trades'!$X:$X,"Failing",'BNY Unsettled Trades'!$A:$A,'Pending Failed Trade Matrix'!$A22) | J22: =SUMIFS('BNY Unsettled Trades'!$AS:$AS,'BNY Unsettled Trades'!$N:$N,'Pending Failed Trade Matrix'!J$16,'BNY Unsettled Trades'!$X:$X,"Failing",'BNY Unsettled Trades'!$A:$A,'Pending Failed Trade Matrix'!$A22) | ... AF22: =SUMIFS('BNY Unsettled Trades'!$AS:$AS,'BNY Unsettled Trades'!$N:$N,'Pending Failed Trade Matrix'!AF$16,'BNY Unsettled Trades'!$X:$X,"Failing",'BNY Unsettled Trades'!$A:$A,'Pending Failed Trade Matrix'!$A22) | AG22: =AF22+SUM(C22/$C$1,D22/$D$1,E22/$E$1,F22/$F$1,G22/$G$1,H22/$H$1,I22/$I$1,J22/$J$1,K22/$K$1,L22/$L$1,M22/$M$1,N22/$N$1,O22/$O$1,P22/$P$1,Q22/$Q$1,R22/$R$1,S22/$S$1,T22/$T$1,U22/$U$1,V22/$V$1,W22/$W$1,X22/$X$1,Y22/$Y$1,Z22/$Z$1,AA22/$AA$1,AB22/$AB$1,AC22/$AC$1,AD22/$AD$1,AE22/$AE$1)
