Workbook

Sheet Eze Basket
A1: Prt | B1: Side | C1: Cust | D1: Trader | E1: Broker | F1: Note | G1: Amount | H1: Security | I1: Price | J1: Done | K1: COMM | N1: REFRESH BB CODES ACROSS SHEET | S1: BASKET DATE | T1: ='Enhanced Basket_AUTOLOAD'!C2 -> 0 | U1: =IF(INT(T1)=TODAY()-1,"Basket Date Good","CHECK BASKET DATE") -> CHECK BASKET DATE | X1: CHECKS | AA1: BASKET CU/RU | AB1: Basket Quantity | AC1: Ticker | AD1: Ticker + Country Code | AE1: Trading Currency | AF1: Settlement Country Code | AG1: Eze Ticker | AH1: Bloomberg Ticker | AI1: Is Eze & BBG Ticker Same | AJ1: ISIN | AK1: SEDOL | AL1: Basket Default Constituent Delivery Type | AM1: Fund+Ticker | AN1: In CIL Request | AO1: Eze Constituent Delivery Type
A2: ='Enhanced Basket_AUTOLOAD'!H2 -> 0 | B2: =IF(AA2>0,"BUY","SELL") -> SELL | C2: BONY | D2: =IF(AO2="In-Kind","INK","MT") -> MT | E2: =IF(D2="INK","MSCOP","") | F2: =IF(E2="MSCOP","INKIND LOAD","CIL LOAD") -> CIL LOAD | G2: =ABS(AA2*AB2) -> 0 | H2: =AG2 -> #N/A | I2: =_xll.BDP(AG2&" equity","crncy_adj_px_last","eqy_fund_crncy=usd") -> #NAME? | J2: =IF(D2="INK",G2,"") | S2: "+ or -": ex: -1 | U2: Standard | X2: If error check Ticker Mapping Tab to isloate issue | Y2: If Error Refresh BB across Sheet | Z2: Trade Importer should reflect kickouts | AA2: =IFERROR(VLOOKUP(A2,$R$4:$S$26,2,0),0) -> 0 | AB2: ='Enhanced Basket_AUTOLOAD'!T2 -> 0 | AC2: ='Enhanced Basket_AUTOLOAD'!M2 -> 0 | AD2: ='Enhanced Basket_AUTOLOAD'!L2 -> 0 | AE2: ='Enhanced Basket_AUTOLOAD'!Z2 -> 0 | AF2: ='Enhanced Basket_AUTOLOAD'!AB2 -> 0 | AG2: =VLOOKUP(AJ2,'Ticker Mapping'!$I$3:$M$6706,5,0) -> #N/A | AH2: =_xll.BDP(AK2&" SEDOL","TICKER_AND_EXCH_CODE") -> #NAME? | AI2: =IF(AG2=AH2,"Y","N") -> #N/A | AJ2: ='Enhanced Basket_AUTOLOAD'!P2 -> 0 | AK2: ='Enhanced Basket_AUTOLOAD'!Q2 -> 0 | AL2: ='Enhanced Basket_AUTOLOAD'!Y2 -> 0 | AM2: =A2&" "&AG2 -> #N/A | AN2: =IF(COUNTIF($Q$28:$Q$73,AM2),"YES","NO") -> NO | AO2: =IF(AND(AL2="In-Kind",AN2="NO"),"In-Kind","Cash-in-Lieu") -> Cash-in-Lieu
A3: ='Enhanced Basket_AUTOLOAD'!H3 -> 0 | B3: =IF(AA3>0,"BUY","SELL") -> SELL | C3: BONY | D3: =IF(AO3="In-Kind","INK","MT") -> MT | E3: =IF(D3="INK","MSCOP","") | F3: =IF(E3="MSCOP","INKIND LOAD","CIL LOAD") -> CIL LOAD | G3: =ABS(AA3*AB3) -> 0 | H3: =AG3 -> #N/A | I3: =_xll.BDP(AG3&" equity","crncy_adj_px_last","eqy_fund_crncy=usd") -> #NAME? | J3: =IF(D3="INK",G3,"") | S3: CU/RU | T3: Total Shares | U3: In-Kind | V3: Cash-in-Lieu | X3: Any #N/A (Ticker) | Y3: Any #N/A (PRICE) | Z3: Count of Names with Zero Shares in Basket | AA3: =IFERROR(VLOOKUP(A3,$R$4:$S$26,2,0),0) -> 0 | AB3: ='Enhanced Basket_AUTOLOAD'!T3 -> 0 | AC3: ='Enhanced Basket_AUTOLOAD'!M3 -> 0 | AD3: ='Enhanced Basket_AUTOLOAD'!L3 -> 0 | AE3: ='Enhanced Basket_AUTOLOAD'!Z3 -> 0 | AF3: ='Enhanced Basket_AUTOLOAD'!AB3 -> 0 | AG3: =VLOOKUP(AJ3,'Ticker Mapping'!$I$3:$M$6706,5,0) -> #N/A | AH3: =_xll.BDP(AK3&" SEDOL","TICKER_AND_EXCH_CODE") -> #NAME? | AI3: =IF(AG3=AH3,"Y","N") -> #N/A | AJ3: ='Enhanced Basket_AUTOLOAD'!P3 -> 0 | AK3: ='Enhanced Basket_AUTOLOAD'!Q3 -> 0 | AL3: ='Enhanced Basket_AUTOLOAD'!Y3 -> 0 | AM3: =A3&" "&AG3 -> #N/A | AN3: =IF(COUNTIF($Q$28:$Q$73,AM3),"YES","NO") -> NO | AO3: =IF(AND(AL3="In-Kind",AN3="NO"),"In-Kind","Cash-in-Lieu") -> Cash-in-Lieu
A4: ='Enhanced Basket_AUTOLOAD'!H4 -> 0 | B4: =IF(AA4>0,"BUY","SELL") -> SELL | C4: BONY | D4: =IF(AO4="In-Kind","INK","MT") -> MT | E4: =IF(D4="INK","MSCOP","") | F4: =IF(E4="MSCOP","INKIND LOAD","CIL LOAD") -> CIL LOAD | G4: =ABS(AA4*AB4) -> 0 | H4: =AG4 -> #N/A | I4: =_xll.BDP(AG4&" equity","crncy_adj_px_last","eqy_fund_crncy=usd") -> #NAME? | J4: =IF(D4="INK",G4,"") | R4: HART | T4: =SUMIF($A:$A,R4,$G:$G) -> 0 | U4: =SUMIFS($G:$G,$AO:$AO,$U$3,$A:$A,R4) -> 0 | V4: =SUMIFS($G:$G,$AO:$AO,$V$3,$A:$A,R4) -> 0 | X4: =IF(SUMPRODUCT(('Ticker Mapping'!F:F=R4)*+ISNA('Ticker Mapping'!M:M))>0,"Yes","No") -> No | Y4: =IF(SUMPRODUCT((A:A=R4)*+ISNA(I:I))>0,"Yes","No") -> No | Z4: =IF(S4<>"",COUNTIFS(A:A,R4,G:G,0),"") | AA4: =IFERROR(VLOOKUP(A4,$R$4:$S$26,2,0),0) -> 0 | AB4: ='Enhanced Basket_AUTOLOAD'!T4 -> 0 | AC4: ='Enhanced Basket_AUTOLOAD'!M4 -> 0 | AD4: ='Enhanced Basket_AUTOLOAD'!L4 -> 0 | AE4: ='Enhanced Basket_AUTOLOAD'!Z4 -> 0 | AF4: ='Enhanced Basket_AUTOLOAD'!AB4 -> 0 | AG4: =VLOOKUP(AJ4,'Ticker Mapping'!$I$3:$M$6706,5,0) -> #N/A | AH4: =_xll.BDP(AK4&" SEDOL","TICKER_AND_EXCH_CODE") -> #NAME? | AI4: =IF(AG4=AH4,"Y","N") -> #N/A | AJ4: ='Enhanced Basket_AUTOLOAD'!P4 -> 0 | AK4: ='Enhanced Basket_AUTOLOAD'!Q4 -> 0 | AL4: ='Enhanced Basket_AUTOLOAD'!Y4 -> 0 | AM4: =A4&" "&AG4 -> #N/A | AN4: =IF(COUNTIF($Q$28:$Q$73,AM4),"YES","NO") -> NO | AO4: =IF(AND(AL4="In-Kind",AN4="NO"),"In-Kind","Cash-in-Lieu") -> Cash-in-Lieu
A5: ='Enhanced Basket_AUTOLOAD'!H5 -> 0 | B5: =IF(AA5>0,"BUY","SELL") -> SELL | C5: BONY | D5: =IF(AO5="In-Kind","INK","MT") -> MT | E5: =IF(D5="INK","MSCOP","") | F5: =IF(E5="MSCOP","INKIND LOAD","CIL LOAD") -> CIL LOAD | G5: =ABS(AA5*AB5) -> 0 | H5: =AG5 -> #N/A | I5: =_xll.BDP(AG5&" equity","crncy_adj_px_last","eqy_fund_crncy=usd") -> #NAME? | J5: =IF(D5="INK",G5,"") | R5: HFXI | T5: =SUMIF($A:$A,R5,$G:$G) -> 0 | U5: =SUMIFS($G:$G,$AO:$AO,$U$3,$A:$A,R5) -> 0 | V5: =SUMIFS($G:$G,$AO:$AO,$V$3,$A:$A,R5) -> 0 | X5: =IF(SUMPRODUCT(('Ticker Mapping'!F:F=R5)*+ISNA('Ticker Mapping'!M:M))>0,"Yes","No") -> No | Y5: =IF(SUMPRODUCT((A:A=R5)*+ISNA(I:I))>0,"Yes","No") -> No | Z5: =IF(S5<>"",COUNTIFS(A:A,R5,G:G,0),"") | AA5: =IFERROR(VLOOKUP(A5,$R$4:$S$26,2,0),0) -> 0 | AB5: ='Enhanced Basket_AUTOLOAD'!T5 -> 0 | AC5: ='Enhanced Basket_AUTOLOAD'!M5 -> 0 | AD5: ='Enhanced Basket_AUTOLOAD'!L5 -> 0 | AE5: ='Enhanced Basket_AUTOLOAD'!Z5 -> 0 | AF5: ='Enhanced Basket_AUTOLOAD'!AB5 -> 0 | AG5: =VLOOKUP(AJ5,'Ticker Mapping'!$I$3:$M$6706,5,0) -> #N/A | AH5: =_xll.BDP(AK5&" SEDOL","TICKER_AND_EXCH_CODE") -> #NAME? | AI5: =IF(AG5=AH5,"Y","N") -> #N/A | AJ5: ='Enhanced Basket_AUTOLOAD'!P5 -> 0 | AK5: ='Enhanced Basket_AUTOLOAD'!Q5 -> 0 | AL5: ='Enhanced Basket_AUTOLOAD'!Y5 -> 0 | AM5: =A5&" "&AG5 -> #N/A | AN5: =IF(COUNTIF($Q$28:$Q$73,AM5),"YES","NO") -> NO | AO5: =IF(AND(AL5="In-Kind",AN5="NO"),"In-Kind","Cash-in-Lieu") -> Cash-in-Lieu
A6: ='Enhanced Basket_AUTOLOAD'!H6 -> 0 | B6: =IF(AA6>0,"BUY","SELL") -> SELL | C6: BONY | D6: =IF(AO6="In-Kind","INK","MT") -> MT | E6: =IF(D6="INK","MSCOP","") | F6: =IF(E6="MSCOP","INKIND LOAD","CIL LOAD") -> CIL LOAD | G6: =ABS(AA6*AB6) -> 0 | H6: =AG6 -> #N/A | I6: =_xll.BDP(AG6&" equity","crncy_adj_px_last","eqy_fund_crncy=usd") -> #NAME? | J6: =IF(D6="INK",G6,"") | R6: IQSI | T6: =SUMIF($A:$A,R6,$G:$G) -> 0 | U6: =SUMIFS($G:$G,$AO:$AO,$U$3,$A:$A,R6) -> 0 | V6: =SUMIFS($G:$G,$AO:$AO,$V$3,$A:$A,R6) -> 0 | X6: =IF(SUMPRODUCT(('Ticker Mapping'!F:F=R6)*+ISNA('Ticker Mapping'!M:M))>0,"Yes","No") -> No | Y6: =IF(SUMPRODUCT((A:A=R6)*+ISNA(I:I))>0,"Yes","No") -> No | Z6: =IF(S6<>"",COUNTIFS(A:A,R6,G:G,0),"") | AA6: =IFERROR(VLOOKUP(A6,$R$4:$S$26,2,0),0) -> 0 | AB6: ='Enhanced Basket_AUTOLOAD'!T6 -> 0 | AC6: ='Enhanced Basket_AUTOLOAD'!M6 -> 0 | AD6: ='Enhanced Basket_AUTOLOAD'!L6 -> 0 | AE6: ='Enhanced Basket_AUTOLOAD'!Z6 -> 0 | AF6: ='Enhanced Basket_AUTOLOAD'!AB6 -> 0 | AG6: =VLOOKUP(AJ6,'Ticker Mapping'!$I$3:$M$6706,5,0) -> #N/A | AH6: =_xll.BDP(AK6&" SEDOL","TICKER_AND_EXCH_CODE") -> #NAME? | AI6: =IF(AG6=AH6,"Y","N") -> #N/A | AJ6: ='Enhanced Basket_AUTOLOAD'!P6 -> 0 | AK6: ='Enhanced Basket_AUTOLOAD'!Q6 -> 0 | AL6: ='Enhanced Basket_AUTOLOAD'!Y6 -> 0 | AM6: =A6&" "&AG6 -> #N/A | AN6: =IF(COUNTIF($Q$28:$Q$73,AM6),"YES","NO") -> NO | AO6: =IF(AND(AL6="In-Kind",AN6="NO"),"In-Kind","Cash-in-Lieu") -> Cash-in-Lieu
A7: ='Enhanced Basket_AUTOLOAD'!H7 -> 0 | B7: =IF(AA7>0,"BUY","SELL") -> SELL | C7: BONY | D7: =IF(AO7="In-Kind","INK","MT") -> MT | E7: =IF(D7="INK","MSCOP","") | F7: =IF(E7="MSCOP","INKIND LOAD","CIL LOAD") -> CIL LOAD | G7: =ABS(AA7*AB7) -> 0 | H7: =AG7 -> #N/A | I7: =_xll.BDP(AG7&" equity","crncy_adj_px_last","eqy_fund_crncy=usd") -> #NAME? | J7: =IF(D7="INK",G7,"") | R7: IQSU | T7: =SUMIF($A:$A,R7,$G:$G) -> 0 | U7: =SUMIFS($G:$G,$AO:$AO,$U$3,$A:$A,R7) -> 0 | V7: =SUMIFS($G:$G,$AO:$AO,$V$3,$A:$A,R7) -> 0 | X7: =IF(SUMPRODUCT(('Ticker Mapping'!F:F=R7)*+ISNA('Ticker Mapping'!M:M))>0,"Yes","No") -> No | Y7: =IF(SUMPRODUCT((A:A=R7)*+ISNA(I:I))>0,"Yes","No") -> No | Z7: =IF(S7<>"",COUNTIFS(A:A,R7,G:G,0),"") | AA7: =IFERROR(VLOOKUP(A7,$R$4:$S$26,2,0),0) -> 0 | AB7: ='Enhanced Basket_AUTOLOAD'!T7 -> 0 | AC7: ='Enhanced Basket_AUTOLOAD'!M7 -> 0 | AD7: ='Enhanced Basket_AUTOLOAD'!L7 -> 0 | AE7: ='Enhanced Basket_AUTOLOAD'!Z7 -> 0 | AF7: ='Enhanced Basket_AUTOLOAD'!AB7 -> 0 | AG7: =VLOOKUP(AJ7,'Ticker Mapping'!$I$3:$M$6706,5,0) -> #N/A | AH7: =_xll.BDP(AK7&" SEDOL","TICKER_AND_EXCH_CODE") -> #NAME? | AI7: =IF(AG7=AH7,"Y","N") -> #N/A | AJ7: ='Enhanced Basket_AUTOLOAD'!P7 -> 0 | AK7: ='Enhanced Basket_AUTOLOAD'!Q7 -> 0 | AL7: ='Enhanced Basket_AUTOLOAD'!Y7 -> 0 | AM7: =A7&" "&AG7 -> #N/A | AN7: =IF(COUNTIF($Q$28:$Q$73,AM7),"YES","NO") -> NO | AO7: =IF(AND(AL7="In-Kind",AN7="NO"),"In-Kind","Cash-in-Lieu") -> Cash-in-Lieu
A8: ='Enhanced Basket_AUTOLOAD'!H8 -> 0 | B8: =IF(AA8>0,"BUY","SELL") -> SELL | C8: BONY | D8: =IF(AO8="In-Kind","INK","MT") -> MT | E8: =IF(D8="INK","MSCOP","") | F8: =IF(E8="MSCOP","INKIND LOAD","CIL LOAD") -> CIL LOAD | G8: =ABS(AA8*AB8) -> 0 | H8: =AG8 -> #N/A | I8: =_xll.BDP(AG8&" equity","crncy_adj_px_last","eqy_fund_crncy=usd") -> #NAME? | J8: =IF(D8="INK",G8,"") | R8: MNA | T8: =SUMIF($A:$A,R8,$G:$G) -> 0 | U8: =SUMIFS($G:$G,$AO:$AO,$U$3,$A:$A,R8) -> 0 | V8: =SUMIFS($G:$G,$AO:$AO,$V$3,$A:$A,R8) -> 0 | X8: =IF(SUMPRODUCT(('Ticker Mapping'!F:F=R8)*+ISNA('Ticker Mapping'!M:M))>0,"Yes","No") -> No | Y8: =IF(SUMPRODUCT((A:A=R8)*+ISNA(I:I))>0,"Yes","No") -> No | Z8: =IF(S8<>"",COUNTIFS(A:A,R8,G:G,0),"") | AA8: =IFERROR(VLOOKUP(A8,$R$4:$S$26,2,0),0) -> 0 | AB8: ='Enhanced Basket_AUTOLOAD'!T8 -> 0 | AC8: ='Enhanced Basket_AUTOLOAD'!M8 -> 0 | AD8: ='Enhanced Basket_AUTOLOAD'!L8 -> 0 | AE8: ='Enhanced Basket_AUTOLOAD'!Z8 -> 0 | AF8: ='Enhanced Basket_AUTOLOAD'!AB8 -> 0 | AG8: =VLOOKUP(AJ8,'Ticker Mapping'!$I$3:$M$6706,5,0) -> #N/A | AH8: =_xll.BDP(AK8&" SEDOL","TICKER_AND_EXCH_CODE") -> #NAME? | AI8: =IF(AG8=AH8,"Y","N") -> #N/A | AJ8: ='Enhanced Basket_AUTOLOAD'!P8 -> 0 | AK8: ='Enhanced Basket_AUTOLOAD'!Q8 -> 0 | AL8: ='Enhanced Basket_AUTOLOAD'!Y8 -> 0 | AM8: =A8&" "&AG8 -> #N/A | AN8: =IF(COUNTIF($Q$28:$Q$73,AM8),"YES","NO") -> NO | AO8: =IF(AND(AL8="In-Kind",AN8="NO"),"In-Kind","Cash-in-Lieu") -> Cash-in-Lieu
A9: ='Enhanced Basket_AUTOLOAD'!H9 -> 0 | B9: =IF(AA9>0,"BUY","SELL") -> SELL | C9: BONY | D9: =IF(AO9="In-Kind","INK","MT") -> MT | E9: =IF(D9="INK","MSCOP","") | F9: =IF(E9="MSCOP","INKIND LOAD","CIL LOAD") -> CIL LOAD | G9: =ABS(AA9*AB9) -> 0 | H9: =AG9 -> #N/A | I9: =_xll.BDP(AG9&" equity","crncy_adj_px_last","eqy_fund_crncy=usd") -> #NAME? | J9: =IF(D9="INK",G9,"") | R9: QAI | T9: =SUMIF($A:$A,R9,$G:$G) -> 0 | U9: =SUMIFS($G:$G,$AO:$AO,$U$3,$A:$A,R9) -> 0 | V9: =SUMIFS($G:$G,$AO:$AO,$V$3,$A:$A,R9) -> 0 | X9: =IF(SUMPRODUCT(('Ticker Mapping'!F:F=R9)*+ISNA('Ticker Mapping'!M:M))>0,"Yes","No") -> No | Y9: =IF(SUMPRODUCT((A:A=R9)*+ISNA(I:I))>0,"Yes","No") -> No | Z9: =IF(S9<>"",COUNTIFS(A:A,R9,G:G,0),"") | AA9: =IFERROR(VLOOKUP(A9,$R$4:$S$26,2,0),0) -> 0 | AB9: ='Enhanced Basket_AUTOLOAD'!T9 -> 0 | AC9: ='Enhanced Basket_AUTOLOAD'!M9 -> 0 | AD9: ='Enhanced Basket_AUTOLOAD'!L9 -> 0 | AE9: ='Enhanced Basket_AUTOLOAD'!Z9 -> 0 | AF9: ='Enhanced Basket_AUTOLOAD'!AB9 -> 0 | AG9: =VLOOKUP(AJ9,'Ticker Mapping'!$I$3:$M$6706,5,0) -> #N/A | AH9: =_xll.BDP(AK9&" SEDOL","TICKER_AND_EXCH_CODE") -> #NAME? | AI9: =IF(AG9=AH9,"Y","N") -> #N/A | AJ9: ='Enhanced Basket_AUTOLOAD'!P9 -> 0 | AK9: ='Enhanced Basket_AUTOLOAD'!Q9 -> 0 | AL9: ='Enhanced Basket_AUTOLOAD'!Y9 -> 0 | AM9: =A9&" "&AG9 -> #N/A | AN9: =IF(COUNTIF($Q$28:$Q$73,AM9),"YES","NO") -> NO | AO9: =IF(AND(AL9="In-Kind",AN9="NO"),"In-Kind","Cash-in-Lieu") -> Cash-in-Lieu
A10: ='Enhanced Basket_AUTOLOAD'!H10 -> 0 | B10: =IF(AA10>0,"BUY","SELL") -> SELL | C10: BONY | D10: =IF(AO10="In-Kind","INK","MT") -> MT | E10: =IF(D10="INK","MSCOP","") | F10: =IF(E10="MSCOP","INKIND LOAD","CIL LOAD") -> CIL LOAD | G10: =ABS(AA10*AB10) -> 0 | H10: =AG10 -> #N/A | I10: =_xll.BDP(AG10&" equity","crncy_adj_px_last","eqy_fund_crncy=usd") -> #NAME? | J10: =IF(D10="INK",G10,"") | R10: LRND | T10: =SUMIF($A:$A,R10,$G:$G) -> 0 | U10: =SUMIFS($G:$G,$AO:$AO,$U$3,$A:$A,R10) -> 0 | V10: =SUMIFS($G:$G,$AO:$AO,$V$3,$A:$A,R10) -> 0 | X10: =IF(SUMPRODUCT(('Ticker Mapping'!F:F=R10)*+ISNA('Ticker Mapping'!M:M))>0,"Yes","No") -> No | Y10: =IF(SUMPRODUCT((A:A=R10)*+ISNA(I:I))>0,"Yes","No") -> No | Z10: =IF(S10<>"",COUNTIFS(A:A,R10,G:G,0),"") | AA10: =IFERROR(VLOOKUP(A10,$R$4:$S$26,2,0),0) -> 0 | AB10: ='Enhanced Basket_AUTOLOAD'!T10 -> 0 | AC10: ='Enhanced Basket_AUTOLOAD'!M10 -> 0 | AD10: ='Enhanced Basket_AUTOLOAD'!L10 -> 0 | AE10: ='Enhanced Basket_AUTOLOAD'!Z10 -> 0 | AF10: ='Enhanced Basket_AUTOLOAD'!AB10 -> 0 | AG10: =VLOOKUP(AJ10,'Ticker Mapping'!$I$3:$M$6706,5,0) -> #N/A | AH10: =_xll.BDP(AK10&" SEDOL","TICKER_AND_EXCH_CODE") -> #NAME? | AI10: =IF(AG10=AH10,"Y","N") -> #N/A | AJ10: ='Enhanced Basket_AUTOLOAD'!P10 -> 0 | AK10: ='Enhanced Basket_AUTOLOAD'!Q10 -> 0 | AL10: ='Enhanced Basket_AUTOLOAD'!Y10 -> 0 | AM10: =A10&" "&AG10 -> #N/A | AN10: =IF(COUNTIF($Q$28:$Q$73,AM10),"YES","NO") -> NO | AO10: =IF(AND(AL10="In-Kind",AN10="NO"),"In-Kind","Cash-in-Lieu") -> Cash-in-Lieu
A11: ='Enhanced Basket_AUTOLOAD'!H11 -> 0 | B11: =IF(AA11>0,"BUY","SELL") -> SELL | C11: BONY | D11: =IF(AO11="In-Kind","INK","MT") -> MT | E11: =IF(D11="INK","MSCOP","") | F11: =IF(E11="MSCOP","INKIND LOAD","CIL LOAD") -> CIL LOAD | G11: =ABS(AA11*AB11) -> 0 | H11: =AG11 -> #N/A | I11: =_xll.BDP(AG11&" equity","crncy_adj_px_last","eqy_fund_crncy=usd") -> #NAME? | J11: =IF(D11="INK",G11,"") | R11: WRND | T11: =SUMIF($A:$A,R11,$G:$G) -> 0 | U11: =SUMIFS($G:$G,$AO:$AO,$U$3,$A:$A,R11) -> 0 | V11: =SUMIFS($G:$G,$AO:$AO,$V$3,$A:$A,R11) -> 0 | X11: =IF(SUMPRODUCT(('Ticker Mapping'!F:F=R11)*+ISNA('Ticker Mapping'!M:M))>0,"Yes","No") -> No | Y11: =IF(SUMPRODUCT((A:A=R11)*+ISNA(I:I))>0,"Yes","No") -> No | Z11: =IF(S11<>"",COUNTIFS(A:A,R11,G:G,0),"") | AA11: =IFERROR(VLOOKUP(A11,$R$4:$S$26,2,0),0) -> 0 | AB11: ='Enhanced Basket_AUTOLOAD'!T11 -> 0 | AC11: ='Enhanced Basket_AUTOLOAD'!M11 -> 0 | AD11: ='Enhanced Basket_AUTOLOAD'!L11 -> 0 | AE11: ='Enhanced Basket_AUTOLOAD'!Z11 -> 0 | AF11: ='Enhanced Basket_AUTOLOAD'!AB11 -> 0 | AG11: =VLOOKUP(AJ11,'Ticker Mapping'!$I$3:$M$6706,5,0) -> #N/A | AH11: =_xll.BDP(AK11&" SEDOL","TICKER_AND_EXCH_CODE") -> #NAME? | AI11: =IF(AG11=AH11,"Y","N") -> #N/A | AJ11: ='Enhanced Basket_AUTOLOAD'!P11 -> 0 | AK11: ='Enhanced Basket_AUTOLOAD'!Q11 -> 0 | AL11: ='Enhanced Basket_AUTOLOAD'!Y11 -> 0 | AM11: =A11&" "&AG11 -> #N/A | AN11: =IF(COUNTIF($Q$28:$Q$73,AM11),"YES","NO") -> NO | AO11: =IF(AND(AL11="In-Kind",AN11="NO"),"In-Kind","Cash-in-Lieu") -> Cash-in-Lieu
A12: ='Enhanced Basket_AUTOLOAD'!H12 -> 0 | B12: =IF(AA12>0,"BUY","SELL") -> SELL | C12: BONY | D12: =IF(AO12="In-Kind","INK","MT") -> MT | E12: =IF(D12="INK","MSCOP","") | F12: =IF(E12="MSCOP","INKIND LOAD","CIL LOAD") -> CIL LOAD | G12: =ABS(AA12*AB12) -> 0 | H12: =AG12 -> #N/A | I12: =_xll.BDP(AG12&" equity","crncy_adj_px_last","eqy_fund_crncy=usd") -> #NAME? | J12: =IF(D12="INK",G12,"") | R12: IQSM | T12: =SUMIF($A:$A,R12,$G:$G) -> 0 | U12: =SUMIFS($G:$G,$AO:$AO,$U$3,$A:$A,R12) -> 0 | V12: =SUMIFS($G:$G,$AO:$AO,$V$3,$A:$A,R12) -> 0 | X12: =IF(SUMPRODUCT(('Ticker Mapping'!F:F=R12)*+ISNA('Ticker Mapping'!M:M))>0,"Yes","No") -> No | Y12: =IF(SUMPRODUCT((A:A=R12)*+ISNA(I:I))>0,"Yes","No") -> No | Z12: =IF(S12<>"",COUNTIFS(A:A,R12,G:G,0),"") | AA12: =IFERROR(VLOOKUP(A12,$R$4:$S$26,2,0),0) -> 0 | AB12: ='Enhanced Basket_AUTOLOAD'!T12 -> 0 | AC12: ='Enhanced Basket_AUTOLOAD'!M12 -> 0 | AD12: ='Enhanced Basket_AUTOLOAD'!L12 -> 0 | AE12: ='Enhanced Basket_AUTOLOAD'!Z12 -> 0 | AF12: ='Enhanced Basket_AUTOLOAD'!AB12 -> 0 | AG12: =VLOOKUP(AJ12,'Ticker Mapping'!$I$3:$M$6706,5,0) -> #N/A | AH12: =_xll.BDP(AK12&" SEDOL","TICKER_AND_EXCH_CODE") -> #NAME? | AI12: =IF(AG12=AH12,"Y","N") -> #N/A | AJ12: ='Enhanced Basket_AUTOLOAD'!P12 -> 0 | AK12: ='Enhanced Basket_AUTOLOAD'!Q12 -> 0 | AL12: ='Enhanced Basket_AUTOLOAD'!Y12 -> 0 | AM12: =A12&" "&AG12 -> #N/A | AN12: =IF(COUNTIF($Q$28:$Q$73,AM12),"YES","NO") -> NO | AO12: =IF(AND(AL12="In-Kind",AN12="NO"),"In-Kind","Cash-in-Lieu") -> Cash-in-Lieu
A13: ='Enhanced Basket_AUTOLOAD'!H13 -> 0 | B13: =IF(AA13>0,"BUY","SELL") -> SELL | C13: BONY | D13: =IF(AO13="In-Kind","INK","MT") -> MT | E13: =IF(D13="INK","MSCOP","") | F13: =IF(E13="MSCOP","INKIND LOAD","CIL LOAD") -> CIL LOAD | G13: =ABS(AA13*AB13) -> 0 | H13: =AG13 -> #N/A | I13: =_xll.BDP(AG13&" equity","crncy_adj_px_last","eqy_fund_crncy=usd") -> #NAME? | J13: =IF(D13="INK",G13,"") | AA13: =IFERROR(VLOOKUP(A13,$R$4:$S$26,2,0),0) -> 0 | AB13: ='Enhanced Basket_AUTOLOAD'!T13 -> 0 | AC13: ='Enhanced Basket_AUTOLOAD'!M13 -> 0 | AD13: ='Enhanced Basket_AUTOLOAD'!L13 -> 0 | AE13: ='Enhanced Basket_AUTOLOAD'!Z13 -> 0 | AF13: ='Enhanced Basket_AUTOLOAD'!AB13 -> 0 | AG13: =VLOOKUP(AJ13,'Ticker Mapping'!$I$3:$M$6706,5,0) -> #N/A | AH13: =_xll.BDP(AK13&" SEDOL","TICKER_AND_EXCH_CODE") -> #NAME? | AI13: =IF(AG13=AH13,"Y","N") -> #N/A | AJ13: ='Enhanced Basket_AUTOLOAD'!P13 -> 0 | AK13: ='Enhanced Basket_AUTOLOAD'!Q13 -> 0 | AL13: ='Enhanced Basket_AUTOLOAD'!Y13 -> 0 | AM13: =A13&" "&AG13 -> #N/A | AN13: =IF(COUNTIF($Q$28:$Q$73,AM13),"YES","NO") -> NO | AO13: =IF(AND(AL13="In-Kind",AN13="NO"),"In-Kind","Cash-in-Lieu") -> Cash-in-Lieu
A14: ='Enhanced Basket_AUTOLOAD'!H14 -> 0 | B14: =IF(AA14>0,"BUY","SELL") -> SELL | C14: BONY | D14: =IF(AO14="In-Kind","INK","MT") -> MT | E14: =IF(D14="INK","MSCOP","") | F14: =IF(E14="MSCOP","INKIND LOAD","CIL LOAD") -> CIL LOAD | G14: =ABS(AA14*AB14) -> 0 | H14: =AG14 -> #N/A | I14: =_xll.BDP(AG14&" equity","crncy_adj_px_last","eqy_fund_crncy=usd") -> #NAME? | J14: =IF(D14="INK",G14,"") | AA14: =IFERROR(VLOOKUP(A14,$R$4:$S$26,2,0),0) -> 0 | AB14: ='Enhanced Basket_AUTOLOAD'!T14 -> 0 | AC14: ='Enhanced Basket_AUTOLOAD'!M14 -> 0 | AD14: ='Enhanced Basket_AUTOLOAD'!L14 -> 0 | AE14: ='Enhanced Basket_AUTOLOAD'!Z14 -> 0 | AF14: ='Enhanced Basket_AUTOLOAD'!AB14 -> 0 | AG14: =VLOOKUP(AJ14,'Ticker Mapping'!$I$3:$M$6706,5,0) -> #N/A | AH14: =_xll.BDP(AK14&" SEDOL","TICKER_AND_EXCH_CODE") -> #NAME? | AI14: =IF(AG14=AH14,"Y","N") -> #N/A | AJ14: ='Enhanced Basket_AUTOLOAD'!P14 -> 0 | AK14: ='Enhanced Basket_AUTOLOAD'!Q14 -> 0 | AL14: ='Enhanced Basket_AUTOLOAD'!Y14 -> 0 | AM14: =A14&" "&AG14 -> #N/A | AN14: =IF(COUNTIF($Q$28:$Q$73,AM14),"YES","NO") -> NO | AO14: =IF(AND(AL14="In-Kind",AN14="NO"),"In-Kind","Cash-in-Lieu") -> Cash-in-Lieu
A15: ='Enhanced Basket_AUTOLOAD'!H15 -> 0 | B15: =IF(AA15>0,"BUY","SELL") -> SELL | C15: BONY | D15: =IF(AO15="In-Kind","INK","MT") -> MT | E15: =IF(D15="INK","MSCOP","") | F15: =IF(E15="MSCOP","INKIND LOAD","CIL LOAD") -> CIL LOAD | G15: =ABS(AA15*AB15) -> 0 | H15: =AG15 -> #N/A | I15: =_xll.BDP(AG15&" equity","crncy_adj_px_last","eqy_fund_crncy=usd") -> #NAME? | J15: =IF(D15="INK",G15,"") | AA15: =IFERROR(VLOOKUP(A15,$R$4:$S$26,2,0),0) -> 0 | AB15: ='Enhanced Basket_AUTOLOAD'!T15 -> 0 | AC15: ='Enhanced Basket_AUTOLOAD'!M15 -> 0 | AD15: ='Enhanced Basket_AUTOLOAD'!L15 -> 0 | AE15: ='Enhanced Basket_AUTOLOAD'!Z15 -> 0 | AF15: ='Enhanced Basket_AUTOLOAD'!AB15 -> 0 | AG15: =VLOOKUP(AJ15,'Ticker Mapping'!$I$3:$M$6706,5,0) -> #N/A | AH15: =_xll.BDP(AK15&" SEDOL","TICKER_AND_EXCH_CODE") -> #NAME? | AI15: =IF(AG15=AH15,"Y","N") -> #N/A | AJ15: ='Enhanced Basket_AUTOLOAD'!P15 -> 0 | AK15: ='Enhanced Basket_AUTOLOAD'!Q15 -> 0 | AL15: ='Enhanced Basket_AUTOLOAD'!Y15 -> 0 | AM15: =A15&" "&AG15 -> #N/A | AN15: =IF(COUNTIF($Q$28:$Q$73,AM15),"YES","NO") -> NO | AO15: =IF(AND(AL15="In-Kind",AN15="NO"),"In-Kind","Cash-in-Lieu") -> Cash-in-Lieu
A16: ='Enhanced Basket_AUTOLOAD'!H16 -> 0 | B16: =IF(AA16>0,"BUY","SELL") -> SELL | C16: BONY | D16: =IF(AO16="In-Kind","INK","MT") -> MT | E16: =IF(D16="INK","MSCOP","") | F16: =IF(E16="MSCOP","INKIND LOAD","CIL LOAD") -> CIL LOAD | G16: =ABS(AA16*AB16) -> 0 | H16: =AG16 -> #N/A | I16: =_xll.BDP(AG16&" equity","crncy_adj_px_last","eqy_fund_crncy=usd") -> #NAME? | J16: =IF(D16="INK",G16,"") | AA16: =IFERROR(VLOOKUP(A16,$R$4:$S$26,2,0),0) -> 0 | AB16: ='Enhanced Basket_AUTOLOAD'!T16 -> 0 | AC16: ='Enhanced Basket_AUTOLOAD'!M16 -> 0 | AD16: ='Enhanced Basket_AUTOLOAD'!L16 -> 0 | AE16: ='Enhanced Basket_AUTOLOAD'!Z16 -> 0 | AF16: ='Enhanced Basket_AUTOLOAD'!AB16 -> 0 | AG16: =VLOOKUP(AJ16,'Ticker Mapping'!$I$3:$M$6706,5,0) -> #N/A | AH16: =_xll.BDP(AK16&" SEDOL","TICKER_AND_EXCH_CODE") -> #NAME? | AI16: =IF(AG16=AH16,"Y","N") -> #N/A | AJ16: ='Enhanced Basket_AUTOLOAD'!P16 -> 0 | AK16: ='Enhanced Basket_AUTOLOAD'!Q16 -> 0 | AL16: ='Enhanced Basket_AUTOLOAD'!Y16 -> 0 | AM16: =A16&" "&AG16 -> #N/A | AN16: =IF(COUNTIF($Q$28:$Q$73,AM16),"YES","NO") -> NO | AO16: =IF(AND(AL16="In-Kind",AN16="NO"),"In-Kind","Cash-in-Lieu") -> Cash-in-Lieu
A17: ='Enhanced Basket_AUTOLOAD'!H17 -> 0 | B17: =IF(AA17>0,"BUY","SELL") -> SELL | C17: BONY | D17: =IF(AO17="In-Kind","INK","MT") -> MT | E17: =IF(D17="INK","MSCOP","") | F17: =IF(E17="MSCOP","INKIND LOAD","CIL LOAD") -> CIL LOAD | G17: =ABS(AA17*AB17) -> 0 | H17: =AG17 -> #N/A | I17: =_xll.BDP(AG17&" equity","crncy_adj_px_last","eqy_fund_crncy=usd") -> #NAME? | J17: =IF(D17="INK",G17,"") | AA17: =IFERROR(VLOOKUP(A17,$R$4:$S$26,2,0),0) -> 0 | AB17: ='Enhanced Basket_AUTOLOAD'!T17 -> 0 | AC17: ='Enhanced Basket_AUTOLOAD'!M17 -> 0 | AD17: ='Enhanced Basket_AUTOLOAD'!L17 -> 0 | AE17: ='Enhanced Basket_AUTOLOAD'!Z17 -> 0 | AF17: ='Enhanced Basket_AUTOLOAD'!AB17 -> 0 | AG17: =VLOOKUP(AJ17,'Ticker Mapping'!$I$3:$M$6706,5,0) -> #N/A | AH17: =_xll.BDP(AK17&" SEDOL","TICKER_AND_EXCH_CODE") -> #NAME? | AI17: =IF(AG17=AH17,"Y","N") -> #N/A | AJ17: ='Enhanced Basket_AUTOLOAD'!P17 -> 0 | AK17: ='Enhanced Basket_AUTOLOAD'!Q17 -> 0 | AL17: ='Enhanced Basket_AUTOLOAD'!Y17 -> 0 | AM17: =A17&" "&AG17 -> #N/A | AN17: =IF(COUNTIF($Q$28:$Q$73,AM17),"YES","NO") -> NO | AO17: =IF(AND(AL17="In-Kind",AN17="NO"),"In-Kind","Cash-in-Lieu") -> Cash-in-Lieu
A18: ='Enhanced Basket_AUTOLOAD'!H18 -> 0 | B18: =IF(AA18>0,"BUY","SELL") -> SELL | C18: BONY | D18: =IF(AO18="In-Kind","INK","MT") -> MT | E18: =IF(D18="INK","MSCOP","") | F18: =IF(E18="MSCOP","INKIND LOAD","CIL LOAD") -> CIL LOAD | G18: =ABS(AA18*AB18) -> 0 | H18: =AG18 -> #N/A | I18: =_xll.BDP(AG18&" equity","crncy_adj_px_last","eqy_fund_crncy=usd") -> #NAME? | J18: =IF(D18="INK",G18,"") | AA18: =IFERROR(VLOOKUP(A18,$R$4:$S$26,2,0),0) -> 0 | AB18: ='Enhanced Basket_AUTOLOAD'!T18 -> 0 | AC18: ='Enhanced Basket_AUTOLOAD'!M18 -> 0 | AD18: ='Enhanced Basket_AUTOLOAD'!L18 -> 0 | AE18: ='Enhanced Basket_AUTOLOAD'!Z18 -> 0 | AF18: ='Enhanced Basket_AUTOLOAD'!AB18 -> 0 | AG18: =VLOOKUP(AJ18,'Ticker Mapping'!$I$3:$M$6706,5,0) -> #N/A | AH18: =_xll.BDP(AK18&" SEDOL","TICKER_AND_EXCH_CODE") -> #NAME? | AI18: =IF(AG18=AH18,"Y","N") -> #N/A | AJ18: ='Enhanced Basket_AUTOLOAD'!P18 -> 0 | AK18: ='Enhanced Basket_AUTOLOAD'!Q18 -> 0 | AL18: ='Enhanced Basket_AUTOLOAD'!Y18 -> 0 | AM18: =A18&" "&AG18 -> #N/A | AN18: =IF(COUNTIF($Q$28:$Q$73,AM18),"YES","NO") -> NO | AO18: =IF(AND(AL18="In-Kind",AN18="NO"),"In-Kind","Cash-in-Lieu") -> Cash-in-Lieu
A19: ='Enhanced Basket_AUTOLOAD'!H19 -> 0 | B19: =IF(AA19>0,"BUY","SELL") -> SELL | C19: BONY | D19: =IF(AO19="In-Kind","INK","MT") -> MT | E19: =IF(D19="INK","MSCOP","") | F19: =IF(E19="MSCOP","INKIND LOAD","CIL LOAD") -> CIL LOAD | G19: =ABS(AA19*AB19) -> 0 | H19: =AG19 -> #N/A | I19: =_xll.BDP(AG19&" equity","crncy_adj_px_last","eqy_fund_crncy=usd") -> #NAME? | J19: =IF(D19="INK",G19,"") | AA19: =IFERROR(VLOOKUP(A19,$R$4:$S$26,2,0),0) -> 0 | AB19: ='Enhanced Basket_AUTOLOAD'!T19 -> 0 | AC19: ='Enhanced Basket_AUTOLOAD'!M19 -> 0 | AD19: ='Enhanced Basket_AUTOLOAD'!L19 -> 0 | AE19: ='Enhanced Basket_AUTOLOAD'!Z19 -> 0 | AF19: ='Enhanced Basket_AUTOLOAD'!AB19 -> 0 | AG19: =VLOOKUP(AJ19,'Ticker Mapping'!$I$3:$M$6706,5,0) -> #N/A | AH19: =_xll.BDP(AK19&" SEDOL","TICKER_AND_EXCH_CODE") -> #NAME? | AI19: =IF(AG19=AH19,"Y","N") -> #N/A | AJ19: ='Enhanced Basket_AUTOLOAD'!P19 -> 0 | AK19: ='Enhanced Basket_AUTOLOAD'!Q19 -> 0 | AL19: ='Enhanced Basket_AUTOLOAD'!Y19 -> 0 | AM19: =A19&" "&AG19 -> #N/A | AN19: =IF(COUNTIF($Q$28:$Q$73,AM19),"YES","NO") -> NO | AO19: =IF(AND(AL19="In-Kind",AN19="NO"),"In-Kind","Cash-in-Lieu") -> Cash-in-Lieu
A20: ='Enhanced Basket_AUTOLOAD'!H20 -> 0 | B20: =IF(AA20>0,"BUY","SELL") -> SELL | C20: BONY | D20: =IF(AO20="In-Kind","INK","MT") -> MT | E20: =IF(D20="INK","MSCOP","") | F20: =IF(E20="MSCOP","INKIND LOAD","CIL LOAD") -> CIL LOAD | G20: =ABS(AA20*AB20) -> 0 | H20: =AG20 -> #N/A | I20: =_xll.BDP(AG20&" equity","crncy_adj_px_last","eqy_fund_crncy=usd") -> #NAME? | J20: =IF(D20="INK",G20,"") | AA20: =IFERROR(VLOOKUP(A20,$R$4:$S$26,2,0),0) -> 0 | AB20: ='Enhanced Basket_AUTOLOAD'!T20 -> 0 | AC20: ='Enhanced Basket_AUTOLOAD'!M20 -> 0 | AD20: ='Enhanced Basket_AUTOLOAD'!L20 -> 0 | AE20: ='Enhanced Basket_AUTOLOAD'!Z20 -> 0 | AF20: ='Enhanced Basket_AUTOLOAD'!AB20 -> 0 | AG20: =VLOOKUP(AJ20,'Ticker Mapping'!$I$3:$M$6706,5,0) -> #N/A | AH20: =_xll.BDP(AK20&" SEDOL","TICKER_AND_EXCH_CODE") -> #NAME? | AI20: =IF(AG20=AH20,"Y","N") -> #N/A | AJ20: ='Enhanced Basket_AUTOLOAD'!P20 -> 0 | AK20: ='Enhanced Basket_AUTOLOAD'!Q20 -> 0 | AL20: ='Enhanced Basket_AUTOLOAD'!Y20 -> 0 | AM20: =A20&" "&AG20 -> #N/A | AN20: =IF(COUNTIF($Q$28:$Q$73,AM20),"YES","NO") -> NO | AO20: =IF(AND(AL20="In-Kind",AN20="NO"),"In-Kind","Cash-in-Lieu") -> Cash-in-Lieu
A21: ='Enhanced Basket_AUTOLOAD'!H21 -> 0 | B21: =IF(AA21>0,"BUY","SELL") -> SELL | C21: BONY | D21: =IF(AO21="In-Kind","INK","MT") -> MT | E21: =IF(D21="INK","MSCOP","") | F21: =IF(E21="MSCOP","INKIND LOAD","CIL LOAD") -> CIL LOAD | G21: =ABS(AA21*AB21) -> 0 | H21: =AG21 -> #N/A | I21: =_xll.BDP(AG21&" equity","crncy_adj_px_last","eqy_fund_crncy=usd") -> #NAME? | J21: =IF(D21="INK",G21,"") | AA21: =IFERROR(VLOOKUP(A21,$R$4:$S$26,2,0),0) -> 0 | AB21: ='Enhanced Basket_AUTOLOAD'!T21 -> 0 | AC21: ='Enhanced Basket_AUTOLOAD'!M21 -> 0 | AD21: ='Enhanced Basket_AUTOLOAD'!L21 -> 0 | AE21: ='Enhanced Basket_AUTOLOAD'!Z21 -> 0 | AF21: ='Enhanced Basket_AUTOLOAD'!AB21 -> 0 | AG21: =VLOOKUP(AJ21,'Ticker Mapping'!$I$3:$M$6706,5,0) -> #N/A | AH21: =_xll.BDP(AK21&" SEDOL","TICKER_AND_EXCH_CODE") -> #NAME? | AI21: =IF(AG21=AH21,"Y","N") -> #N/A | AJ21: ='Enhanced Basket_AUTOLOAD'!P21 -> 0 | AK21: ='Enhanced Basket_AUTOLOAD'!Q21 -> 0 | AL21: ='Enhanced Basket_AUTOLOAD'!Y21 -> 0 | AM21: =A21&" "&AG21 -> #N/A | AN21: =IF(COUNTIF($Q$28:$Q$73,AM21),"YES","NO") -> NO | AO21: =IF(AND(AL21="In-Kind",AN21="NO"),"In-Kind","Cash-in-Lieu") -> Cash-in-Lieu
A22: ='Enhanced Basket_AUTOLOAD'!H22 -> 0 | B22: =IF(AA22>0,"BUY","SELL") -> SELL | C22: BONY | D22: =IF(AO22="In-Kind","INK","MT") -> MT | E22: =IF(D22="INK","MSCOP","") | F22: =IF(E22="MSCOP","INKIND LOAD","CIL LOAD") -> CIL LOAD | G22: =ABS(AA22*AB22) -> 0 | H22: =AG22 -> #N/A | I22: =_xll.BDP(AG22&" equity","crncy_adj_px_last","eqy_fund_crncy=usd") -> #NAME? | J22: =IF(D22="INK",G22,"") | AA22: =IFERROR(VLOOKUP(A22,$R$4:$S$26,2,0),0) -> 0 | AB22: ='Enhanced Basket_AUTOLOAD'!T22 -> 0 | AC22: ='Enhanced Basket_AUTOLOAD'!M22 -> 0 | AD22: ='Enhanced Basket_AUTOLOAD'!L22 -> 0 | AE22: ='Enhanced Basket_AUTOLOAD'!Z22 -> 0 | AF22: ='Enhanced Basket_AUTOLOAD'!AB22 -> 0 | AG22: =VLOOKUP(AJ22,'Ticker Mapping'!$I$3:$M$6706,5,0) -> #N/A | AH22: =_xll.BDP(AK22&" SEDOL","TICKER_AND_EXCH_CODE") -> #NAME? | AI22: =IF(AG22=AH22,"Y","N") -> #N/A | AJ22: ='Enhanced Basket_AUTOLOAD'!P22 -> 0 | AK22: ='Enhanced Basket_AUTOLOAD'!Q22 -> 0 | AL22: ='Enhanced Basket_AUTOLOAD'!Y22 -> 0 | AM22: =A22&" "&AG22 -> #N/A | AN22: =IF(COUNTIF($Q$28:$Q$73,AM22),"YES","NO") -> NO | AO22: =IF(AND(AL22="In-Kind",AN22="NO"),"In-Kind","Cash-in-Lieu") -> Cash-in-Lieu
A23: ='Enhanced Basket_AUTOLOAD'!H23 -> 0 | B23: =IF(AA23>0,"BUY","SELL") -> SELL | C23: BONY | D23: =IF(AO23="In-Kind","INK","MT") -> MT | E23: =IF(D23="INK","MSCOP","") | F23: =IF(E23="MSCOP","INKIND LOAD","CIL LOAD") -> CIL LOAD | G23: =ABS(AA23*AB23) -> 0 | H23: =AG23 -> #N/A | I23: =_xll.BDP(AG23&" equity","crncy_adj_px_last","eqy_fund_crncy=usd") -> #NAME? | J23: =IF(D23="INK",G23,"") | AA23: =IFERROR(VLOOKUP(A23,$R$4:$S$26,2,0),0) -> 0 | AB23: ='Enhanced Basket_AUTOLOAD'!T23 -> 0 | AC23: ='Enhanced Basket_AUTOLOAD'!M23 -> 0 | AD23: ='Enhanced Basket_AUTOLOAD'!L23 -> 0 | AE23: ='Enhanced Basket_AUTOLOAD'!Z23 -> 0 | AF23: ='Enhanced Basket_AUTOLOAD'!AB23 -> 0 | AG23: =VLOOKUP(AJ23,'Ticker Mapping'!$I$3:$M$6706,5,0) -> #N/A | AH23: =_xll.BDP(AK23&" SEDOL","TICKER_AND_EXCH_CODE") -> #NAME? | AI23: =IF(AG23=AH23,"Y","N") -> #N/A | AJ23: ='Enhanced Basket_AUTOLOAD'!P23 -> 0 | AK23: ='Enhanced Basket_AUTOLOAD'!Q23 -> 0 | AL23: ='Enhanced Basket_AUTOLOAD'!Y23 -> 0 | AM23: =A23&" "&AG23 -> #N/A | AN23: =IF(COUNTIF($Q$28:$Q$73,AM23),"YES","NO") -> NO | AO23: =IF(AND(AL23="In-Kind",AN23="NO"),"In-Kind","Cash-in-Lieu") -> Cash-in-Lieu
A24: ='Enhanced Basket_AUTOLOAD'!H24 -> 0 | B24: =IF(AA24>0,"BUY","SELL") -> SELL | C24: BONY | D24: =IF(AO24="In-Kind","INK","MT") -> MT | E24: =IF(D24="INK","MSCOP","") | F24: =IF(E24="MSCOP","INKIND LOAD","CIL LOAD") -> CIL LOAD | G24: =ABS(AA24*AB24) -> 0 | H24: =AG24 -> #N/A | I24: =_xll.BDP(AG24&" equity","crncy_adj_px_last","eqy_fund_crncy=usd") -> #NAME? | J24: =IF(D24="INK",G24,"") | AA24: =IFERROR(VLOOKUP(A24,$R$4:$S$26,2,0),0) -> 0 | AB24: ='Enhanced Basket_AUTOLOAD'!T24 -> 0 | AC24: ='Enhanced Basket_AUTOLOAD'!M24 -> 0 | AD24: ='Enhanced Basket_AUTOLOAD'!L24 -> 0 | AE24: ='Enhanced Basket_AUTOLOAD'!Z24 -> 0 | AF24: ='Enhanced Basket_AUTOLOAD'!AB24 -> 0 | AG24: =VLOOKUP(AJ24,'Ticker Mapping'!$I$3:$M$6706,5,0) -> #N/A | AH24: =_xll.BDP(AK24&" SEDOL","TICKER_AND_EXCH_CODE") -> #NAME? | AI24: =IF(AG24=AH24,"Y","N") -> #N/A | AJ24: ='Enhanced Basket_AUTOLOAD'!P24 -> 0 | AK24: ='Enhanced Basket_AUTOLOAD'!Q24 -> 0 | AL24: ='Enhanced Basket_AUTOLOAD'!Y24 -> 0 | AM24: =A24&" "&AG24 -> #N/A | AN24: =IF(COUNTIF($Q$28:$Q$73,AM24),"YES","NO") -> NO | AO24: =IF(AND(AL24="In-Kind",AN24="NO"),"In-Kind","Cash-in-Lieu") -> Cash-in-Lieu
A25: ='Enhanced Basket_AUTOLOAD'!H25 -> 0 | B25: =IF(AA25>0,"BUY","SELL") -> SELL | C25: BONY | D25: =IF(AO25="In-Kind","INK","MT") -> MT | E25: =IF(D25="INK","MSCOP","") | F25: =IF(E25="MSCOP","INKIND LOAD","CIL LOAD") -> CIL LOAD | G25: =ABS(AA25*AB25) -> 0 | H25: =AG25 -> #N/A | I25: =_xll.BDP(AG25&" equity","crncy_adj_px_last","eqy_fund_crncy=usd") -> #NAME? | J25: =IF(D25="INK",G25,"") | AA25: =IFERROR(VLOOKUP(A25,$R$4:$S$26,2,0),0) -> 0 | AB25: ='Enhanced Basket_AUTOLOAD'!T25 -> 0 | AC25: ='Enhanced Basket_AUTOLOAD'!M25 -> 0 | AD25: ='Enhanced Basket_AUTOLOAD'!L25 -> 0 | AE25: ='Enhanced Basket_AUTOLOAD'!Z25 -> 0 | AF25: ='Enhanced Basket_AUTOLOAD'!AB25 -> 0 | AG25: =VLOOKUP(AJ25,'Ticker Mapping'!$I$3:$M$6706,5,0) -> #N/A | AH25: =_xll.BDP(AK25&" SEDOL","TICKER_AND_EXCH_CODE") -> #NAME? | AI25: =IF(AG25=AH25,"Y","N") -> #N/A | AJ25: ='Enhanced Basket_AUTOLOAD'!P25 -> 0 | AK25: ='Enhanced Basket_AUTOLOAD'!Q25 -> 0 | AL25: ='Enhanced Basket_AUTOLOAD'!Y25 -> 0 | AM25: =A25&" "&AG25 -> #N/A | AN25: =IF(COUNTIF($Q$28:$Q$73,AM25),"YES","NO") -> NO | AO25: =IF(AND(AL25="In-Kind",AN25="NO"),"In-Kind","Cash-in-Lieu") -> Cash-in-Lieu
A26: ='Enhanced Basket_AUTOLOAD'!H26 -> 0 | B26: =IF(AA26>0,"BUY","SELL") -> SELL | C26: BONY | D26: =IF(AO26="In-Kind","INK","MT") -> MT | E26: =IF(D26="INK","MSCOP","") | F26: =IF(E26="MSCOP","INKIND LOAD","CIL LOAD") -> CIL LOAD | G26: =ABS(AA26*AB26) -> 0 | H26: =AG26 -> #N/A | I26: =_xll.BDP(AG26&" equity","crncy_adj_px_last","eqy_fund_crncy=usd") -> #NAME? | J26: =IF(D26="INK",G26,"") | R26: CIL Request (outside of standard) | AA26: =IFERROR(VLOOKUP(A26,$R$4:$S$26,2,0),0) -> 0 | AB26: ='Enhanced Basket_AUTOLOAD'!T26 -> 0 | AC26: ='Enhanced Basket_AUTOLOAD'!M26 -> 0 | AD26: ='Enhanced Basket_AUTOLOAD'!L26 -> 0 | AE26: ='Enhanced Basket_AUTOLOAD'!Z26 -> 0 | AF26: ='Enhanced Basket_AUTOLOAD'!AB26 -> 0 | AG26: =VLOOKUP(AJ26,'Ticker Mapping'!$I$3:$M$6706,5,0) -> #N/A | AH26: =_xll.BDP(AK26&" SEDOL","TICKER_AND_EXCH_CODE") -> #NAME? | AI26: =IF(AG26=AH26,"Y","N") -> #N/A | AJ26: ='Enhanced Basket_AUTOLOAD'!P26 -> 0 | AK26: ='Enhanced Basket_AUTOLOAD'!Q26 -> 0 | AL26: ='Enhanced Basket_AUTOLOAD'!Y26 -> 0 | AM26: =A26&" "&AG26 -> #N/A | AN26: =IF(COUNTIF($Q$28:$Q$73,AM26),"YES","NO") -> NO | AO26: =IF(AND(AL26="In-Kind",AN26="NO"),"In-Kind","Cash-in-Lieu") -> Cash-in-Lieu
A27: ='Enhanced Basket_AUTOLOAD'!H27 -> 0 | B27: =IF(AA27>0,"BUY","SELL") -> SELL | C27: BONY | D27: =IF(AO27="In-Kind","INK","MT") -> MT | E27: =IF(D27="INK","MSCOP","") | F27: =IF(E27="MSCOP","INKIND LOAD","CIL LOAD") -> CIL LOAD | G27: =ABS(AA27*AB27) -> 0 | H27: =AG27 -> #N/A | I27: =_xll.BDP(AG27&" equity","crncy_adj_px_last","eqy_fund_crncy=usd") -> #NAME? | J27: =IF(D27="INK",G27,"") | R27: Fund | S27: Ticker | U27: Amount | AA27: =IFERROR(VLOOKUP(A27,$R$4:$S$26,2,0),0) -> 0 | AB27: ='Enhanced Basket_AUTOLOAD'!T27 -> 0 | AC27: ='Enhanced Basket_AUTOLOAD'!M27 -> 0 | AD27: ='Enhanced Basket_AUTOLOAD'!L27 -> 0 | AE27: ='Enhanced Basket_AUTOLOAD'!Z27 -> 0 | AF27: ='Enhanced Basket_AUTOLOAD'!AB27 -> 0 | AG27: =VLOOKUP(AJ27,'Ticker Mapping'!$I$3:$M$6706,5,0) -> #N/A | AH27: =_xll.BDP(AK27&" SEDOL","TICKER_AND_EXCH_CODE") -> #NAME? | AI27: =IF(AG27=AH27,"Y","N") -> #N/A | AJ27: ='Enhanced Basket_AUTOLOAD'!P27 -> 0 | AK27: ='Enhanced Basket_AUTOLOAD'!Q27 -> 0 | AL27: ='Enhanced Basket_AUTOLOAD'!Y27 -> 0 | AM27: =A27&" "&AG27 -> #N/A | AN27: =IF(COUNTIF($Q$28:$Q$73,AM27),"YES","NO") -> NO | AO27: =IF(AND(AL27="In-Kind",AN27="NO"),"In-Kind","Cash-in-Lieu") -> Cash-in-Lieu
A28: ='Enhanced Basket_AUTOLOAD'!H28 -> 0 | B28: =IF(AA28>0,"BUY","SELL") -> SELL | C28: BONY | D28: =IF(AO28="In-Kind","INK","MT") -> MT | E28: =IF(D28="INK","MSCOP","") | F28: =IF(E28="MSCOP","INKIND LOAD","CIL LOAD") -> CIL LOAD | G28: =ABS(AA28*AB28) -> 0 | H28: =AG28 -> #N/A | I28: =_xll.BDP(AG28&" equity","crncy_adj_px_last","eqy_fund_crncy=usd") -> #NAME? | J28: =IF(D28="INK",G28,"") | Q28: =R28&" "&S28 | T28: Cash-in-Lieu | U28: =SUMIFS($G:$G,$A:$A,R28,$H:$H,S28) -> 0 | AA28: =IFERROR(VLOOKUP(A28,$R$4:$S$26,2,0),0) -> 0 | AB28: ='Enhanced Basket_AUTOLOAD'!T28 -> 0 | AC28: ='Enhanced Basket_AUTOLOAD'!M28 -> 0 | AD28: ='Enhanced Basket_AUTOLOAD'!L28 -> 0 | AE28: ='Enhanced Basket_AUTOLOAD'!Z28 -> 0 | AF28: ='Enhanced Basket_AUTOLOAD'!AB28 -> 0 | AG28: =VLOOKUP(AJ28,'Ticker Mapping'!$I$3:$M$6706,5,0) -> #N/A | AH28: =_xll.BDP(AK28&" SEDOL","TICKER_AND_EXCH_CODE") -> #NAME? | AI28: =IF(AG28=AH28,"Y","N") -> #N/A | AJ28: ='Enhanced Basket_AUTOLOAD'!P28 -> 0 | AK28: ='Enhanced Basket_AUTOLOAD'!Q28 -> 0 | AL28: ='Enhanced Basket_AUTOLOAD'!Y28 -> 0 | AM28: =A28&" "&AG28 -> #N/A | AN28: =IF(COUNTIF($Q$28:$Q$73,AM28),"YES","NO") -> NO | AO28: =IF(AND(AL28="In-Kind",AN28="NO"),"In-Kind","Cash-in-Lieu") -> Cash-in-Lieu
A29: ='Enhanced Basket_AUTOLOAD'!H29 -> 0 | B29: =IF(AA29>0,"BUY","SELL") -> SELL | C29: BONY | D29: =IF(AO29="In-Kind","INK","MT") -> MT | E29: =IF(D29="INK","MSCOP","") | F29: =IF(E29="MSCOP","INKIND LOAD","CIL LOAD") -> CIL LOAD | G29: =ABS(AA29*AB29) -> 0 | H29: =AG29 -> #N/A | I29: =_xll.BDP(AG29&" equity","crncy_adj_px_last","eqy_fund_crncy=usd") -> #NAME? | J29: =IF(D29="INK",G29,"") | Q29: =R29&" "&S29 | T29: Cash-in-Lieu | U29: =SUMIFS($G:$G,$A:$A,R29,$H:$H,S29) -> 0 | AA29: =IFERROR(VLOOKUP(A29,$R$4:$S$26,2,0),0) -> 0 | AB29: ='Enhanced Basket_AUTOLOAD'!T29 -> 0 | AC29: ='Enhanced Basket_AUTOLOAD'!M29 -> 0 | AD29: ='Enhanced Basket_AUTOLOAD'!L29 -> 0 | AE29: ='Enhanced Basket_AUTOLOAD'!Z29 -> 0 | AF29: ='Enhanced Basket_AUTOLOAD'!AB29 -> 0 | AG29: =VLOOKUP(AJ29,'Ticker Mapping'!$I$3:$M$6706,5,0) -> #N/A | AH29: =_xll.BDP(AK29&" SEDOL","TICKER_AND_EXCH_CODE") -> #NAME? | AI29: =IF(AG29=AH29,"Y","N") -> #N/A | AJ29: ='Enhanced Basket_AUTOLOAD'!P29 -> 0 | AK29: ='Enhanced Basket_AUTOLOAD'!Q29 -> 0 | AL29: ='Enhanced Basket_AUTOLOAD'!Y29 -> 0 | AM29: =A29&" "&AG29 -> #N/A | AN29: =IF(COUNTIF($Q$28:$Q$73,AM29),"YES","NO") -> NO | AO29: =IF(AND(AL29="In-Kind",AN29="NO"),"In-Kind","Cash-in-Lieu") -> Cash-in-Lieu
A30: ='Enhanced Basket_AUTOLOAD'!H30 -> 0 | B30: =IF(AA30>0,"BUY","SELL") -> SELL | C30: BONY | D30: =IF(AO30="In-Kind","INK","MT") -> MT | E30: =IF(D30="INK","MSCOP","") | F30: =IF(E30="MSCOP","INKIND LOAD","CIL LOAD") -> CIL LOAD | G30: =ABS(AA30*AB30) -> 0 | H30: =AG30 -> #N/A | I30: =_xll.BDP(AG30&" equity","crncy_adj_px_last","eqy_fund_crncy=usd") -> #NAME? | J30: =IF(D30="INK",G30,"") | Q30: =R30&" "&S30 | T30: Cash-in-Lieu | U30: =SUMIFS($G:$G,$A:$A,R30,$H:$H,S30) -> 0 | AA30: =IFERROR(VLOOKUP(A30,$R$4:$S$26,2,0),0) -> 0 | AB30: ='Enhanced Basket_AUTOLOAD'!T30 -> 0 | AC30: ='Enhanced Basket_AUTOLOAD'!M30 -> 0 | AD30: ='Enhanced Basket_AUTOLOAD'!L30 -> 0 | AE30: ='Enhanced Basket_AUTOLOAD'!Z30 -> 0 | AF30: ='Enhanced Basket_AUTOLOAD'!AB30 -> 0 | AG30: =VLOOKUP(AJ30,'Ticker Mapping'!$I$3:$M$6706,5,0) -> #N/A | AH30: =_xll.BDP(AK30&" SEDOL","TICKER_AND_EXCH_CODE") -> #NAME? | AI30: =IF(AG30=AH30,"Y","N") -> #N/A | AJ30: ='Enhanced Basket_AUTOLOAD'!P30 -> 0 | AK30: ='Enhanced Basket_AUTOLOAD'!Q30 -> 0 | AL30: ='Enhanced Basket_AUTOLOAD'!Y30 -> 0 | AM30: =A30&" "&AG30 -> #N/A | AN30: =IF(COUNTIF($Q$28:$Q$73,AM30),"YES","NO") -> NO | AO30: =IF(AND(AL30="In-Kind",AN30="NO"),"In-Kind","Cash-in-Lieu") -> Cash-in-Lieu
A31: ='Enhanced Basket_AUTOLOAD'!H31 -> 0 | B31: =IF(AA31>0,"BUY","SELL") -> SELL | C31: BONY | D31: =IF(AO31="In-Kind","INK","MT") -> MT | E31: =IF(D31="INK","MSCOP","") | F31: =IF(E31="MSCOP","INKIND LOAD","CIL LOAD") -> CIL LOAD | G31: =ABS(AA31*AB31) -> 0 | H31: =AG31 -> #N/A | I31: =_xll.BDP(AG31&" equity","crncy_adj_px_last","eqy_fund_crncy=usd") -> #NAME? | J31: =IF(D31="INK",G31,"") | Q31: =R31&" "&S31 | T31: Cash-in-Lieu | U31: =SUMIFS($G:$G,$A:$A,R31,$H:$H,S31) -> 0 | AA31: =IFERROR(VLOOKUP(A31,$R$4:$S$26,2,0),0) -> 0 | AB31: ='Enhanced Basket_AUTOLOAD'!T31 -> 0 | AC31: ='Enhanced Basket_AUTOLOAD'!M31 -> 0 | AD31: ='Enhanced Basket_AUTOLOAD'!L31 -> 0 | AE31: ='Enhanced Basket_AUTOLOAD'!Z31 -> 0 | AF31: ='Enhanced Basket_AUTOLOAD'!AB31 -> 0 | AG31: =VLOOKUP(AJ31,'Ticker Mapping'!$I$3:$M$6706,5,0) -> #N/A | AH31: =_xll.BDP(AK31&" SEDOL","TICKER_AND_EXCH_CODE") -> #NAME? | AI31: =IF(AG31=AH31,"Y","N") -> #N/A | AJ31: ='Enhanced Basket_AUTOLOAD'!P31 -> 0 | AK31: ='Enhanced Basket_AUTOLOAD'!Q31 -> 0 | AL31: ='Enhanced Basket_AUTOLOAD'!Y31 -> 0 | AM31: =A31&" "&AG31 -> #N/A | AN31: =IF(COUNTIF($Q$28:$Q$73,AM31),"YES","NO") -> NO | AO31: =IF(AND(AL31="In-Kind",AN31="NO"),"In-Kind","Cash-in-Lieu") -> Cash-in-Lieu
A32: ='Enhanced Basket_AUTOLOAD'!H32 -> 0 | B32: =IF(AA32>0,"BUY","SELL") -> SELL | C32: BONY | D32: =IF(AO32="In-Kind","INK","MT") -> MT | E32: =IF(D32="INK","MSCOP","") | F32: =IF(E32="MSCOP","INKIND LOAD","CIL LOAD") -> CIL LOAD | G32: =ABS(AA32*AB32) -> 0 | H32: =AG32 -> #N/A | I32: =_xll.BDP(AG32&" equity","crncy_adj_px_last","eqy_fund_crncy=usd") -> #NAME? | J32: =IF(D32="INK",G32,"") | Q32: =R32&" "&S32 | T32: Cash-in-Lieu | U32: =SUMIFS($G:$G,$A:$A,R32,$H:$H,S32) -> 0 | AA32: =IFERROR(VLOOKUP(A32,$R$4:$S$26,2,0),0) -> 0 | AB32: ='Enhanced Basket_AUTOLOAD'!T32 -> 0 | AC32: ='Enhanced Basket_AUTOLOAD'!M32 -> 0 | AD32: ='Enhanced Basket_AUTOLOAD'!L32 -> 0 | AE32: ='Enhanced Basket_AUTOLOAD'!Z32 -> 0 | AF32: ='Enhanced Basket_AUTOLOAD'!AB32 -> 0 | AG32: =VLOOKUP(AJ32,'Ticker Mapping'!$I$3:$M$6706,5,0) -> #N/A | AH32: =_xll.BDP(AK32&" SEDOL","TICKER_AND_EXCH_CODE") -> #NAME? | AI32: =IF(AG32=AH32,"Y","N") -> #N/A | AJ32: ='Enhanced Basket_AUTOLOAD'!P32 -> 0 | AK32: ='Enhanced Basket_AUTOLOAD'!Q32 -> 0 | AL32: ='Enhanced Basket_AUTOLOAD'!Y32 -> 0 | AM32: =A32&" "&AG32 -> #N/A | AN32: =IF(COUNTIF($Q$28:$Q$73,AM32),"YES","NO") -> NO | AO32: =IF(AND(AL32="In-Kind",AN32="NO"),"In-Kind","Cash-in-Lieu") -> Cash-in-Lieu
A33: ='Enhanced Basket_AUTOLOAD'!H33 -> 0 | B33: =IF(AA33>0,"BUY","SELL") -> SELL | C33: BONY | D33: =IF(AO33="In-Kind","INK","MT") -> MT | E33: =IF(D33="INK","MSCOP","") | F33: =IF(E33="MSCOP","INKIND LOAD","CIL LOAD") -> CIL LOAD | G33: =ABS(AA33*AB33) -> 0 | H33: =AG33 -> #N/A | I33: =_xll.BDP(AG33&" equity","crncy_adj_px_last","eqy_fund_crncy=usd") -> #NAME? | J33: =IF(D33="INK",G33,"") | Q33: =R33&" "&S33 | T33: Cash-in-Lieu | U33: =SUMIFS($G:$G,$A:$A,R33,$H:$H,S33) -> 0 | AA33: =IFERROR(VLOOKUP(A33,$R$4:$S$26,2,0),0) -> 0 | AB33: ='Enhanced Basket_AUTOLOAD'!T33 -> 0 | AC33: ='Enhanced Basket_AUTOLOAD'!M33 -> 0 | AD33: ='Enhanced Basket_AUTOLOAD'!L33 -> 0 | AE33: ='Enhanced Basket_AUTOLOAD'!Z33 -> 0 | AF33: ='Enhanced Basket_AUTOLOAD'!AB33 -> 0 | AG33: =VLOOKUP(AJ33,'Ticker Mapping'!$I$3:$M$6706,5,0) -> #N/A | AH33: =_xll.BDP(AK33&" SEDOL","TICKER_AND_EXCH_CODE") -> #NAME? | AI33: =IF(AG33=AH33,"Y","N") -> #N/A | AJ33: ='Enhanced Basket_AUTOLOAD'!P33 -> 0 | AK33: ='Enhanced Basket_AUTOLOAD'!Q33 -> 0 | AL33: ='Enhanced Basket_AUTOLOAD'!Y33 -> 0 | AM33: =A33&" "&AG33 -> #N/A | AN33: =IF(COUNTIF($Q$28:$Q$73,AM33),"YES","NO") -> NO | AO33: =IF(AND(AL33="In-Kind",AN33="NO"),"In-Kind","Cash-in-Lieu") -> Cash-in-Lieu
A34: ='Enhanced Basket_AUTOLOAD'!H34 -> 0 | B34: =IF(AA34>0,"BUY","SELL") -> SELL | C34: BONY | D34: =IF(AO34="In-Kind","INK","MT") -> MT | E34: =IF(D34="INK","MSCOP","") | F34: =IF(E34="MSCOP","INKIND LOAD","CIL LOAD") -> CIL LOAD | G34: =ABS(AA34*AB34) -> 0 | H34: =AG34 -> #N/A | I34: =_xll.BDP(AG34&" equity","crncy_adj_px_last","eqy_fund_crncy=usd") -> #NAME? | J34: =IF(D34="INK",G34,"") | Q34: =R34&" "&S34 | T34: Cash-in-Lieu | U34: =SUMIFS($G:$G,$A:$A,R34,$H:$H,S34) -> 0 | AA34: =IFERROR(VLOOKUP(A34,$R$4:$S$26,2,0),0) -> 0 | AB34: ='Enhanced Basket_AUTOLOAD'!T34 -> 0 | AC34: ='Enhanced Basket_AUTOLOAD'!M34 -> 0 | AD34: ='Enhanced Basket_AUTOLOAD'!L34 -> 0 | AE34: ='Enhanced Basket_AUTOLOAD'!Z34 -> 0 | AF34: ='Enhanced Basket_AUTOLOAD'!AB34 -> 0 | AG34: =VLOOKUP(AJ34,'Ticker Mapping'!$I$3:$M$6706,5,0) -> #N/A | AH34: =_xll.BDP(AK34&" SEDOL","TICKER_AND_EXCH_CODE") -> #NAME? | AI34: =IF(AG34=AH34,"Y","N") -> #N/A | AJ34: ='Enhanced Basket_AUTOLOAD'!P34 -> 0 | AK34: ='Enhanced Basket_AUTOLOAD'!Q34 -> 0 | AL34: ='Enhanced Basket_AUTOLOAD'!Y34 -> 0 | AM34: =A34&" "&AG34 -> #N/A | AN34: =IF(COUNTIF($Q$28:$Q$73,AM34),"YES","NO") -> NO | AO34: =IF(AND(AL34="In-Kind",AN34="NO"),"In-Kind","Cash-in-Lieu") -> Cash-in-Lieu
A35: ='Enhanced Basket_AUTOLOAD'!H35 -> 0 | B35: =IF(AA35>0,"BUY","SELL") -> SELL | C35: BONY | D35: =IF(AO35="In-Kind","INK","MT") -> MT | E35: =IF(D35="INK","MSCOP","") | F35: =IF(E35="MSCOP","INKIND LOAD","CIL LOAD") -> CIL LOAD | G35: =ABS(AA35*AB35) -> 0 | H35: =AG35 -> #N/A | I35: =_xll.BDP(AG35&" equity","crncy_adj_px_last","eqy_fund_crncy=usd") -> #NAME? | J35: =IF(D35="INK",G35,"") | Q35: =R35&" "&S35 | T35: Cash-in-Lieu | U35: =SUMIFS($G:$G,$A:$A,R35,$H:$H,S35) -> 0 | AA35: =IFERROR(VLOOKUP(A35,$R$4:$S$26,2,0),0) -> 0 | AB35: ='Enhanced Basket_AUTOLOAD'!T35 -> 0 | AC35: ='Enhanced Basket_AUTOLOAD'!M35 -> 0 | AD35: ='Enhanced Basket_AUTOLOAD'!L35 -> 0 | AE35: ='Enhanced Basket_AUTOLOAD'!Z35 -> 0 | AF35: ='Enhanced Basket_AUTOLOAD'!AB35 -> 0 | AG35: =VLOOKUP(AJ35,'Ticker Mapping'!$I$3:$M$6706,5,0) -> #N/A | AH35: =_xll.BDP(AK35&" SEDOL","TICKER_AND_EXCH_CODE") -> #NAME? | AI35: =IF(AG35=AH35,"Y","N") -> #N/A | AJ35: ='Enhanced Basket_AUTOLOAD'!P35 -> 0 | AK35: ='Enhanced Basket_AUTOLOAD'!Q35 -> 0 | AL35: ='Enhanced Basket_AUTOLOAD'!Y35 -> 0 | AM35: =A35&" "&AG35 -> #N/A | AN35: =IF(COUNTIF($Q$28:$Q$73,AM35),"YES","NO") -> NO | AO35: =IF(AND(AL35="In-Kind",AN35="NO"),"In-Kind","Cash-in-Lieu") -> Cash-in-Lieu
A36: ='Enhanced Basket_AUTOLOAD'!H36 -> 0 | B36: =IF(AA36>0,"BUY","SELL") -> SELL | C36: BONY | D36: =IF(AO36="In-Kind","INK","MT") -> MT | E36: =IF(D36="INK","MSCOP","") | F36: =IF(E36="MSCOP","INKIND LOAD","CIL LOAD") -> CIL LOAD | G36: =ABS(AA36*AB36) -> 0 | H36: =AG36 -> #N/A | I36: =_xll.BDP(AG36&" equity","crncy_adj_px_last","eqy_fund_crncy=usd") -> #NAME? | J36: =IF(D36="INK",G36,"") | Q36: =R36&" "&S36 | T36: Cash-in-Lieu | U36: =SUMIFS($G:$G,$A:$A,R36,$H:$H,S36) -> 0 | AA36: =IFERROR(VLOOKUP(A36,$R$4:$S$26,2,0),0) -> 0 | AB36: ='Enhanced Basket_AUTOLOAD'!T36 -> 0 | AC36: ='Enhanced Basket_AUTOLOAD'!M36 -> 0 | AD36: ='Enhanced Basket_AUTOLOAD'!L36 -> 0 | AE36: ='Enhanced Basket_AUTOLOAD'!Z36 -> 0 | AF36: ='Enhanced Basket_AUTOLOAD'!AB36 -> 0 | AG36: =VLOOKUP(AJ36,'Ticker Mapping'!$I$3:$M$6706,5,0) -> #N/A | AH36: =_xll.BDP(AK36&" SEDOL","TICKER_AND_EXCH_CODE") -> #NAME? | AI36: =IF(AG36=AH36,"Y","N") -> #N/A | AJ36: ='Enhanced Basket_AUTOLOAD'!P36 -> 0 | AK36: ='Enhanced Basket_AUTOLOAD'!Q36 -> 0 | AL36: ='Enhanced Basket_AUTOLOAD'!Y36 -> 0 | AM36: =A36&" "&AG36 -> #N/A | AN36: =IF(COUNTIF($Q$28:$Q$73,AM36),"YES","NO") -> NO | AO36: =IF(AND(AL36="In-Kind",AN36="NO"),"In-Kind","Cash-in-Lieu") -> Cash-in-Lieu
A37: ='Enhanced Basket_AUTOLOAD'!H37 -> 0 | B37: =IF(AA37>0,"BUY","SELL") -> SELL | C37: BONY | D37: =IF(AO37="In-Kind","INK","MT") -> MT | E37: =IF(D37="INK","MSCOP","") | F37: =IF(E37="MSCOP","INKIND LOAD","CIL LOAD") -> CIL LOAD | G37: =ABS(AA37*AB37) -> 0 | H37: =AG37 -> #N/A | I37: =_xll.BDP(AG37&" equity","crncy_adj_px_last","eqy_fund_crncy=usd") -> #NAME? | J37: =IF(D37="INK",G37,"") | Q37: =R37&" "&S37 | T37: Cash-in-Lieu | U37: =SUMIFS($G:$G,$A:$A,R37,$H:$H,S37) -> 0 | AA37: =IFERROR(VLOOKUP(A37,$R$4:$S$26,2,0),0) -> 0 | AB37: ='Enhanced Basket_AUTOLOAD'!T37 -> 0 | AC37: ='Enhanced Basket_AUTOLOAD'!M37 -> 0 | AD37: ='Enhanced Basket_AUTOLOAD'!L37 -> 0 | AE37: ='Enhanced Basket_AUTOLOAD'!Z37 -> 0 | AF37: ='Enhanced Basket_AUTOLOAD'!AB37 -> 0 | AG37: =VLOOKUP(AJ37,'Ticker Mapping'!$I$3:$M$6706,5,0) -> #N/A | AH37: =_xll.BDP(AK37&" SEDOL","TICKER_AND_EXCH_CODE") -> #NAME? | AI37: =IF(AG37=AH37,"Y","N") -> #N/A | AJ37: ='Enhanced Basket_AUTOLOAD'!P37 -> 0 | AK37: ='Enhanced Basket_AUTOLOAD'!Q37 -> 0 | AL37: ='Enhanced Basket_AUTOLOAD'!Y37 -> 0 | AM37: =A37&" "&AG37 -> #N/A | AN37: =IF(COUNTIF($Q$28:$Q$73,AM37),"YES","NO") -> NO | AO37: =IF(AND(AL37="In-Kind",AN37="NO"),"In-Kind","Cash-in-Lieu") -> Cash-in-Lieu
A38: ='Enhanced Basket_AUTOLOAD'!H38 -> 0 | B38: =IF(AA38>0,"BUY","SELL") -> SELL | C38: BONY | D38: =IF(AO38="In-Kind","INK","MT") -> MT | E38: =IF(D38="INK","MSCOP","") | F38: =IF(E38="MSCOP","INKIND LOAD","CIL LOAD") -> CIL LOAD | G38: =ABS(AA38*AB38) -> 0 | H38: =AG38 -> #N/A | I38: =_xll.BDP(AG38&" equity","crncy_adj_px_last","eqy_fund_crncy=usd") -> #NAME? | J38: =IF(D38="INK",G38,"") | Q38: =R38&" "&S38 | T38: Cash-in-Lieu | U38: =SUMIFS($G:$G,$A:$A,R38,$H:$H,S38) -> 0 | AA38: =IFERROR(VLOOKUP(A38,$R$4:$S$26,2,0),0) -> 0 | AB38: ='Enhanced Basket_AUTOLOAD'!T38 -> 0 | AC38: ='Enhanced Basket_AUTOLOAD'!M38 -> 0 | AD38: ='Enhanced Basket_AUTOLOAD'!L38 -> 0 | AE38: ='Enhanced Basket_AUTOLOAD'!Z38 -> 0 | AF38: ='Enhanced Basket_AUTOLOAD'!AB38 -> 0 | AG38: =VLOOKUP(AJ38,'Ticker Mapping'!$I$3:$M$6706,5,0) -> #N/A | AH38: =_xll.BDP(AK38&" SEDOL","TICKER_AND_EXCH_CODE") -> #NAME? | AI38: =IF(AG38=AH38,"Y","N") -> #N/A | AJ38: ='Enhanced Basket_AUTOLOAD'!P38 -> 0 | AK38: ='Enhanced Basket_AUTOLOAD'!Q38 -> 0 | AL38: ='Enhanced Basket_AUTOLOAD'!Y38 -> 0 | AM38: =A38&" "&AG38 -> #N/A | AN38: =IF(COUNTIF($Q$28:$Q$73,AM38),"YES","NO") -> NO | AO38: =IF(AND(AL38="In-Kind",AN38="NO"),"In-Kind","Cash-in-Lieu") -> Cash-in-Lieu
A39: ='Enhanced Basket_AUTOLOAD'!H39 -> 0 | B39: =IF(AA39>0,"BUY","SELL") -> SELL | C39: BONY | D39: =IF(AO39="In-Kind","INK","MT") -> MT | E39: =IF(D39="INK","MSCOP","") | F39: =IF(E39="MSCOP","INKIND LOAD","CIL LOAD") -> CIL LOAD | G39: =ABS(AA39*AB39) -> 0 | H39: =AG39 -> #N/A | I39: =_xll.BDP(AG39&" equity","crncy_adj_px_last","eqy_fund_crncy=usd") -> #NAME? | J39: =IF(D39="INK",G39,"") | Q39: =R39&" "&S39 | T39: Cash-in-Lieu | U39: =SUMIFS($G:$G,$A:$A,R39,$H:$H,S39) -> 0 | AA39: =IFERROR(VLOOKUP(A39,$R$4:$S$26,2,0),0) -> 0 | AB39: ='Enhanced Basket_AUTOLOAD'!T39 -> 0 | AC39: ='Enhanced Basket_AUTOLOAD'!M39 -> 0 | AD39: ='Enhanced Basket_AUTOLOAD'!L39 -> 0 | AE39: ='Enhanced Basket_AUTOLOAD'!Z39 -> 0 | AF39: ='Enhanced Basket_AUTOLOAD'!AB39 -> 0 | AG39: =VLOOKUP(AJ39,'Ticker Mapping'!$I$3:$M$6706,5,0) -> #N/A | AH39: =_xll.BDP(AK39&" SEDOL","TICKER_AND_EXCH_CODE") -> #NAME? | AI39: =IF(AG39=AH39,"Y","N") -> #N/A | AJ39: ='Enhanced Basket_AUTOLOAD'!P39 -> 0 | AK39: ='Enhanced Basket_AUTOLOAD'!Q39 -> 0 | AL39: ='Enhanced Basket_AUTOLOAD'!Y39 -> 0 | AM39: =A39&" "&AG39 -> #N/A | AN39: =IF(COUNTIF($Q$28:$Q$73,AM39),"YES","NO") -> NO | AO39: =IF(AND(AL39="In-Kind",AN39="NO"),"In-Kind","Cash-in-Lieu") -> Cash-in-Lieu
... A73: ='Enhanced Basket_AUTOLOAD'!H73 -> 0 | B73: =IF(AA73>0,"BUY","SELL") -> SELL | C73: BONY | D73: =IF(AO73="In-Kind","INK","MT") -> MT | E73: =IF(D73="INK","MSCOP","") | F73: =IF(E73="MSCOP","INKIND LOAD","CIL LOAD") -> CIL LOAD | G73: =ABS(AA73*AB73) -> 0 | H73: =AG73 -> #N/A | I73: =_xll.BDP(AG73&" equity","crncy_adj_px_last","eqy_fund_crncy=usd") -> #NAME? | J73: =IF(D73="INK",G73,"") | Q73: =R73&" "&S73 | T73: Cash-in-Lieu | U73: =SUMIFS($G:$G,$A:$A,R73,$H:$H,S73) -> 0 | AA73: =IFERROR(VLOOKUP(A73,$R$4:$S$26,2,0),0) -> 0 | AB73: ='Enhanced Basket_AUTOLOAD'!T73 -> 0 | AC73: ='Enhanced Basket_AUTOLOAD'!M73 -> 0 | AD73: ='Enhanced Basket_AUTOLOAD'!L73 -> 0 | AE73: ='Enhanced Basket_AUTOLOAD'!Z73 -> 0 | AF73: ='Enhanced Basket_AUTOLOAD'!AB73 -> 0 | AG73: =VLOOKUP(AJ73,'Ticker Mapping'!$I$3:$M$6706,5,0) -> #N/A | AH73: =_xll.BDP(AK73&" SEDOL","TICKER_AND_EXCH_CODE") -> #NAME? | AI73: =IF(AG73=AH73,"Y","N") -> #N/A | AJ73: ='Enhanced Basket_AUTOLOAD'!P73 -> 0 | AK73: ='Enhanced Basket_AUTOLOAD'!Q73 -> 0 | AL73: ='Enhanced Basket_AUTOLOAD'!Y73 -> 0 | AM73: =A73&" "&AG73 -> #N/A | AN73: =IF(COUNTIF($Q$28:$Q$73,AM73),"YES","NO") -> NO | AO73: =IF(AND(AL73="In-Kind",AN73="NO"),"In-Kind","Cash-in-Lieu") -> Cash-in-Lieu
...

Sheet Eze Load
A1: Prt | B1: Side | C1: Cust | D1: Trader | E1: Broker | F1: Note | G1: Amount | H1: Security | I1: Price | J1: Done | K1: COMM

Sheet Enhanced Basket_AUTOLOAD
A1: ETF Issuer Name | B1: Basket Reporting Status | C1: Basket Evaluation Date | D1: Basket Trade Date | E1: Primary Basket ID | F1: Basket Ticker | G1: ETF Trading ID | H1: ETF Trading Ticker | I1: Basket Name | J1: Basket Purpose | K1: Allowable Order Types | L1: Alternative Ticker | M1: Ticker | N1: RIC Code | O1: CUSIP | P1: ISIN | Q1: SEDOL | R1: FIGI | S1: Security Description | T1: Basket Quantity | U1: Basket Quantity From Prior Day | V1: Basket Quantity Change | W1: Cash In Lieu Indicator | X1: Constituent Restriction Type | Y1: Constituent Delivery Type | Z1: Trading Currency | AA1: Local Price Currency | AB1: Settlement Country Code

Sheet EZE Daily Holdings_AUTOLOAD
A1: IndexIQ Advisors LLC
A2: EOD IQ Funds
A3: Report Date: 7/10/2025 6:30:05 PM
A4: Portfolio | B4: Currency | C4: Quantity | D4: NotionalCost | E4: Price | F4: MarketVal/Notional Val | G4: Ticker | H4: BR | I4: SecType | J4: Underlying Ticker

Sheet EZE Daily_With_BB CODES
F1: ID_CUSIP | G1: ID_ISIN | H1: ID_ISIN
D2: EZE Ticker | F2: CUSIP | G2: ISIN | H2: SEDOL | J2: EZE Ticker
D3: ='EZE Daily Holdings_AUTOLOAD'!G5 -> 0 | F3: =_xll.BDP(D3&" equity",$F$1) -> #NAME? | G3: =_xll.BDP(D3&" equity",$G$1) -> #NAME? | H3: =_xll.BDP(D3&" equity",$H$1) -> #NAME? | J3: =D3 -> 0
D4: ='EZE Daily Holdings_AUTOLOAD'!G6 -> 0 | F4: =_xll.BDP(D4&" equity",$F$1) -> #NAME? | G4: =_xll.BDP(D4&" equity",$G$1) -> #NAME? | H4: =_xll.BDP(D4&" equity",$H$1) -> #NAME? | J4: =D4 -> 0
D5: ='EZE Daily Holdings_AUTOLOAD'!G7 -> 0 | F5: =_xll.BDP(D5&" equity",$F$1) -> #NAME? | G5: =_xll.BDP(D5&" equity",$G$1) -> #NAME? | H5: =_xll.BDP(D5&" equity",$H$1) -> #NAME? | J5: =D5 -> 0
D6: ='EZE Daily Holdings_AUTOLOAD'!G8 -> 0 | F6: =_xll.BDP(D6&" equity",$F$1) -> #NAME? | G6: =_xll.BDP(D6&" equity",$G$1) -> #NAME? | H6: =_xll.BDP(D6&" equity",$H$1) -> #NAME? | J6: =D6 -> 0
D7: ='EZE Daily Holdings_AUTOLOAD'!G9 -> 0 | F7: =_xll.BDP(D7&" equity",$F$1) -> #NAME? | G7: =_xll.BDP(D7&" equity",$G$1) -> #NAME? | H7: =_xll.BDP(D7&" equity",$H$1) -> #NAME? | J7: =D7 -> 0
D8: ='EZE Daily Holdings_AUTOLOAD'!G10 -> 0 | F8: =_xll.BDP(D8&" equity",$F$1) -> #NAME? | G8: =_xll.BDP(D8&" equity",$G$1) -> #NAME? | H8: =_xll.BDP(D8&" equity",$H$1) -> #NAME? | J8: =D8 -> 0
D9: ='EZE Daily Holdings_AUTOLOAD'!G11 -> 0 | F9: =_xll.BDP(D9&" equity",$F$1) -> #NAME? | G9: =_xll.BDP(D9&" equity",$G$1) -> #NAME? | H9: =_xll.BDP(D9&" equity",$H$1) -> #NAME? | J9: =D9 -> 0
D10: ='EZE Daily Holdings_AUTOLOAD'!G12 -> 0 | F10: =_xll.BDP(D10&" equity",$F$1) -> #NAME? | G10: =_xll.BDP(D10&" equity",$G$1) -> #NAME? | H10: =_xll.BDP(D10&" equity",$H$1) -> #NAME? | J10: =D10 -> 0
D11: ='EZE Daily Holdings_AUTOLOAD'!G13 -> 0 | F11: =_xll.BDP(D11&" equity",$F$1) -> #NAME? | G11: =_xll.BDP(D11&" equity",$G$1) -> #NAME? | H11: =_xll.BDP(D11&" equity",$H$1) -> #NAME? | J11: =D11 -> 0
D12: ='EZE Daily Holdings_AUTOLOAD'!G14 -> 0 | F12: =_xll.BDP(D12&" equity",$F$1) -> #NAME? | G12: =_xll.BDP(D12&" equity",$G$1) -> #NAME? | H12: =_xll.BDP(D12&" equity",$H$1) -> #NAME? | J12: =D12 -> 0
D13: ='EZE Daily Holdings_AUTOLOAD'!G15 -> 0 | F13: =_xll.BDP(D13&" equity",$F$1) -> #NAME? | G13: =_xll.BDP(D13&" equity",$G$1) -> #NAME? | H13: =_xll.BDP(D13&" equity",$H$1) -> #NAME? | J13: =D13 -> 0
D14: ='EZE Daily Holdings_AUTOLOAD'!G16 -> 0 | F14: =_xll.BDP(D14&" equity",$F$1) -> #NAME? | G14: =_xll.BDP(D14&" equity",$G$1) -> #NAME? | H14: =_xll.BDP(D14&" equity",$H$1) -> #NAME? | J14: =D14 -> 0
... D5451: ='EZE Daily Holdings_AUTOLOAD'!G5453 -> 0 | F5451: =_xll.BDP(D5451&" equity",$F$1) -> #NAME? | G5451: =_xll.BDP(D5451&" equity",$G$1) -> #NAME? | H5451: =_xll.BDP(D5451&" equity",$H$1) -> #NAME? | J5451: =D5451 -> 0

Sheet Ticker Mapping
E1: Enhanced Basket | M1: Based off Enahnced ISIN
F2: FUND | G2: ='Enhanced Basket_AUTOLOAD'!M1 -> Ticker | H2: ='Enhanced Basket_AUTOLOAD'!O1 -> CUSIP | I2: ='Enhanced Basket_AUTOLOAD'!P1 -> ISIN | J2: ='Enhanced Basket_AUTOLOAD'!Q1 -> SEDOL | M2: EZE Ticker (used for load)
F3: ='Enhanced Basket_AUTOLOAD'!H2 -> 0 | G3: ='Enhanced Basket_AUTOLOAD'!M2 -> 0 | H3: ='Enhanced Basket_AUTOLOAD'!O2 -> 0 | I3: ='Enhanced Basket_AUTOLOAD'!P2 -> 0 | J3: ='Enhanced Basket_AUTOLOAD'!Q2 -> 0 | M3: =IF(I895="USCSH000000","",VLOOKUP(I3,'EZE Daily_With_BB CODES'!$H$3:$J$4445,3,0)) -> #N/A
F4: ='Enhanced Basket_AUTOLOAD'!H3 -> 0 | G4: ='Enhanced Basket_AUTOLOAD'!M3 -> 0 | H4: ='Enhanced Basket_AUTOLOAD'!O3 -> 0 | I4: ='Enhanced Basket_AUTOLOAD'!P3 -> 0 | J4: ='Enhanced Basket_AUTOLOAD'!Q3 -> 0 | M4: =IF(TRIM(CLEAN(I4))="USCSH0000000","",VLOOKUP(I4,'EZE Daily_With_BB CODES'!$H$3:$J$4445,3,0)) -> #N/A
F5: ='Enhanced Basket_AUTOLOAD'!H4 -> 0 | G5: ='Enhanced Basket_AUTOLOAD'!M4 -> 0 | H5: ='Enhanced Basket_AUTOLOAD'!O4 -> 0 | I5: ='Enhanced Basket_AUTOLOAD'!P4 -> 0 | J5: ='Enhanced Basket_AUTOLOAD'!Q4 -> 0 | M5: =IF(TRIM(CLEAN(I5))="USCSH0000000","",VLOOKUP(I5,'EZE Daily_With_BB CODES'!$H$3:$J$4445,3,0)) -> #N/A
F6: ='Enhanced Basket_AUTOLOAD'!H5 -> 0 | G6: ='Enhanced Basket_AUTOLOAD'!M5 -> 0 | H6: ='Enhanced Basket_AUTOLOAD'!O5 -> 0 | I6: ='Enhanced Basket_AUTOLOAD'!P5 -> 0 | J6: ='Enhanced Basket_AUTOLOAD'!Q5 -> 0 | M6: =IF(TRIM(CLEAN(I6))="USCSH0000000","",VLOOKUP(I6,'EZE Daily_With_BB CODES'!$H$3:$J$4445,3,0)) -> #N/A
F7: ='Enhanced Basket_AUTOLOAD'!H6 -> 0 | G7: ='Enhanced Basket_AUTOLOAD'!M6 -> 0 | H7: ='Enhanced Basket_AUTOLOAD'!O6 -> 0 | I7: ='Enhanced Basket_AUTOLOAD'!P6 -> 0 | J7: ='Enhanced Basket_AUTOLOAD'!Q6 -> 0 | M7: =IF(TRIM(CLEAN(I7))="USCSH0000000","",VLOOKUP(I7,'EZE Daily_With_BB CODES'!$H$3:$J$4445,3,0)) -> #N/A
F8: ='Enhanced Basket_AUTOLOAD'!H7 -> 0 | G8: ='Enhanced Basket_AUTOLOAD'!M7 -> 0 | H8: ='Enhanced Basket_AUTOLOAD'!O7 -> 0 | I8: ='Enhanced Basket_AUTOLOAD'!P7 -> 0 | J8: ='Enhanced Basket_AUTOLOAD'!Q7 -> 0 | M8: =IF(TRIM(CLEAN(I8))="USCSH0000000","",VLOOKUP(I8,'EZE Daily_With_BB CODES'!$H$3:$J$4445,3,0)) -> #N/A
F9: ='Enhanced Basket_AUTOLOAD'!H8 -> 0 | G9: ='Enhanced Basket_AUTOLOAD'!M8 -> 0 | H9: ='Enhanced Basket_AUTOLOAD'!O8 -> 0 | I9: ='Enhanced Basket_AUTOLOAD'!P8 -> 0 | J9: ='Enhanced Basket_AUTOLOAD'!Q8 -> 0 | M9: =IF(TRIM(CLEAN(I9))="USCSH0000000","",VLOOKUP(I9,'EZE Daily_With_BB CODES'!$H$3:$J$4445,3,0)) -> #N/A
F10: ='Enhanced Basket_AUTOLOAD'!H9 -> 0 | G10: ='Enhanced Basket_AUTOLOAD'!M9 -> 0 | H10: ='Enhanced Basket_AUTOLOAD'!O9 -> 0 | I10: ='Enhanced Basket_AUTOLOAD'!P9 -> 0 | J10: ='Enhanced Basket_AUTOLOAD'!Q9 -> 0 | M10: =IF(TRIM(CLEAN(I10))="USCSH0000000","",VLOOKUP(I10,'EZE Daily_With_BB CODES'!$H$3:$J$4445,3,0)) -> #N/A
F11: ='Enhanced Basket_AUTOLOAD'!H10 -> 0 | G11: ='Enhanced Basket_AUTOLOAD'!M10 -> 0 | H11: ='Enhanced Basket_AUTOLOAD'!O10 -> 0 | I11: ='Enhanced Basket_AUTOLOAD'!P10 -> 0 | J11: ='Enhanced Basket_AUTOLOAD'!Q10 -> 0 | M11: =IF(TRIM(CLEAN(I11))="USCSH0000000","",VLOOKUP(I11,'EZE Daily_With_BB CODES'!$H$3:$J$4445,3,0)) -> #N/A
F12: ='Enhanced Basket_AUTOLOAD'!H11 -> 0 | G12: ='Enhanced Basket_AUTOLOAD'!M11 -> 0 | H12: ='Enhanced Basket_AUTOLOAD'!O11 -> 0 | I12: ='Enhanced Basket_AUTOLOAD'!P11 -> 0 | J12: ='Enhanced Basket_AUTOLOAD'!Q11 -> 0 | M12: =IF(TRIM(CLEAN(I12))="USCSH0000000","",VLOOKUP(I12,'EZE Daily_With_BB CODES'!$H$3:$J$4445,3,0)) -> #N/A
F13: ='Enhanced Basket_AUTOLOAD'!H12 -> 0 | G13: ='Enhanced Basket_AUTOLOAD'!M12 -> 0 | H13: ='Enhanced Basket_AUTOLOAD'!O12 -> 0 | I13: ='Enhanced Basket_AUTOLOAD'!P12 -> 0 | J13: ='Enhanced Basket_AUTOLOAD'!Q12 -> 0 | M13: =IF(TRIM(CLEAN(I13))="USCSH0000000","",VLOOKUP(I13,'EZE Daily_With_BB CODES'!$H$3:$J$4445,3,0)) -> #N/A
F14: ='Enhanced Basket_AUTOLOAD'!H13 -> 0 | G14: ='Enhanced Basket_AUTOLOAD'!M13 -> 0 | H14: ='Enhanced Basket_AUTOLOAD'!O13 -> 0 | I14: ='Enhanced Basket_AUTOLOAD'!P13 -> 0 | J14: ='Enhanced Basket_AUTOLOAD'!Q13 -> 0 | M14: =IF(TRIM(CLEAN(I14))="USCSH0000000","",VLOOKUP(I14,'EZE Daily_With_BB CODES'!$H$3:$J$4445,3,0)) -> #N/A
F15: ='Enhanced Basket_AUTOLOAD'!H14 -> 0 | G15: ='Enhanced Basket_AUTOLOAD'!M14 -> 0 | H15: ='Enhanced Basket_AUTOLOAD'!O14 -> 0 | I15: ='Enhanced Basket_AUTOLOAD'!P14 -> 0 | J15: ='Enhanced Basket_AUTOLOAD'!Q14 -> 0 | M15: =IF(TRIM(CLEAN(I15))="USCSH0000000","",VLOOKUP(I15,'EZE Daily_With_BB CODES'!$H$3:$J$4445,3,0)) -> #N/A
... F397: ='Enhanced Basket_AUTOLOAD'!H396 -> 0 | G397: ='Enhanced Basket_AUTOLOAD'!M396 -> 0 | H397: ='Enhanced Basket_AUTOLOAD'!O396 -> 0 | I397: ='Enhanced Basket_AUTOLOAD'!P396 -> 0 | J397: ='Enhanced Basket_AUTOLOAD'!Q396 -> 0 | M397: =IF(TRIM(CLEAN(I397))="USCSH0000000","",VLOOKUP(I397,'EZE Daily_With_BB CODES'!$H$3:$J$4445,3,0)) -> #N/A
F398: ='Enhanced Basket_AUTOLOAD'!H397 -> 0 | G398: ='Enhanced Basket_AUTOLOAD'!M397 -> 0 | H398: ='Enhanced Basket_AUTOLOAD'!O397 -> 0 | I398: ='Enhanced Basket_AUTOLOAD'!P397 -> 0 | J398: ='Enhanced Basket_AUTOLOAD'!Q397 -> 0 | M398: =IF(TRIM(CLEAN(I398))="USCSH0000000","",VLOOKUP(I398,'EZE Daily_With_BB CODES'!$H$3:$J$4445,3,0)) -> #N/A | X398: =IF(SUMPRODUCT((F:F=X2)*+ISNA(M:M))>0,"Yes","No") -> Yes
F399: ='Enhanced Basket_AUTOLOAD'!H398 -> 0 | G399: ='Enhanced Basket_AUTOLOAD'!M398 -> 0 | H399: ='Enhanced Basket_AUTOLOAD'!O398 -> 0 | I399: ='Enhanced Basket_AUTOLOAD'!P398 -> 0 | J399: ='Enhanced Basket_AUTOLOAD'!Q398 -> 0 | M399: =IF(TRIM(CLEAN(I399))="USCSH0000000","",VLOOKUP(I399,'EZE Daily_With_BB CODES'!$H$3:$J$4445,3,0)) -> #N/A
F400: ='Enhanced Basket_AUTOLOAD'!H399 -> 0 | G400: ='Enhanced Basket_AUTOLOAD'!M399 -> 0 | H400: ='Enhanced Basket_AUTOLOAD'!O399 -> 0 | I400: ='Enhanced Basket_AUTOLOAD'!P399 -> 0 | J400: ='Enhanced Basket_AUTOLOAD'!Q399 -> 0 | M400: =IF(TRIM(CLEAN(I400))="USCSH0000000","",VLOOKUP(I400,'EZE Daily_With_BB CODES'!$H$3:$J$4445,3,0)) -> #N/A
F401: ='Enhanced Basket_AUTOLOAD'!H400 -> 0 | G401: ='Enhanced Basket_AUTOLOAD'!M400 -> 0 | H401: ='Enhanced Basket_AUTOLOAD'!O400 -> 0 | I401: ='Enhanced Basket_AUTOLOAD'!P400 -> 0 | J401: ='Enhanced Basket_AUTOLOAD'!Q400 -> 0 | M401: =IF(TRIM(CLEAN(I401))="USCSH0000000","",VLOOKUP(I401,'EZE Daily_With_BB CODES'!$H$3:$J$4445,3,0)) -> #N/A
