Workbook
Name ifs: #REF!
Name ifs: 'JP Code_Sheet'!$N$3
Name sumif: #REF!
Name sumif: 'JP Code_Sheet'!$N$3

Sheet JP_POSTED CASH_Detail
A1: Report Name: Posted Cash - Detail | C1: (Sent to passive:RANCIS VARIATION MARGIN CHECK:~7:30am) | D1: Use Second TAB
A2: From Date: 24-Jan-2023 To Date: 24-Jan-2023
A3: Run ID: S-641-061-435
A5: Cash Account Number | B5: Posted Date | C5: Transaction Group Description | D5: Account Number | E5: Security Name | F5: Transaction Number | G5: Transaction Category Description | H5: Transaction Status Description | I5: Account Name | J5: Cash Account Name | K5: Cash Account CCY Code | L5: Linked Custody Account | M5: Location/Nominee Code | N5: Location/Nominee Name | O5: Reg./Sub Acct Code | P5: Reg./Sub Acct Name | Q5: ASDA/CSDA | R5: Collection Status Description | S5: Customer Reference 1 | T5: Customer Reference 2 | U5: Income Reference | V5: Transaction Type Description | W5: Asset Type Description | X5: Asset Category Description | Y5: Security ID | Z5: Coupon Rate | AA5: Maturity Date | AB5: Pool Number | AC5: ISIN | AD5: Ticker | AE5: Units | AF5: Current Face | AG5: Price | AH5: Gross Amount | AI5: Gross Amount CCY Code | AJ5: Principal Amount | AK5: Income Amount | AL5: Commission | AM5: Commission CCY Code | AN5: Other Charges | AO5: UK Withholding Tax | AP5: UK Withholding Tax CCY Code | AQ5: Non UK Withholding Tax | AR5: Non UK Withholding Tax CCY Code | AS5: Source Tax/NRA | AT5: Source Tax/NRA CCY Code | AU5: Net Amount | AV5: Exchange Rate | AW5: Trade Date | AX5: Contractual S/D | AY5: Autosettle Date | AZ5: Ex Date | BA5: Record Date | BB5: Payable Date | BC5: Value Date | BD5: Last Update Date | BE5: Last Update Time | BF5: Dividend/Interest Rate | BG5: UK Withholding Rate | BH5: Non UK Withholding Rate | BI5: Source Tax/NRA Rate | BJ5: Factor | BK5: Previous Factor | BL5: Principal MOF | BM5: Interest MOF | BN5: Trading Broker Number | BO5: Trading Broker Name | BP5: Clearing Broker Number | BQ5: Clearing Broker Name | BR5: Additional Information | BS5: Bank Reference Number | BT5: By Order Of | BU5: Sending/Receiving Bank | BV5: OCC ID | BW5: S and P CUSIP | BX5: NIL Payment/Unknown Rate | BY5: Branch Code | BZ5: Branch Name | CA5: DGSD Eligible

Sheet JP_Cash Projection - Statement
A1: Cash Projections - Statement | B1: INTRADAY (RUN at 9:00)
A2: As Of Date: 14-Jun-2022
A3: Run ID: D-628-797-558
A5: Cash Account CCY Code | B5: Cash Account Number (Balance) | C5: Account Number (Balance) | D5: Account Name (Balance) | E5: Projected Date | F5: Net Opening Cash Balance | G5: Sweep Balance | H5: Total Settled Amount | I5: Total Projected Amount | J5: Projected Ending Balance | K5: Cash Account Name (Balance) | L5: Settled Purchases | M5: Settled Sales | N5: Settled Securities Lending | O5: Settled Dividend Payments | P5: Settled Interest Payments | Q5: Settled Principal Payments | R5: Settled Combined P and I | S5: Settled Maturities/RDM | T5: Settled Corporate Actions | U5: Settled Options/Futures | V5: Settled Miscellaneous | W5: Settled Receipts | X5: Settled Disbursements | Y5: Projected Purchases | Z5: Projected Sales | AA5: Projected Securities Lending | AB5: Projected Dividend Payments | AC5: Projected Interest Payments | AD5: Projected Principal Payments | AE5: Projected Combined P and I | AF5: Projected Maturities/RDM | AG5: Projected Corporate Actions | AH5: Projected Options/Futures | AI5: Projected Miscellaneous | AJ5: Projected Receipts | AK5: Projected Disbursements | AL5: Branch Code | AM5: Branch Name

Sheet JP_Cash Projection - Detail
A1: Cash Projections - Detail | B1: INTRADAY (RUN at 10:00)
A2: As Of Date: 14-Jun-2022
A3: Run ID: D-628-797-558
A5: Cash Account CCY Code | B5: Cash Account Number | C5: Transaction Group Description | D5: Transaction Status Description | E5: Projected Date | F5: Security Name | G5: Transaction Number | H5: Transaction Category Description | I5: Account Number | J5: Account Name | K5: Cash Account Name | L5: Linked Custody Account | M5: Location/Nominee Code | N5: Location/Nominee Name | O5: Reg./Sub Acct Code | P5: Reg./Sub Acct Name | Q5: ASDA/CSDA | R5: Matched | S5: Collection Status Description | T5: Customer Reference 1 | U5: Customer Reference 2 | V5: Income Reference | W5: Transaction Type Description | X5: Asset Type Description | Y5: Asset Category Description | Z5: Security ID | AA5: Coupon Rate | AB5: Maturity Date | AC5: Pool Number | AD5: ISIN | AE5: Ticker | AF5: Units | AG5: Current Face | AH5: Price | AI5: Gross Amount | AJ5: Gross Amount CCY Code | AK5: Principal Amount | AL5: Income Amount | AM5: Commission | AN5: Commission CCY Code | AO5: Other Charges | AP5: UK Withholding Tax | AQ5: UK Withholding Tax CCY Code | AR5: Non UK Withholding Tax | AS5: Non UK Withholding Tax CCY Code | AT5: Source Tax/NRA | AU5: Source Tax/NRA CCY Code | AV5: Net Amount | AW5: Exchange Rate | AX5: Trade Date | AY5: Contractual S/D | AZ5: Posted Date | BA5: Autosettle Date | BB5: Ex Date | BC5: Record Date | BD5: Payable Date | BE5: Value Date | BF5: Last Update Date | BG5: Last Update Time | BH5: Creation Date | BI5: Dividend/Interest Rate | BJ5: UK Withholding Rate | BK5: Non UK Withholding Rate | BL5: Source Tax/NRA Rate | BM5: Factor | BN5: Previous Factor | BO5: Principal MOF | BP5: Interest MOF | BQ5: Trading Broker Number | BR5: Trading Broker Name | BS5: Clearing Broker Number | BT5: Clearing Broker Name | BU5: Additional Information | BV5: Bank Reference Number | BW5: Sending/Receiving Bank | BX5: By Order Of | BY5: OCC ID | BZ5: S and P CUSIP | CA5: NIL Payment/Unknown Rate | CB5: Branch Code | CC5: Branch Name

Sheet JP_Priced Positions_custody
A1: Priced Positions | C1: INTRADAY (RUN at 9:00)
A2: As Of Date: 14-Jun-2022
A3: Run ID: D-628-813-198
A5: Account Number | B5: Cash Account CCY Code | C5: Cash Account Number | D5: Security Name | E5: Location Nominee Code | F5: Reg./Sub Acct Code | G5: Account Name | H5: Linked Custody Account | I5: Cash Account Name | J5: Last Update Date | K5: Asset Type Description | L5: Asset Category Description | M5: Security ID | N5: ISIN | O5: Ticker | P5: Coupon Rate | Q5: Dated Date | R5: Maturity Date | S5: Pool Number | T5: Awaiting Receipt | U5: Awaiting Delivery | V5: In Transit (US) | W5: At Registrar (Glbl) | X5: On Loan | Y5: Pledged (US) | Z5: Available | AA5: Settled Units | AB5: Current Face (Settled) | AC5: Total Units | AD5: Current Face (Total) | AE5: Nominal Value | AF5: Blocked Quantity | AG5: Local Currency | AH5: Market Price | AI5: Price Date | AJ5: Settled Market Value (Local) | AK5: Total Market Value (Local) | AL5: Base Currency | AM5: Exchange Rate | AN5: Settled Market Value (Base) | AO5: Total Market Value (Base) | AP5: Factor | AQ5: Factor Date | AR5: Previous Factor | AS5: Country Code | AT5: Country Description | AU5: Location Nominee Name | AV5: Reg./Sub Acct Name | AW5: Sub Account Type Description | AX5: Location/Nominee Country Code | AY5: Location/Nominee Country Name | AZ5: OCC ID | BA5: S and P CUSIP | BB5: Public CUSIP | BC5: Branch Code | BD5: Branch Name | BE5: DGSD Eligible

Sheet JP_Outstanding Trades
A1: Outstanding Trades
A2: From Date: 17-Jun-2022 To Date: 17-Jun-2022 | B2: INTRA_DAY | C2: Exlcude todays trades
A3: Run ID: D-629-027-467
A5: Account Number | B5: Contractual S/D | C5: Net Amount CCY Code | D5: Transaction Category Description | E5: Transaction Status Description | F5: Account Name | G5: Security ID | H5: ISIN | I5: OCC ID | J5: Security Name | K5: Coupon Rate | L5: Maturity Date | M5: Pool Number | N5: Fail Description | O5: Transaction Type Description | P5: Age (Days) | Q5: Transaction Number | R5: Trading Broker Name | S5: Trade Date | T5: Autosettle Date | U5: Units | V5: Current Face | W5: Net Amount | X5: Elective Event Impact

Sheet Previous Trades Import_OMS Quer
A1: SecType | B1: Portfolio | C1: TradeDate | D1: Trdr | E1: SettleDate | F1: Dest | G1: Side | H1: SecurityDesc | I1: Symbol | J1: AvgPrc | K1: Amount | L1: Done | M1: NetMoney | N1: Note | O1: Currency

Sheet Previous Trade Calc
A1: SecType | B1: Portfolio | C1: TradeDate | D1: Trdr | E1: SettleDate | F1: Dest | G1: Side | H1: SecurityDesc | I1: Symbol | J1: AvgPrc | K1: Amount | L1: Done | M1: NetMoney | N1: Note | O1: Currency | Q1: LOCAL | R1: FX RATE | S1: USD
A2: ='Previous Trades Import_OMS Quer'!A2 -> 0 | B2: ='Previous Trades Import_OMS Quer'!B2 -> 0 | C2: ='Previous Trades Import_OMS Quer'!C2 -> 0 | D2: ='Previous Trades Import_OMS Quer'!D2 -> 0 | E2: ='Previous Trades Import_OMS Quer'!E2 -> 0 | F2: ='Previous Trades Import_OMS Quer'!F2 -> 0 | G2: ='Previous Trades Import_OMS Quer'!G2 -> 0 | H2: ='Previous Trades Import_OMS Quer'!H2 -> 0 | ... N2: ='Previous Trades Import_OMS Quer'!N2 -> 0 | O2: =CLEAN('Previous Trades Import_OMS Quer'!O2) | Q2: =IF(G2="sell",M2,-M2) -> 0 | R2: =VLOOKUP(O2,'Currency Balance'!$O$3:$Q$32,3,0) -> #N/A | S2: =Q2/R2 -> #N/A
A3: ='Previous Trades Import_OMS Quer'!A3 -> 0 | B3: ='Previous Trades Import_OMS Quer'!B3 -> 0 | C3: ='Previous Trades Import_OMS Quer'!C3 -> 0 | D3: ='Previous Trades Import_OMS Quer'!D3 -> 0 | E3: ='Previous Trades Import_OMS Quer'!E3 -> 0 | F3: ='Previous Trades Import_OMS Quer'!F3 -> 0 | G3: ='Previous Trades Import_OMS Quer'!G3 -> 0 | H3: ='Previous Trades Import_OMS Quer'!H3 -> 0 | ... N3: ='Previous Trades Import_OMS Quer'!N3 -> 0 | O3: =CLEAN('Previous Trades Import_OMS Quer'!O3) | Q3: =IF(G3="sell",M3,-M3) -> 0 | R3: =VLOOKUP(O3,'Currency Balance'!$O$3:$Q$32,3,0) -> #N/A | S3: =Q3/R3 -> #N/A
A4: ='Previous Trades Import_OMS Quer'!A4 -> 0 | B4: ='Previous Trades Import_OMS Quer'!B4 -> 0 | C4: ='Previous Trades Import_OMS Quer'!C4 -> 0 | D4: ='Previous Trades Import_OMS Quer'!D4 -> 0 | E4: ='Previous Trades Import_OMS Quer'!E4 -> 0 | F4: ='Previous Trades Import_OMS Quer'!F4 -> 0 | G4: ='Previous Trades Import_OMS Quer'!G4 -> 0 | H4: ='Previous Trades Import_OMS Quer'!H4 -> 0 | ... N4: ='Previous Trades Import_OMS Quer'!N4 -> 0 | O4: =CLEAN('Previous Trades Import_OMS Quer'!O4) | Q4: =IF(G4="sell",M4,-M4) -> 0 | R4: =VLOOKUP(O4,'Currency Balance'!$O$3:$Q$32,3,0) -> #N/A | S4: =Q4/R4 -> #N/A
A5: ='Previous Trades Import_OMS Quer'!A5 -> 0 | B5: ='Previous Trades Import_OMS Quer'!B5 -> 0 | C5: ='Previous Trades Import_OMS Quer'!C5 -> 0 | D5: ='Previous Trades Import_OMS Quer'!D5 -> 0 | E5: ='Previous Trades Import_OMS Quer'!E5 -> 0 | F5: ='Previous Trades Import_OMS Quer'!F5 -> 0 | G5: ='Previous Trades Import_OMS Quer'!G5 -> 0 | H5: ='Previous Trades Import_OMS Quer'!H5 -> 0 | ... N5: ='Previous Trades Import_OMS Quer'!N5 -> 0 | O5: =CLEAN('Previous Trades Import_OMS Quer'!O5) | Q5: =IF(G5="sell",M5,-M5) -> 0 | R5: =VLOOKUP(O5,'Currency Balance'!$O$3:$Q$32,3,0) -> #N/A | S5: =Q5/R5 -> #N/A
A6: ='Previous Trades Import_OMS Quer'!A6 -> 0 | B6: ='Previous Trades Import_OMS Quer'!B6 -> 0 | C6: ='Previous Trades Import_OMS Quer'!C6 -> 0 | D6: ='Previous Trades Import_OMS Quer'!D6 -> 0 | E6: ='Previous Trades Import_OMS Quer'!E6 -> 0 | F6: ='Previous Trades Import_OMS Quer'!F6 -> 0 | G6: ='Previous Trades Import_OMS Quer'!G6 -> 0 | H6: ='Previous Trades Import_OMS Quer'!H6 -> 0 | ... N6: ='Previous Trades Import_OMS Quer'!N6 -> 0 | O6: =CLEAN('Previous Trades Import_OMS Quer'!O6) | Q6: =IF(G6="sell",M6,-M6) -> 0 | R6: =VLOOKUP(O6,'Currency Balance'!$O$3:$Q$32,3,0) -> #N/A | S6: =Q6/R6 -> #N/A
A7: ='Previous Trades Import_OMS Quer'!A7 -> 0 | B7: ='Previous Trades Import_OMS Quer'!B7 -> 0 | C7: ='Previous Trades Import_OMS Quer'!C7 -> 0 | D7: ='Previous Trades Import_OMS Quer'!D7 -> 0 | E7: ='Previous Trades Import_OMS Quer'!E7 -> 0 | F7: ='Previous Trades Import_OMS Quer'!F7 -> 0 | G7: ='Previous Trades Import_OMS Quer'!G7 -> 0 | H7: ='Previous Trades Import_OMS Quer'!H7 -> 0 | ... N7: ='Previous Trades Import_OMS Quer'!N7 -> 0 | O7: =CLEAN('Previous Trades Import_OMS Quer'!O7) | Q7: =IF(G7="sell",M7,-M7) -> 0 | R7: =VLOOKUP(O7,'Currency Balance'!$O$3:$Q$32,3,0) -> #N/A | S7: =Q7/R7 -> #N/A
A8: ='Previous Trades Import_OMS Quer'!A8 -> 0 | B8: ='Previous Trades Import_OMS Quer'!B8 -> 0 | C8: ='Previous Trades Import_OMS Quer'!C8 -> 0 | D8: ='Previous Trades Import_OMS Quer'!D8 -> 0 | E8: ='Previous Trades Import_OMS Quer'!E8 -> 0 | F8: ='Previous Trades Import_OMS Quer'!F8 -> 0 | G8: ='Previous Trades Import_OMS Quer'!G8 -> 0 | H8: ='Previous Trades Import_OMS Quer'!H8 -> 0 | ... N8: ='Previous Trades Import_OMS Quer'!N8 -> 0 | O8: =CLEAN('Previous Trades Import_OMS Quer'!O8) | Q8: =IF(G8="sell",M8,-M8) -> 0 | R8: =VLOOKUP(O8,'Currency Balance'!$O$3:$Q$32,3,0) -> #N/A | S8: =Q8/R8 -> #N/A
A9: ='Previous Trades Import_OMS Quer'!A9 -> 0 | B9: ='Previous Trades Import_OMS Quer'!B9 -> 0 | C9: ='Previous Trades Import_OMS Quer'!C9 -> 0 | D9: ='Previous Trades Import_OMS Quer'!D9 -> 0 | E9: ='Previous Trades Import_OMS Quer'!E9 -> 0 | F9: ='Previous Trades Import_OMS Quer'!F9 -> 0 | G9: ='Previous Trades Import_OMS Quer'!G9 -> 0 | H9: ='Previous Trades Import_OMS Quer'!H9 -> 0 | ... N9: ='Previous Trades Import_OMS Quer'!N9 -> 0 | O9: =CLEAN('Previous Trades Import_OMS Quer'!O9) | Q9: =IF(G9="sell",M9,-M9) -> 0 | R9: =VLOOKUP(O9,'Currency Balance'!$O$3:$Q$32,3,0) -> #N/A | S9: =Q9/R9 -> #N/A
A10: ='Previous Trades Import_OMS Quer'!A10 -> 0 | B10: ='Previous Trades Import_OMS Quer'!B10 -> 0 | C10: ='Previous Trades Import_OMS Quer'!C10 -> 0 | D10: ='Previous Trades Import_OMS Quer'!D10 -> 0 | E10: ='Previous Trades Import_OMS Quer'!E10 -> 0 | F10: ='Previous Trades Import_OMS Quer'!F10 -> 0 | G10: ='Previous Trades Import_OMS Quer'!G10 -> 0 | H10: ='Previous Trades Import_OMS Quer'!H10 -> 0 | ... N10: ='Previous Trades Import_OMS Quer'!N10 -> 0 | O10: =CLEAN('Previous Trades Import_OMS Quer'!O10) | Q10: =IF(G10="sell",M10,-M10) -> 0 | R10: =VLOOKUP(O10,'Currency Balance'!$O$3:$Q$32,3,0) -> #N/A | S10: =Q10/R10 -> #N/A
A11: ='Previous Trades Import_OMS Quer'!A11 -> 0 | B11: ='Previous Trades Import_OMS Quer'!B11 -> 0 | C11: ='Previous Trades Import_OMS Quer'!C11 -> 0 | D11: ='Previous Trades Import_OMS Quer'!D11 -> 0 | E11: ='Previous Trades Import_OMS Quer'!E11 -> 0 | F11: ='Previous Trades Import_OMS Quer'!F11 -> 0 | G11: ='Previous Trades Import_OMS Quer'!G11 -> 0 | H11: ='Previous Trades Import_OMS Quer'!H11 -> 0 | ... N11: ='Previous Trades Import_OMS Quer'!N11 -> 0 | O11: =CLEAN('Previous Trades Import_OMS Quer'!O11) | Q11: =IF(G11="sell",M11,-M11) -> 0 | R11: =VLOOKUP(O11,'Currency Balance'!$O$3:$Q$32,3,0) -> #N/A | S11: =Q11/R11 -> #N/A
A12: ='Previous Trades Import_OMS Quer'!A12 -> 0 | B12: ='Previous Trades Import_OMS Quer'!B12 -> 0 | C12: ='Previous Trades Import_OMS Quer'!C12 -> 0 | D12: ='Previous Trades Import_OMS Quer'!D12 -> 0 | E12: ='Previous Trades Import_OMS Quer'!E12 -> 0 | F12: ='Previous Trades Import_OMS Quer'!F12 -> 0 | G12: ='Previous Trades Import_OMS Quer'!G12 -> 0 | H12: ='Previous Trades Import_OMS Quer'!H12 -> 0 | ... N12: ='Previous Trades Import_OMS Quer'!N12 -> 0 | O12: =CLEAN('Previous Trades Import_OMS Quer'!O12) | Q12: =IF(G12="sell",M12,-M12) -> 0 | R12: =VLOOKUP(O12,'Currency Balance'!$O$3:$Q$32,3,0) -> #N/A | S12: =Q12/R12 -> #N/A
A13: ='Previous Trades Import_OMS Quer'!A13 -> 0 | B13: ='Previous Trades Import_OMS Quer'!B13 -> 0 | C13: ='Previous Trades Import_OMS Quer'!C13 -> 0 | D13: ='Previous Trades Import_OMS Quer'!D13 -> 0 | E13: ='Previous Trades Import_OMS Quer'!E13 -> 0 | F13: ='Previous Trades Import_OMS Quer'!F13 -> 0 | G13: ='Previous Trades Import_OMS Quer'!G13 -> 0 | H13: ='Previous Trades Import_OMS Quer'!H13 -> 0 | ... N13: ='Previous Trades Import_OMS Quer'!N13 -> 0 | O13: =CLEAN('Previous Trades Import_OMS Quer'!O13) | Q13: =IF(G13="sell",M13,-M13) -> 0 | R13: =VLOOKUP(O13,'Currency Balance'!$O$3:$Q$32,3,0) -> #N/A | S13: =Q13/R13 -> #N/A
... A179: ='Previous Trades Import_OMS Quer'!A179 -> 0 | B179: ='Previous Trades Import_OMS Quer'!B179 -> 0 | C179: ='Previous Trades Import_OMS Quer'!C179 -> 0 | D179: ='Previous Trades Import_OMS Quer'!D179 -> 0 | E179: ='Previous Trades Import_OMS Quer'!E179 -> 0 | F179: ='Previous Trades Import_OMS Quer'!F179 -> 0 | G179: ='Previous Trades Import_OMS Quer'!G179 -> 0 | H179: ='Previous Trades Import_OMS Quer'!H179 -> 0 | ... N179: ='Previous Trades Import_OMS Quer'!N179 -> 0 | O179: =CLEAN('Previous Trades Import_OMS Quer'!O179) | Q179: =IF(G179="sell",M179,-M179) -> 0 | R179: =VLOOKUP(O179,'Currency Balance'!$O$3:$Q$32,3,0) -> #N/A | S179: =Q179/R179 -> #N/A
A180: ='Previous Trades Import_OMS Quer'!A180 -> 0 | B180: ='Previous Trades Import_OMS Quer'!B180 -> 0 | C180: ='Previous Trades Import_OMS Quer'!C180 -> 0 | D180: ='Previous Trades Import_OMS Quer'!D180 -> 0 | E180: ='Previous Trades Import_OMS Quer'!E180 -> 0 | F180: ='Previous Trades Import_OMS Quer'!F180 -> 0 | G180: ='Previous Trades Import_OMS Quer'!G180 -> 0 | H180: ='Previous Trades Import_OMS Quer'!H180 -> 0 | ... N180: ='Previous Trades Import_OMS Quer'!N180 -> 0 | O180: =CLEAN('Previous Trades Import_OMS Quer'!O180) | Q180: =IF(G180="sell",M180,-M180) -> 0 | R180: =VLOOKUP(O180,'Currency Balance'!$O$3:$Q$32,3,0) -> #N/A | S180: =Q180/R180 -> #N/A | T180: =L180*50*I180 -> 0
A181: ='Previous Trades Import_OMS Quer'!A181 -> 0 | B181: ='Previous Trades Import_OMS Quer'!B181 -> 0 | C181: ='Previous Trades Import_OMS Quer'!C181 -> 0 | D181: ='Previous Trades Import_OMS Quer'!D181 -> 0 | E181: ='Previous Trades Import_OMS Quer'!E181 -> 0 | F181: ='Previous Trades Import_OMS Quer'!F181 -> 0 | G181: ='Previous Trades Import_OMS Quer'!G181 -> 0 | H181: ='Previous Trades Import_OMS Quer'!H181 -> 0 | ... N181: ='Previous Trades Import_OMS Quer'!N181 -> 0 | O181: =CLEAN('Previous Trades Import_OMS Quer'!O181) | Q181: =IF(G181="sell",M181,-M181) -> 0 | R181: =VLOOKUP(O181,'Currency Balance'!$O$3:$Q$32,3,0) -> #N/A | S181: =Q181/R181 -> #N/A
A182: ='Previous Trades Import_OMS Quer'!A182 -> 0 | B182: ='Previous Trades Import_OMS Quer'!B182 -> 0 | C182: ='Previous Trades Import_OMS Quer'!C182 -> 0 | D182: ='Previous Trades Import_OMS Quer'!D182 -> 0 | E182: ='Previous Trades Import_OMS Quer'!E182 -> 0 | F182: ='Previous Trades Import_OMS Quer'!F182 -> 0 | G182: ='Previous Trades Import_OMS Quer'!G182 -> 0 | H182: ='Previous Trades Import_OMS Quer'!H182 -> 0 | ... N182: ='Previous Trades Import_OMS Quer'!N182 -> 0 | O182: =CLEAN('Previous Trades Import_OMS Quer'!O182) | Q182: =IF(G182="sell",M182,-M182) -> 0 | R182: =VLOOKUP(O182,'Currency Balance'!$O$3:$Q$32,3,0) -> #N/A | S182: =Q182/R182 -> #N/A
A183: ='Previous Trades Import_OMS Quer'!A183 -> 0 | B183: ='Previous Trades Import_OMS Quer'!B183 -> 0 | C183: ='Previous Trades Import_OMS Quer'!C183 -> 0 | D183: ='Previous Trades Import_OMS Quer'!D183 -> 0 | E183: ='Previous Trades Import_OMS Quer'!E183 -> 0 | F183: ='Previous Trades Import_OMS Quer'!F183 -> 0 | G183: ='Previous Trades Import_OMS Quer'!G183 -> 0 | H183: ='Previous Trades Import_OMS Quer'!H183 -> 0 | ... N183: ='Previous Trades Import_OMS Quer'!N183 -> 0 | O183: =CLEAN('Previous Trades Import_OMS Quer'!O183) | Q183: =IF(G183="sell",M183,-M183) -> 0 | R183: =VLOOKUP(O183,'Currency Balance'!$O$3:$Q$32,3,0) -> #N/A | S183: =Q183/R183 -> #N/A
A184: ='Previous Trades Import_OMS Quer'!A184 -> 0 | B184: ='Previous Trades Import_OMS Quer'!B184 -> 0 | C184: ='Previous Trades Import_OMS Quer'!C184 -> 0 | D184: ='Previous Trades Import_OMS Quer'!D184 -> 0 | E184: ='Previous Trades Import_OMS Quer'!E184 -> 0 | F184: ='Previous Trades Import_OMS Quer'!F184 -> 0 | G184: ='Previous Trades Import_OMS Quer'!G184 -> 0 | H184: ='Previous Trades Import_OMS Quer'!H184 -> 0 | ... N184: ='Previous Trades Import_OMS Quer'!N184 -> 0 | O184: =CLEAN('Previous Trades Import_OMS Quer'!O184) | Q184: =IF(G184="sell",M184,-M184) -> 0 | R184: =VLOOKUP(O184,'Currency Balance'!$O$3:$Q$32,3,0) -> #N/A | S184: =Q184/R184 -> #N/A
A185: ='Previous Trades Import_OMS Quer'!A185 -> 0 | B185: ='Previous Trades Import_OMS Quer'!B185 -> 0 | C185: ='Previous Trades Import_OMS Quer'!C185 -> 0 | D185: ='Previous Trades Import_OMS Quer'!D185 -> 0 | E185: ='Previous Trades Import_OMS Quer'!E185 -> 0 | F185: ='Previous Trades Import_OMS Quer'!F185 -> 0 | G185: ='Previous Trades Import_OMS Quer'!G185 -> 0 | H185: ='Previous Trades Import_OMS Quer'!H185 -> 0 | ... N185: ='Previous Trades Import_OMS Quer'!N185 -> 0 | O185: =CLEAN('Previous Trades Import_OMS Quer'!O185) | Q185: =IF(G185="sell",M185,-M185) -> 0 | R185: =VLOOKUP(O185,'Currency Balance'!$O$3:$Q$32,3,0) -> #N/A | S185: =Q185/R185 -> #N/A
A186: ='Previous Trades Import_OMS Quer'!A186 -> 0 | B186: ='Previous Trades Import_OMS Quer'!B186 -> 0 | C186: ='Previous Trades Import_OMS Quer'!C186 -> 0 | D186: ='Previous Trades Import_OMS Quer'!D186 -> 0 | E186: ='Previous Trades Import_OMS Quer'!E186 -> 0 | F186: ='Previous Trades Import_OMS Quer'!F186 -> 0 | G186: ='Previous Trades Import_OMS Quer'!G186 -> 0 | H186: ='Previous Trades Import_OMS Quer'!H186 -> 0 | ... N186: ='Previous Trades Import_OMS Quer'!N186 -> 0 | O186: =CLEAN('Previous Trades Import_OMS Quer'!O186) | Q186: =IF(G186="sell",M186,-M186) -> 0 | R186: =VLOOKUP(O186,'Currency Balance'!$O$3:$Q$32,3,0) -> #N/A | S186: =Q186/R186 -> #N/A
A187: ='Previous Trades Import_OMS Quer'!A187 -> 0 | B187: ='Previous Trades Import_OMS Quer'!B187 -> 0 | C187: ='Previous Trades Import_OMS Quer'!C187 -> 0 | D187: ='Previous Trades Import_OMS Quer'!D187 -> 0 | E187: ='Previous Trades Import_OMS Quer'!E187 -> 0 | F187: ='Previous Trades Import_OMS Quer'!F187 -> 0 | G187: ='Previous Trades Import_OMS Quer'!G187 -> 0 | H187: ='Previous Trades Import_OMS Quer'!H187 -> 0 | ... N187: ='Previous Trades Import_OMS Quer'!N187 -> 0 | O187: =CLEAN('Previous Trades Import_OMS Quer'!O187) | Q187: =IF(G187="sell",M187,-M187) -> 0 | R187: =VLOOKUP(O187,'Currency Balance'!$O$3:$Q$32,3,0) -> #N/A | S187: =Q187/R187 -> #N/A
A188: ='Previous Trades Import_OMS Quer'!A188 -> 0 | B188: ='Previous Trades Import_OMS Quer'!B188 -> 0 | C188: ='Previous Trades Import_OMS Quer'!C188 -> 0 | D188: ='Previous Trades Import_OMS Quer'!D188 -> 0 | E188: ='Previous Trades Import_OMS Quer'!E188 -> 0 | F188: ='Previous Trades Import_OMS Quer'!F188 -> 0 | G188: ='Previous Trades Import_OMS Quer'!G188 -> 0 | H188: ='Previous Trades Import_OMS Quer'!H188 -> 0 | ... N188: ='Previous Trades Import_OMS Quer'!N188 -> 0 | O188: =CLEAN('Previous Trades Import_OMS Quer'!O188) | Q188: =IF(G188="sell",M188,-M188) -> 0 | R188: =VLOOKUP(O188,'Currency Balance'!$O$3:$Q$32,3,0) -> #N/A | S188: =Q188/R188 -> #N/A
A189: ='Previous Trades Import_OMS Quer'!A189 -> 0 | B189: ='Previous Trades Import_OMS Quer'!B189 -> 0 | C189: ='Previous Trades Import_OMS Quer'!C189 -> 0 | D189: ='Previous Trades Import_OMS Quer'!D189 -> 0 | E189: ='Previous Trades Import_OMS Quer'!E189 -> 0 | F189: ='Previous Trades Import_OMS Quer'!F189 -> 0 | G189: ='Previous Trades Import_OMS Quer'!G189 -> 0 | H189: ='Previous Trades Import_OMS Quer'!H189 -> 0 | ... N189: ='Previous Trades Import_OMS Quer'!N189 -> 0 | O189: =CLEAN('Previous Trades Import_OMS Quer'!O189) | Q189: =IF(G189="sell",M189,-M189) -> 0 | R189: =VLOOKUP(O189,'Currency Balance'!$O$3:$Q$32,3,0) -> #N/A | S189: =Q189/R189 -> #N/A
A190: ='Previous Trades Import_OMS Quer'!A190 -> 0 | B190: ='Previous Trades Import_OMS Quer'!B190 -> 0 | C190: ='Previous Trades Import_OMS Quer'!C190 -> 0 | D190: ='Previous Trades Import_OMS Quer'!D190 -> 0 | E190: ='Previous Trades Import_OMS Quer'!E190 -> 0 | F190: ='Previous Trades Import_OMS Quer'!F190 -> 0 | G190: ='Previous Trades Import_OMS Quer'!G190 -> 0 | H190: ='Previous Trades Import_OMS Quer'!H190 -> 0 | ... N190: ='Previous Trades Import_OMS Quer'!N190 -> 0 | O190: =CLEAN('Previous Trades Import_OMS Quer'!O190) | Q190: =IF(G190="sell",M190,-M190) -> 0 | R190: =VLOOKUP(O190,'Currency Balance'!$O$3:$Q$32,3,0) -> #N/A | S190: =Q190/R190 -> #N/A
A191: ='Previous Trades Import_OMS Quer'!A191 -> 0 | B191: ='Previous Trades Import_OMS Quer'!B191 -> 0 | C191: ='Previous Trades Import_OMS Quer'!C191 -> 0 | D191: ='Previous Trades Import_OMS Quer'!D191 -> 0 | E191: ='Previous Trades Import_OMS Quer'!E191 -> 0 | F191: ='Previous Trades Import_OMS Quer'!F191 -> 0 | G191: ='Previous Trades Import_OMS Quer'!G191 -> 0 | H191: ='Previous Trades Import_OMS Quer'!H191 -> 0 | ... N191: ='Previous Trades Import_OMS Quer'!N191 -> 0 | O191: =CLEAN('Previous Trades Import_OMS Quer'!O191) | Q191: =IF(G191="sell",M191,-M191) -> 0 | R191: =VLOOKUP(O191,'Currency Balance'!$O$3:$Q$32,3,0) -> #N/A | S191: =Q191/R191 -> #N/A
A192: ='Previous Trades Import_OMS Quer'!A192 -> 0 | B192: ='Previous Trades Import_OMS Quer'!B192 -> 0 | C192: ='Previous Trades Import_OMS Quer'!C192 -> 0 | D192: ='Previous Trades Import_OMS Quer'!D192 -> 0 | E192: ='Previous Trades Import_OMS Quer'!E192 -> 0 | F192: ='Previous Trades Import_OMS Quer'!F192 -> 0 | G192: ='Previous Trades Import_OMS Quer'!G192 -> 0 | H192: ='Previous Trades Import_OMS Quer'!H192 -> 0 | ... N192: ='Previous Trades Import_OMS Quer'!N192 -> 0 | O192: =CLEAN('Previous Trades Import_OMS Quer'!O192) | Q192: =IF(G192="sell",M192,-M192) -> 0 | R192: =VLOOKUP(O192,'Currency Balance'!$O$3:$Q$32,3,0) -> #N/A | S192: =Q192/R192 -> #N/A
... A8743: ='Previous Trades Import_OMS Quer'!A8743 -> 0 | B8743: ='Previous Trades Import_OMS Quer'!B8743 -> 0 | C8743: ='Previous Trades Import_OMS Quer'!C8743 -> 0 | D8743: ='Previous Trades Import_OMS Quer'!D8743 -> 0 | E8743: ='Previous Trades Import_OMS Quer'!E8743 -> 0 | F8743: ='Previous Trades Import_OMS Quer'!F8743 -> 0 | G8743: ='Previous Trades Import_OMS Quer'!G8743 -> 0 | H8743: ='Previous Trades Import_OMS Quer'!H8743 -> 0 | ... N8743: ='Previous Trades Import_OMS Quer'!N8743 -> 0 | O8743: =CLEAN('Previous Trades Import_OMS Quer'!O8743) | Q8743: =IF(G8743="sell",M8743,-M8743) -> 0 | R8743: =VLOOKUP(O8743,'Currency Balance'!$O$3:$Q$32,3,0) -> #N/A | S8743: =Q8743/R8743 -> #N/A

Sheet JP Code_Sheet
A1: =TODAY() -> 45467 | B1: THIS DATE DRIVES THE ENTIRE SHEET | C1: Removed Sweep purhcase/sales | G1: Use eze for sheet | I1: FLOW | J1: FLOW | K1: CASH DEBIT OTHER DISBURSEMENTS | L1: TOTAL NET FLOW | M1: CASH PROJECTION | N1: MUSXX | O1: PURCHASES | P1: Sales | Q1: JPMORGAN SHORT TERM INVESTMENT FUNDS | T1: REDEMPTION TO FUND | U1: Subscription to fund | V1: FAILING TRADES | W1: OUTSTANDING | X1: Autosettled: already factored in cash | Y1: REVERSAL INTERFUND TRANSFER | Z1: CASH CREDIT FOR OTHER RECEIPTS | AA1: Failing trades (as a result of stock loan) | AB1: Failing trades (as a result of stock loan) | AC1: DISCRETIONARY LENDING SALE FAIL
A2: Custody # | B2: SODCASH | C2: Pending Trades (not using in sheets/uze eze: spot check here) | D2: Income USD | F2: Final sweep | G2: TBILL | H2: Equity | I2: Redemption | J2: Sub | M2: SWEEP | N2: Sweep Priced Positions | O2: Sweep Pending trades | P2: Sweep Pending trades | Q2: Total Sweep Pending | T2: CASH DEBIT OTHER DISBURSEMENTS | V2: PURCHASE | W2: SALE | X2: Net Failing trades | AA2: PURCHASE | AB2: SALE | AC2: Net
A34: Local | B34: LOCAL | D34: LOCAL (div's only appear to hit in USD. Income converted)
A35: AIA40 (USD) | B35: ='Currency Balance'!D33 -> 0 | C35: ='Currency Balance'!H32+'Currency Balance'!J32 -> #NAME?
A36: Base | B36: BASE
A37: G 01305 | C37: =C35+C31 -> #NAME? | D37: =D31+D33 -> 0 | H37: =H31+H33 -> 0
A38: COMBINED (base)
A40: COLUMN | B40: F | C40: L+M+Y+Z | D40: N+O+R+AA+AB+AE (today's date only) | I40: W: REDEMPTION TO FUND :(column AK) | J40: W: Subcription TO FUND :(column AK) | M40: Asset category type(L) | N40: O (ticker= MUSXX)
B41: Cash Projection (SOD):Same Day | C41: Cashprojection (ALL 5 DAYS PROKECTED) | D41: Cash Projection( same Day) | G41: Priced Positions | H41: Priced Positions (DTC for Domestic, diff coding for intl) | I41: Cash Projection Detail | J41: Cash Projection Detail | K41: CASH DEBIT OTHER DISBURSEMENTS | L41: Includes interfund transfers (excluded accounts in Francis tab) | M41: Priced positions | N41: Priced Positions | O41: Cash Projection Detail | P41: Cash Projection Detail | Y41: Cash Projection Detail | Z41: Cash Projection Detail | AA41: JP Outstanding Trades | AB41: JP Outstanding Trades
D42: Detail will show each div (ex and pay) | G42: T+1 accounting | H42: T+1 accounting | Y42: Column W= "Reversal interfund transfer" | Z42: Column W= "CASH CREDIT FOR OTHER RECEIPTS" | AA42: Trades flagged as outstand and DISCRETIONARY LENDING SALE FAIL
C43: Common Stock | D43: Settled Dividend Payments | AA43: *Only picks up trades aged over 2 days | AB43: 2
C44: Preferred Stock | D44: Settled Securities Lending
C45: Mutual Funds & UITS (inlcudes MUSXX) | D45: Settled Combined P and I (interest payments and principal Payments)
D46: Projected Dividend Payments
D47: Projected Combined P and I
B50: *NOTE"
B51: The mutual fund pays a monthy dividend that does not appear to be reflected in projeted cash since it's posted later in the evening.
B52: Run Posted cash later in the evening and filter by "Transaction Category Description", ticker ("MUSXX")
B53: If you see breaks in MAS accounting sheet
A65: BNY REPORTS
A66: Custody # | B66: SODCASH | C66: Pending Trades | D66: Income USD | E66: Cash Flow | F66: Final sweep | G66: TBILL | H66: Equity | I66: Redemption | J66: Sub | M66: SWEEP | N66: Sweep Priced Positions | O66: Sweep Pending trades | P66: Sweep Pending trades | Q66: Total Sweep Pending | T66: CASH DEBIT OTHER DISBURSEMENTS
A72: Reporting | B72: Projected Cash | C72: Projected Cash | D72: Projected Cash | H72: BNY_ Custody Val | V72: Projected Cash | W72: Projected Cash
B73: Consolidate Sweep and Cash | C73: Buy+Sells W/ settled date today and beyond (today date built into code) | D73: Dividends: Income paying today: based off today's date) | H73: Common and mutual funds
B74: Sum opening balance if E in NOT blank | C74: Transaction Amount Reporting Equivalent | D74: Transaction Amount Reporting Equivalent | H74: Posted Basis: All pending trades( prior day cut-off 7:00)
H75: Prior Day | V75: Buy W/ settled date before today (todasy date built into code) | W75: Sells W/ settled date before today

Sheet BNY_Projected Cash Statement
A1: =N2 -> Cash Reporting Date | B1: =BV3 -> 0 | C1: INTRADAY (RUN at 9:00am)
A2: Account Number | B2: Account Name | C2: Cash Account Number | D2: Cash Account Name | E2: Sweep Vehicle Number | F2: Sweep Vehicle Name | G2: Account Group | H2: Reporting Currency Code | I2: Reporting Currency Name | J2: Local Currency Code | K2: Local Currency Name | L2: Location Code | M2: Location Name | N2: Cash Reporting Date | O2: Reference Number | P2: Client Reference Number | Q2: Related Reference | R2: Tax Code | S2: Tax Code Description | T2: Transaction Type Code | U2: Transaction Type | V2: Main Transaction Code | W2: Sub Transaction Code | X2: Detailed Transaction Type Name | Y2: Transaction Description 1 | Z2: Transaction Description 2 | AA2: Transaction Description 3 | AB2: Transaction Description 4 | AC2: Transaction Description 5 | AD2: Transaction Description 6 | AE2: Trade / Ex Date | AF2: Settle / Pay Date | AG2: Actual Settle Date | AH2: Record Date | AI2: Cash Post Date | AJ2: Cash Value Date | AK2: Shares/Par | AL2: Local Price/Rate | AM2: Local Principal Amount | AN2: Local Income Amount | AO2: Gross Amount | AP2: Source Tax Withheld Amount | AQ2: Bank Tax Withheld Amount | AR2: Opening Balance Local | AS2: Transaction Amount Local | AT2: Closing Balance Local | AU2: Opening Balance Reporting Equivalent | AV2: Transaction Amount Reporting Equivalent | AW2: Closing Balance Reporting Equivalent | AX2: Trading Broker Code | AY2: Trading Broker Name | AZ2: Trading BIC Broker Code | BA2: Clearing Broker Code | BB2: Clearing Broker Name | BC2: Clearing BIC Broker Code | BD2: Security Short Description | BE2: Security Description 1 | BF2: Security Description 2 | BG2: Security Description 3 | BH2: Security Description 4 | BI2: Security Description 5 | BJ2: Exchange Rate | BK2: CUSIP/CINS | BL2: TICKER | BM2: ISIN | BN2: SEDOL | BO2: VALOREN | BP2: SICOVAM | BQ2: WPK | BR2: QUICK | BS2: Wire Reference Number | BT2: Begin Date | BU2: End Date | BV2: Report Run Date | BW2: Report Run Time | BX2: Current Factor | BY2: Previous Factor | BZ2: Amortized Units | CA2: Event ID | CB2: Flat Tax % | CC2: Flat Tax Amount | CD2: Solidarity % | CE2: Solidarity Amount | CF2: Flat Tax Currency | CG2: Account - GSP | CH2: Extended Account | CI2: Opening STIF Balance | CJ2: STIF Transaction Amount | CK2: Closing STIF Balance | CL2: Create Date | CM2: Last Updated | CN2: Contractual Indicator Code | CO2: Settlement Policy | CP2: CID | CQ2: IAS Account Number | CR2: IAS Account Name | CS2: IAS Consolidated Account Number | CT2: IAS Consolidated Account Name | CU2: GFC Indicator | CV2: Issue Currency Code | CW2: Accrual Currency Code | CX2: Asset Category

Sheet BONY_Custody Valuation
A1: =AS2 -> As Of Date | B1: =AS3 -> 0 | C1: POSTED (Prior Day)
A2: Account Number | B2: Account Name | C2: Account Group | D2: Reporting Currency Code | E2: Reporting Currency Name | F2: Security Short Description | G2: Security Description 1 | H2: Security Description 2 | I2: Security Description 3 | J2: Security Description 4 | K2: Security Description 5 | L2: Location Code | M2: Location Name | N2: Country of Incorporation Code | O2: Country of Incorporation Name | P2: Local Currency Code | Q2: Local Currency Name | R2: Asset Category Code | S2: Asset Category Name | T2: Asset Type Code | U2: Asset Type Name | V2: Price Date | W2: Maturity Date | X2: Coupon Rate | Y2: Exchange Rate | Z2: Amortized Face | AA2: Units | AB2: Market Value Reporting Currency | AC2: Accrued Interest Reporting Currency | AD2: Accrued Market Value Reporting Currency | AE2: Local Price | AF2: Market Value Local | AG2: Accrued Interest Local | AH2: Accrued Market Value Local | AI2: Cash Investment Vehicle | AJ2: CUSIP CINS | AK2: ISIN | AL2: TICKER | AM2: QUICK | AN2: SEDOL | AO2: VALOREN | AP2: SICOVAM | AQ2: WPK | AR2: Basis | AS2: As Of Date | AT2: Moodys Rating | AU2: S&P Rating | AV2: Report Run Date | AW2: Report Run Time | AX2: Previous Factor Record Date | AY2: Previous Factor Payable Date | AZ2: Previous Factor | BA2: Current Factor Record Date | BB2: Current Factor Payable Date | BC2: Current Factor | BD2: Account Base Currency Code | BE2: Account Base Currency Name | BF2: Accrued Income | BG2: Accrued Interest Currency Code | BH2: Accrued Interest Currency Name | BI2: Issue Currency Code | BJ2: Issue Currency Name | BK2: Issue Date | BL2: Pending Deliver Shares / Par | BM2: Pending Receive Shares / Par | BN2: Price Currency Code | BO2: Price Currency Name | BP2: Principal Amount | BQ2: Principal Currency Code | BR2: Principal Currency Name | BS2: Registration Code | BT2: Registration Name | BU2: Security Status Code | BV2: Security Status Name | BW2: Strike Price | BX2: Traded Shares/Par | BY2: Account - GSP | BZ2: Extended Account | CA2: IAS Account Number | CB2: CID | CC2: IAS Account Name | CD2: IAS Consolidated Account Number | CE2: IAS Consolidated Account Name

Sheet MAS
A1: Custody # | B1: Portfolio | C1: Name of Fund | D1: SOD Cash | E1: Pending Trades +Failing (JP) | F1: Futures Vari | G1: Income | H1: Sweep | I1: Collateral & MD | J1: Total Cash | K1: T-BILL | L1: Equity MV | M1: Total Equity MV | N1: Total Assets | O1: Percent Cash | P1: Cash Flow/Interfund Transfer | Q1: Net Cash | R1: Percent Net Cash | S1: TR Swaps (MTM) | U1: Net Cash (NO Income) | V1: Custody SOD CASH
A2: G 26748 | B2: MCON | C2: MAINSTAY CONSERVATIVE ALLOCATION FUND | D2: =VLOOKUP(A2,'JP Code_Sheet'!$A$2:$E$20,2,0) -> #N/A | E2: =VLOOKUP(A2,'JP Code_Sheet'!$A$3:$C$30,3,0) -> #N/A | G2: =VLOOKUP(A2,'JP Code_Sheet'!$A$2:$E$20,4,0) -> #N/A | H2: =VLOOKUP(A2,'JP Code_Sheet'!$A$3:$F$32,6,0) -> #N/A | J2: =D2+E2+G2+H2+I2 -> #N/A | K2: =VLOOKUP(A2,'JP Code_Sheet'!$A$3:$G$32,7,0) -> #N/A | L2: =VLOOKUP(A2,'JP Code_Sheet'!$A$3:$H$32,8,0) -> #N/A | M2: =K2+L2 -> #N/A | N2: =J2+M2 -> #N/A | O2: =J2/N2 -> #N/A | P2: =VLOOKUP(A2,'JP Code_Sheet'!$A$3:$L$33,12,0) -> #N/A | Q2: =J2+P2 -> #N/A | R2: =Q2/N2 -> #N/A
A3: G 26770 | B3: MODGRO | C3: MAINSTAY GROWTH FUND | D3: =VLOOKUP(A3,'JP Code_Sheet'!$A$2:$E$20,2,0) -> #N/A | E3: =VLOOKUP(A3,'JP Code_Sheet'!$A$3:$C$30,3,0) -> #N/A | G3: =VLOOKUP(A3,'JP Code_Sheet'!$A$2:$E$20,4,0) -> #N/A | H3: =VLOOKUP(A3,'JP Code_Sheet'!$A$3:$F$32,6,0) -> #N/A | J3: =D3+E3+G3+H3+I3 -> #N/A | K3: =VLOOKUP(A3,'JP Code_Sheet'!$A$3:$G$32,7,0) -> #N/A | L3: =VLOOKUP(A3,'JP Code_Sheet'!$A$3:$H$32,8,0) -> #N/A | M3: =K3+L3 -> #N/A | N3: =J3+M3 -> #N/A | O3: =J3/N3 -> #N/A | P3: =VLOOKUP(A3,'JP Code_Sheet'!$A$3:$L$33,12,0) -> #N/A | Q3: =J3+P3 -> #N/A | R3: =Q3/N3 -> #N/A
A4: G 26756 | B4: MGRO | C4: MAINSTAY EQUITY FUND | D4: =VLOOKUP(A4,'JP Code_Sheet'!$A$2:$E$20,2,0) -> #N/A | E4: =VLOOKUP(A4,'JP Code_Sheet'!$A$3:$C$30,3,0) -> #N/A | G4: =VLOOKUP(A4,'JP Code_Sheet'!$A$2:$E$20,4,0) -> #N/A | H4: =VLOOKUP(A4,'JP Code_Sheet'!$A$3:$F$32,6,0) -> #N/A | J4: =D4+E4+G4+H4+I4 -> #N/A | K4: =VLOOKUP(A4,'JP Code_Sheet'!$A$3:$G$32,7,0) -> #N/A | L4: =VLOOKUP(A4,'JP Code_Sheet'!$A$3:$H$32,8,0) -> #N/A | M4: =K4+L4 -> #N/A | N4: =J4+M4 -> #N/A | O4: =J4/N4 -> #N/A | P4: =VLOOKUP(A4,'JP Code_Sheet'!$A$3:$L$33,12,0) -> #N/A | Q4: =J4+P4 -> #N/A | R4: =Q4/N4 -> #N/A
A5: G 26769 | B5: MMOD | C5: MAINSTAY MODERATE ALLOCATION FUND | D5: =VLOOKUP(A5,'JP Code_Sheet'!$A$2:$E$20,2,0) -> #N/A | E5: =VLOOKUP(A5,'JP Code_Sheet'!$A$3:$C$30,3,0) -> #N/A | G5: =VLOOKUP(A5,'JP Code_Sheet'!$A$2:$E$20,4,0) -> #N/A | H5: =VLOOKUP(A5,'JP Code_Sheet'!$A$3:$F$32,6,0) -> #N/A | J5: =D5+E5+G5+H5+I5 -> #N/A | K5: =VLOOKUP(A5,'JP Code_Sheet'!$A$3:$G$32,7,0) -> #N/A | L5: =VLOOKUP(A5,'JP Code_Sheet'!$A$3:$H$32,8,0) -> #N/A | M5: =K5+L5 -> #N/A | N5: =J5+M5 -> #N/A | O5: =J5/N5 -> #N/A | P5: =VLOOKUP(A5,'JP Code_Sheet'!$A$3:$L$33,12,0) -> #N/A | Q5: =J5+P5 -> #N/A | R5: =Q5/N5 -> #N/A
A6: G 26775 | B6: VMCON | C6: MAINSTAY VP CONSERVATIVE ALLOCATION | D6: =VLOOKUP(A6,'JP Code_Sheet'!$A$2:$E$20,2,0) -> #N/A | E6: =VLOOKUP(A6,'JP Code_Sheet'!$A$3:$C$30,3,0) -> #N/A | G6: =VLOOKUP(A6,'JP Code_Sheet'!$A$2:$E$20,4,0) -> #N/A | H6: =VLOOKUP(A6,'JP Code_Sheet'!$A$3:$F$32,6,0) -> #N/A | J6: =D6+E6+G6+H6+I6 -> #N/A | K6: =VLOOKUP(A6,'JP Code_Sheet'!$A$3:$G$32,7,0) -> #N/A | L6: =VLOOKUP(A6,'JP Code_Sheet'!$A$3:$H$32,8,0) -> #N/A | M6: =K6+L6 -> #N/A | N6: =J6+M6 -> #N/A | O6: =J6/N6 -> #N/A | P6: =VLOOKUP(A6,'JP Code_Sheet'!$A$3:$L$33,12,0) -> #N/A | Q6: =J6+P6 -> #N/A | R6: =Q6/N6 -> #N/A
A7: G 26782 | B7: VMGRO | C7: MAINSTAY VP EQUITY ALLOCATION FUND | D7: =VLOOKUP(A7,'JP Code_Sheet'!$A$2:$E$20,2,0) -> #N/A | E7: =VLOOKUP(A7,'JP Code_Sheet'!$A$3:$C$30,3,0) -> #N/A | G7: =VLOOKUP(A7,'JP Code_Sheet'!$A$2:$E$20,4,0) -> #N/A | H7: =VLOOKUP(A7,'JP Code_Sheet'!$A$3:$F$32,6,0) -> #N/A | J7: =D7+E7+G7+H7+I7 -> #N/A | K7: =VLOOKUP(A7,'JP Code_Sheet'!$A$3:$G$32,7,0) -> #N/A | L7: =VLOOKUP(A7,'JP Code_Sheet'!$A$3:$H$32,8,0) -> #N/A | M7: =K7+L7 -> #N/A | N7: =J7+M7 -> #N/A | O7: =J7/N7 -> #N/A | P7: =VLOOKUP(A7,'JP Code_Sheet'!$A$3:$L$33,12,0) -> #N/A | Q7: =J7+P7 -> #N/A | R7: =Q7/N7 -> #N/A
A8: G 26798 | B8: VMMOD | C8: MAINSTAY VP MODERATE ALLOCATION FUND | D8: =VLOOKUP(A8,'JP Code_Sheet'!$A$2:$E$20,2,0) -> #N/A | E8: =VLOOKUP(A8,'JP Code_Sheet'!$A$3:$C$30,3,0) -> #N/A | G8: =VLOOKUP(A8,'JP Code_Sheet'!$A$2:$E$20,4,0) -> #N/A | H8: =VLOOKUP(A8,'JP Code_Sheet'!$A$3:$F$32,6,0) -> #N/A | J8: =D8+E8+G8+H8+I8 -> #N/A | K8: =VLOOKUP(A8,'JP Code_Sheet'!$A$3:$G$32,7,0) -> #N/A | L8: =VLOOKUP(A8,'JP Code_Sheet'!$A$3:$H$32,8,0) -> #N/A | M8: =K8+L8 -> #N/A | N8: =J8+M8 -> #N/A | O8: =J8/N8 -> #N/A | P8: =VLOOKUP(A8,'JP Code_Sheet'!$A$3:$L$33,12,0) -> #N/A | Q8: =J8+P8 -> #N/A | R8: =Q8/N8 -> #N/A
A9: G 26799 | B9: VMMDGR | C9: MAINSTAY VP GROWTH ALLOCATION FUND | D9: =VLOOKUP(A9,'JP Code_Sheet'!$A$2:$E$20,2,0) -> #N/A | E9: =VLOOKUP(A9,'JP Code_Sheet'!$A$3:$C$30,3,0) -> #N/A | G9: =VLOOKUP(A9,'JP Code_Sheet'!$A$2:$E$20,4,0) -> #N/A | H9: =VLOOKUP(A9,'JP Code_Sheet'!$A$3:$F$32,6,0) -> #N/A | J9: =D9+E9+G9+H9+I9 -> #N/A | K9: =VLOOKUP(A9,'JP Code_Sheet'!$A$3:$G$32,7,0) -> #N/A | L9: =VLOOKUP(A9,'JP Code_Sheet'!$A$3:$H$32,8,0) -> #N/A | M9: =K9+L9 -> #N/A | N9: =J9+M9 -> #N/A | O9: =J9/N9 -> #N/A | P9: =VLOOKUP(A9,'JP Code_Sheet'!$A$3:$L$33,12,0) -> #N/A | Q9: =J9+P9 -> #N/A | R9: =Q9/N9 -> #N/A
A10: G 27131 | B10: MODETF | C10: MAINSTAY MODERATE ETF ALLOCATION FUND | D10: =VLOOKUP(A10,'JP Code_Sheet'!$A$2:$E$20,2,0) -> #N/A | E10: =VLOOKUP(B10,$B$31:$H$38,7,0) -> #N/A | G10: =VLOOKUP(A10,'JP Code_Sheet'!$A$2:$E$20,4,0) -> #N/A | H10: =VLOOKUP(A10,'JP Code_Sheet'!$A$3:$F$32,6,0) -> #N/A | J10: =D10+E10+G10+H10+I10 -> #N/A | K10: =VLOOKUP(A10,'JP Code_Sheet'!$A$3:$G$32,7,0) -> #N/A | L10: =VLOOKUP(A10,'JP Code_Sheet'!$A$3:$H$32,8,0) -> #N/A | M10: =K10+L10 -> #N/A | N10: =J10+M10 -> #N/A | O10: =J10/N10 -> #N/A | P10: =VLOOKUP(A10,'JP Code_Sheet'!$A$3:$L$33,12,0) -> #N/A | Q10: =J10+P10 -> #N/A | R10: =Q10/N10 -> #N/A | S10: =B10 -> MODETF | U10: =(D10+E10+H10+I10)+P10 -> #N/A | V10: =D10+E10+H10 -> #N/A
A11: G 27129 | B11: DEFETF | C11: MAINSTAY DEFENSIVE ETF ALLOCATION FUND | D11: =VLOOKUP(A11,'JP Code_Sheet'!$A$2:$E$20,2,0) -> #N/A | E11: =VLOOKUP(B11,$B$31:$H$38,7,0) -> #N/A | G11: =VLOOKUP(A11,'JP Code_Sheet'!$A$2:$E$20,4,0) -> #N/A | H11: =VLOOKUP(A11,'JP Code_Sheet'!$A$3:$F$32,6,0) -> #N/A | J11: =D11+E11+G11+H11+I11 -> #N/A | K11: =VLOOKUP(A11,'JP Code_Sheet'!$A$3:$G$32,7,0) -> #N/A | L11: =VLOOKUP(A11,'JP Code_Sheet'!$A$3:$H$32,8,0) -> #N/A | M11: =K11+L11 -> #N/A | N11: =J11+M11 -> #N/A | O11: =J11/N11 -> #N/A | P11: =VLOOKUP(A11,'JP Code_Sheet'!$A$3:$L$33,12,0) -> #N/A | Q11: =J11+P11 -> #N/A | R11: =Q11/N11 -> #N/A | S11: =B11 -> DEFETF | U11: =(D11+E11+H11+I11)+P11 -> #N/A | V11: =D11+E11+H11 -> #N/A
A12: G 27130 | B12: CONETF | C12: MAINSTAY CONSERVATIVE ETF ALLOCATION | D12: =VLOOKUP(A12,'JP Code_Sheet'!$A$2:$E$20,2,0) -> #N/A | E12: =VLOOKUP(B12,$B$31:$H$38,7,0) -> #N/A | G12: =VLOOKUP(A12,'JP Code_Sheet'!$A$2:$E$20,4,0) -> #N/A | H12: =VLOOKUP(A12,'JP Code_Sheet'!$A$3:$F$32,6,0) -> #N/A | J12: =D12+E12+G12+H12+I12 -> #N/A | K12: =VLOOKUP(A12,'JP Code_Sheet'!$A$3:$G$32,7,0) -> #N/A | L12: =VLOOKUP(A12,'JP Code_Sheet'!$A$3:$H$32,8,0) -> #N/A | M12: =K12+L12 -> #N/A | N12: =J12+M12 -> #N/A | O12: =J12/N12 -> #N/A | P12: =VLOOKUP(A12,'JP Code_Sheet'!$A$3:$L$33,12,0) -> #N/A | Q12: =J12+P12 -> #N/A | R12: =Q12/N12 -> #N/A | S12: =B12 -> CONETF | U12: =(D12+E12+H12+I12)+P12 -> #N/A | V12: =D12+E12+H12 -> #N/A
A13: G 27133 | B13: MGRETF | C13: MAINSTAY GROWTH ETF | D13: =VLOOKUP(A13,'JP Code_Sheet'!$A$2:$E$20,2,0) -> #N/A | E13: =VLOOKUP(B13,$B$31:$H$38,7,0) -> #N/A | G13: =VLOOKUP(A13,'JP Code_Sheet'!$A$2:$E$20,4,0) -> #N/A | H13: =VLOOKUP(A13,'JP Code_Sheet'!$A$3:$F$32,6,0) -> #N/A | J13: =D13+E13+G13+H13+I13 -> #N/A | K13: =VLOOKUP(A13,'JP Code_Sheet'!$A$3:$G$32,7,0) -> #N/A | L13: =VLOOKUP(A13,'JP Code_Sheet'!$A$3:$H$32,8,0) -> #N/A | M13: =K13+L13 -> #N/A | N13: =J13+M13 -> #N/A | O13: =J13/N13 -> #N/A | P13: =VLOOKUP(A13,'JP Code_Sheet'!$A$3:$L$33,12,0) -> #N/A | Q13: =J13+P13 -> #N/A | R13: =Q13/N13 -> #N/A | S13: =B13 -> MGRETF | U13: =(D13+E13+H13+I13)+P13 -> #N/A | V13: =D13+E13+H13 -> #N/A
A14: G 27134 | B14: GRWETF | C14: MAINSTAY EQUITY ETF ALLOCATION FUND | D14: =VLOOKUP(A14,'JP Code_Sheet'!$A$2:$E$20,2,0) -> #N/A | E14: =VLOOKUP(B14,$B$31:$H$38,7,0) -> #N/A | G14: =VLOOKUP(A14,'JP Code_Sheet'!$A$2:$E$20,4,0) -> #N/A | H14: =VLOOKUP(A14,'JP Code_Sheet'!$A$3:$F$32,6,0) -> #N/A | J14: =D14+E14+G14+H14+I14 -> #N/A | K14: =VLOOKUP(A14,'JP Code_Sheet'!$A$3:$G$32,7,0) -> #N/A | L14: =VLOOKUP(A14,'JP Code_Sheet'!$A$3:$H$32,8,0) -> #N/A | M14: =K14+L14 -> #N/A | N14: =J14+M14 -> #N/A | O14: =J14/N14 -> #N/A | P14: =VLOOKUP(A14,'JP Code_Sheet'!$A$3:$L$33,12,0) -> #N/A | Q14: =J14+P14 -> #N/A | R14: =Q14/N14 -> #N/A | S14: =B14 -> GRWETF | U14: =(D14+E14+H14+I14)+P14 -> #N/A | V14: =D14+E14+H14 -> #N/A
A15: G 39869 | B15: ESGETF | C15: MAINSTAY ESG MULTI-ASSET ALLOCATION | D15: =VLOOKUP(A15,'JP Code_Sheet'!$A$2:$E$20,2,0) -> #N/A | E15: =VLOOKUP(B15,$B$31:$H$38,7,0) -> #N/A | G15: =VLOOKUP(A15,'JP Code_Sheet'!$A$2:$E$20,4,0) -> #N/A | H15: =VLOOKUP(A15,'JP Code_Sheet'!$A$3:$F$32,6,0) -> #N/A | J15: =D15+E15+G15+H15+I15 -> #N/A | K15: =VLOOKUP(A15,'JP Code_Sheet'!$A$3:$G$32,7,0) -> #N/A | L15: =VLOOKUP(A15,'JP Code_Sheet'!$A$3:$H$32,8,0) -> #N/A | M15: =K15+L15 -> #N/A | N15: =J15+M15 -> #N/A | O15: =J15/N15 -> #N/A | P15: =VLOOKUP(A15,'JP Code_Sheet'!$A$3:$L$33,12,0) -> #N/A | Q15: =J15+P15 -> #N/A | R15: =Q15/N15 -> #N/A | S15: =B15 -> ESGETF | U15: =(D15+E15+H15+I15)+P15 -> #N/A | V15: =D15+E15+H15 -> #N/A
A16: G 26821 | B16: BALETF | C16: MAINSTAY ETF ACCOUNT | D16: =VLOOKUP(A16,'JP Code_Sheet'!$A$2:$E$20,2,0) -> #N/A | E16: =VLOOKUP(B16,$B$31:$H$38,7,0) -> #N/A | G16: =VLOOKUP(A16,'JP Code_Sheet'!$A$2:$E$20,4,0) -> #N/A | H16: =VLOOKUP(A16,'JP Code_Sheet'!$A$3:$F$32,6,0) -> #N/A | J16: =D16+E16+G16+H16+I16 -> #N/A | K16: =VLOOKUP(A16,'JP Code_Sheet'!$A$3:$G$32,7,0) -> #N/A | L16: =VLOOKUP(A16,'JP Code_Sheet'!$A$3:$H$32,8,0) -> #N/A | M16: =K16+L16 -> #N/A | N16: =J16+M16 -> #N/A | O16: =J16/N16 -> #N/A | P16: =VLOOKUP(A16,'JP Code_Sheet'!$A$3:$L$33,12,0) -> #N/A | Q16: =J16+P16 -> #N/A | R16: =Q16/N16 -> #N/A | S16: =B16 -> BALETF | U16: =(D16+E16+H16+I16)+P16 -> #N/A | V16: =D16+E16+H16 -> #N/A
A17: G 26824 | B17: VPBALETF | C17: MAINSTAY VP ETF ACCOUNT | D17: =VLOOKUP(A17,'JP Code_Sheet'!$A$2:$E$20,2,0) -> #N/A | E17: =VLOOKUP(B17,$B$31:$H$38,7,0) -> #N/A | G17: =VLOOKUP(A17,'JP Code_Sheet'!$A$2:$E$20,4,0) -> #N/A | H17: =VLOOKUP(A17,'JP Code_Sheet'!$A$3:$F$32,6,0) -> #N/A | J17: =D17+E17+G17+H17+I17 -> #N/A | K17: =VLOOKUP(A17,'JP Code_Sheet'!$A$3:$G$32,7,0) -> #N/A | L17: =VLOOKUP(A17,'JP Code_Sheet'!$A$3:$H$32,8,0) -> #N/A | M17: =K17+L17 -> #N/A | N17: =J17+M17 -> #N/A | O17: =J17/N17 -> #N/A | P17: =VLOOKUP(A17,'JP Code_Sheet'!$A$3:$L$33,12,0) -> #N/A | Q17: =J17+P17 -> #N/A | R17: =Q17/N17 -> #N/A | S17: =B17 -> VPBALETF | U17: =(D17+E17+H17+I17)+P17 -> #N/A | V17: =D17+E17+H17 -> #N/A
N18: NOT EZE PLUG | U18: PLUG INTO EZE | V18: Input to Rec Sheet
A19: T-0 | C19: EZE | Q19: Check for late flows
A20: =D20-1 -> 45466 | B20: S/D | D20: ='JP Code_Sheet'!A1 -> 45467 | E20: =D20+1 -> 45468 | F20: =E20+1 -> 45469 | G20: =F20+1 -> 45470 | H20: =G20+1 -> 45471 | I20: =H20+1 -> 45472 | J20: =I20+1 -> 45473 | K20: =J20+1 -> 45474 | L20: =K20+1 -> 45475 | M20: Total Pending
A21: =SUMIFS('Previous Trade Calc'!$Q:$Q,'Previous Trade Calc'!$B:$B,MAS!$B$21,'Previous Trade Calc'!$E:$E,$A$20) -> 0 | B21: MODETF | D21: =SUMIFS('Previous Trade Calc'!$Q:$Q,'Previous Trade Calc'!$B:$B,MAS!$B$21,'Previous Trade Calc'!$E:$E,D20) -> 0 | E21: =SUMIFS('Previous Trade Calc'!$Q:$Q,'Previous Trade Calc'!$B:$B,MAS!$B$21,'Previous Trade Calc'!$E:$E,E20) -> 0 | F21: =SUMIFS('Previous Trade Calc'!$Q:$Q,'Previous Trade Calc'!$B:$B,MAS!$B$21,'Previous Trade Calc'!$E:$E,F20) -> 0 | G21: =SUMIFS('Previous Trade Calc'!$Q:$Q,'Previous Trade Calc'!$B:$B,MAS!$B$21,'Previous Trade Calc'!$E:$E,G20) -> 0 | H21: =SUMIFS('Previous Trade Calc'!$Q:$Q,'Previous Trade Calc'!$B:$B,MAS!$B$21,'Previous Trade Calc'!$E:$E,H20) -> 0 | I21: =SUMIFS('Previous Trade Calc'!$Q:$Q,'Previous Trade Calc'!$B:$B,MAS!$B$21,'Previous Trade Calc'!$E:$E,I20) -> 0 | J21: =SUMIFS('Previous Trade Calc'!$Q:$Q,'Previous Trade Calc'!$B:$B,MAS!$B$21,'Previous Trade Calc'!$E:$E,J20) -> 0 | K21: =SUMIFS('Previous Trade Calc'!$Q:$Q,'Previous Trade Calc'!$B:$B,MAS!$B$21,'Previous Trade Calc'!$E:$E,K20) -> 0 | L21: =SUMIFS('Previous Trade Calc'!$Q:$Q,'Previous Trade Calc'!$B:$B,MAS!$B$21,'Previous Trade Calc'!$E:$E,L20) -> 0 | M21: =SUM(D21:L21) -> 0 | U21: @CASHUSD
A22: =SUMIFS('Previous Trade Calc'!$Q:$Q,'Previous Trade Calc'!$B:$B,MAS!$B$22,'Previous Trade Calc'!$E:$E,$A$20) -> 0 | B22: DEFETF | D22: =SUMIFS('Previous Trade Calc'!$Q:$Q,'Previous Trade Calc'!$B:$B,MAS!$B$22,'Previous Trade Calc'!$E:$E,D20) -> 0 | E22: =SUMIFS('Previous Trade Calc'!$Q:$Q,'Previous Trade Calc'!$B:$B,MAS!$B$22,'Previous Trade Calc'!$E:$E,E20) -> 0 | F22: =SUMIFS('Previous Trade Calc'!$Q:$Q,'Previous Trade Calc'!$B:$B,MAS!$B$22,'Previous Trade Calc'!$E:$E,F20) -> 0 | G22: =SUMIFS('Previous Trade Calc'!$Q:$Q,'Previous Trade Calc'!$B:$B,MAS!$B$22,'Previous Trade Calc'!$E:$E,G20) -> 0 | H22: =SUMIFS('Previous Trade Calc'!$Q:$Q,'Previous Trade Calc'!$B:$B,MAS!$B$22,'Previous Trade Calc'!$E:$E,H20) -> 0 | I22: =SUMIFS('Previous Trade Calc'!$Q:$Q,'Previous Trade Calc'!$B:$B,MAS!$B$22,'Previous Trade Calc'!$E:$E,I20) -> 0 | J22: =SUMIFS('Previous Trade Calc'!$Q:$Q,'Previous Trade Calc'!$B:$B,MAS!$B$22,'Previous Trade Calc'!$E:$E,J20) -> 0 | K22: =SUMIFS('Previous Trade Calc'!$Q:$Q,'Previous Trade Calc'!$B:$B,MAS!$B$22,'Previous Trade Calc'!$E:$E,K20) -> 0 | L22: =SUMIFS('Previous Trade Calc'!$Q:$Q,'Previous Trade Calc'!$B:$B,MAS!$B$22,'Previous Trade Calc'!$E:$E,L20) -> 0 | M22: =SUM(D22:L22) -> 0
A23: =SUMIFS('Previous Trade Calc'!$Q:$Q,'Previous Trade Calc'!$B:$B,MAS!$B$23,'Previous Trade Calc'!$E:$E,$A$20) -> 0 | B23: CONETF | D23: =SUMIFS('Previous Trade Calc'!$Q:$Q,'Previous Trade Calc'!$B:$B,MAS!$B$23,'Previous Trade Calc'!$E:$E,D20) -> 0 | E23: =SUMIFS('Previous Trade Calc'!$Q:$Q,'Previous Trade Calc'!$B:$B,MAS!$B$23,'Previous Trade Calc'!$E:$E,E20) -> 0 | F23: =SUMIFS('Previous Trade Calc'!$Q:$Q,'Previous Trade Calc'!$B:$B,MAS!$B$23,'Previous Trade Calc'!$E:$E,F20) -> 0 | G23: =SUMIFS('Previous Trade Calc'!$Q:$Q,'Previous Trade Calc'!$B:$B,MAS!$B$23,'Previous Trade Calc'!$E:$E,G20) -> 0 | H23: =SUMIFS('Previous Trade Calc'!$Q:$Q,'Previous Trade Calc'!$B:$B,MAS!$B$23,'Previous Trade Calc'!$E:$E,H20) -> 0 | I23: =SUMIFS('Previous Trade Calc'!$Q:$Q,'Previous Trade Calc'!$B:$B,MAS!$B$23,'Previous Trade Calc'!$E:$E,I20) -> 0 | J23: =SUMIFS('Previous Trade Calc'!$Q:$Q,'Previous Trade Calc'!$B:$B,MAS!$B$23,'Previous Trade Calc'!$E:$E,J20) -> 0 | K23: =SUMIFS('Previous Trade Calc'!$Q:$Q,'Previous Trade Calc'!$B:$B,MAS!$B$23,'Previous Trade Calc'!$E:$E,K20) -> 0 | L23: =SUMIFS('Previous Trade Calc'!$Q:$Q,'Previous Trade Calc'!$B:$B,MAS!$B$23,'Previous Trade Calc'!$E:$E,L20) -> 0 | M23: =SUM(D23:L23) -> 0
A24: =SUMIFS('Previous Trade Calc'!$Q:$Q,'Previous Trade Calc'!$B:$B,MAS!$B$24,'Previous Trade Calc'!$E:$E,$A$20) -> 0 | B24: MGRETF | D24: =SUMIFS('Previous Trade Calc'!$Q:$Q,'Previous Trade Calc'!$B:$B,MAS!$B$24,'Previous Trade Calc'!$E:$E,D20) -> 0 | E24: =SUMIFS('Previous Trade Calc'!$Q:$Q,'Previous Trade Calc'!$B:$B,MAS!$B$24,'Previous Trade Calc'!$E:$E,E20) -> 0 | F24: =SUMIFS('Previous Trade Calc'!$Q:$Q,'Previous Trade Calc'!$B:$B,MAS!$B$24,'Previous Trade Calc'!$E:$E,F20) -> 0 | G24: =SUMIFS('Previous Trade Calc'!$Q:$Q,'Previous Trade Calc'!$B:$B,MAS!$B$24,'Previous Trade Calc'!$E:$E,G20) -> 0 | H24: =SUMIFS('Previous Trade Calc'!$Q:$Q,'Previous Trade Calc'!$B:$B,MAS!$B$24,'Previous Trade Calc'!$E:$E,H20) -> 0 | I24: =SUMIFS('Previous Trade Calc'!$Q:$Q,'Previous Trade Calc'!$B:$B,MAS!$B$24,'Previous Trade Calc'!$E:$E,I20) -> 0 | J24: =SUMIFS('Previous Trade Calc'!$Q:$Q,'Previous Trade Calc'!$B:$B,MAS!$B$24,'Previous Trade Calc'!$E:$E,J20) -> 0 | K24: =SUMIFS('Previous Trade Calc'!$Q:$Q,'Previous Trade Calc'!$B:$B,MAS!$B$24,'Previous Trade Calc'!$E:$E,K20) -> 0 | L24: =SUMIFS('Previous Trade Calc'!$Q:$Q,'Previous Trade Calc'!$B:$B,MAS!$B$24,'Previous Trade Calc'!$E:$E,L20) -> 0 | M24: =SUM(D24:L24) -> 0
A25: =SUMIFS('Previous Trade Calc'!$Q:$Q,'Previous Trade Calc'!$B:$B,MAS!$B$25,'Previous Trade Calc'!$E:$E,$A$20) -> 0 | B25: GRWETF | D25: =SUMIFS('Previous Trade Calc'!$Q:$Q,'Previous Trade Calc'!$B:$B,MAS!$B$25,'Previous Trade Calc'!$E:$E,D20) -> 0 | E25: =SUMIFS('Previous Trade Calc'!$Q:$Q,'Previous Trade Calc'!$B:$B,MAS!$B$25,'Previous Trade Calc'!$E:$E,E20) -> 0 | F25: =SUMIFS('Previous Trade Calc'!$Q:$Q,'Previous Trade Calc'!$B:$B,MAS!$B$25,'Previous Trade Calc'!$E:$E,F20) -> 0 | G25: =SUMIFS('Previous Trade Calc'!$Q:$Q,'Previous Trade Calc'!$B:$B,MAS!$B$25,'Previous Trade Calc'!$E:$E,G20) -> 0 | H25: =SUMIFS('Previous Trade Calc'!$Q:$Q,'Previous Trade Calc'!$B:$B,MAS!$B$25,'Previous Trade Calc'!$E:$E,H20) -> 0 | I25: =SUMIFS('Previous Trade Calc'!$Q:$Q,'Previous Trade Calc'!$B:$B,MAS!$B$25,'Previous Trade Calc'!$E:$E,I20) -> 0 | J25: =SUMIFS('Previous Trade Calc'!$Q:$Q,'Previous Trade Calc'!$B:$B,MAS!$B$25,'Previous Trade Calc'!$E:$E,J20) -> 0 | K25: =SUMIFS('Previous Trade Calc'!$Q:$Q,'Previous Trade Calc'!$B:$B,MAS!$B$25,'Previous Trade Calc'!$E:$E,K20) -> 0 | L25: =SUMIFS('Previous Trade Calc'!$Q:$Q,'Previous Trade Calc'!$B:$B,MAS!$B$25,'Previous Trade Calc'!$E:$E,L20) -> 0 | M25: =SUM(D25:L25) -> 0
A26: =SUMIFS('Previous Trade Calc'!$Q:$Q,'Previous Trade Calc'!$B:$B,MAS!$B$26,'Previous Trade Calc'!$E:$E,$A$20) -> 0 | B26: ESGETF | D26: =SUMIFS('Previous Trade Calc'!$Q:$Q,'Previous Trade Calc'!$B:$B,MAS!$B$26,'Previous Trade Calc'!$E:$E,D20) -> 0 | E26: =SUMIFS('Previous Trade Calc'!$Q:$Q,'Previous Trade Calc'!$B:$B,MAS!$B$26,'Previous Trade Calc'!$E:$E,E20) -> 0 | F26: =SUMIFS('Previous Trade Calc'!$Q:$Q,'Previous Trade Calc'!$B:$B,MAS!$B$26,'Previous Trade Calc'!$E:$E,F20) -> 0 | G26: =SUMIFS('Previous Trade Calc'!$Q:$Q,'Previous Trade Calc'!$B:$B,MAS!$B$26,'Previous Trade Calc'!$E:$E,G20) -> 0 | H26: =SUMIFS('Previous Trade Calc'!$Q:$Q,'Previous Trade Calc'!$B:$B,MAS!$B$26,'Previous Trade Calc'!$E:$E,H20) -> 0 | I26: =SUMIFS('Previous Trade Calc'!$Q:$Q,'Previous Trade Calc'!$B:$B,MAS!$B$26,'Previous Trade Calc'!$E:$E,I20) -> 0 | J26: =SUMIFS('Previous Trade Calc'!$Q:$Q,'Previous Trade Calc'!$B:$B,MAS!$B$26,'Previous Trade Calc'!$E:$E,J20) -> 0 | K26: =SUMIFS('Previous Trade Calc'!$Q:$Q,'Previous Trade Calc'!$B:$B,MAS!$B$26,'Previous Trade Calc'!$E:$E,K20) -> 0 | L26: =SUMIFS('Previous Trade Calc'!$Q:$Q,'Previous Trade Calc'!$B:$B,MAS!$B$26,'Previous Trade Calc'!$E:$E,L20) -> 0 | M26: =SUM(D26:L26) -> 0
A27: =SUMIFS('Previous Trade Calc'!$Q:$Q,'Previous Trade Calc'!$B:$B,MAS!$B$27,'Previous Trade Calc'!$E:$E,$A$20) -> 0 | B27: BALETF | D27: =SUMIFS('Previous Trade Calc'!$Q:$Q,'Previous Trade Calc'!$B:$B,MAS!$B$27,'Previous Trade Calc'!$E:$E,D20) -> 0 | E27: =SUMIFS('Previous Trade Calc'!$Q:$Q,'Previous Trade Calc'!$B:$B,MAS!$B$27,'Previous Trade Calc'!$E:$E,E20) -> 0 | F27: =SUMIFS('Previous Trade Calc'!$Q:$Q,'Previous Trade Calc'!$B:$B,MAS!$B$27,'Previous Trade Calc'!$E:$E,F20) -> 0 | G27: =SUMIFS('Previous Trade Calc'!$Q:$Q,'Previous Trade Calc'!$B:$B,MAS!$B$27,'Previous Trade Calc'!$E:$E,G20) -> 0 | H27: =SUMIFS('Previous Trade Calc'!$Q:$Q,'Previous Trade Calc'!$B:$B,MAS!$B$27,'Previous Trade Calc'!$E:$E,H20) -> 0 | I27: =SUMIFS('Previous Trade Calc'!$Q:$Q,'Previous Trade Calc'!$B:$B,MAS!$B$27,'Previous Trade Calc'!$E:$E,I20) -> 0 | J27: =SUMIFS('Previous Trade Calc'!$Q:$Q,'Previous Trade Calc'!$B:$B,MAS!$B$27,'Previous Trade Calc'!$E:$E,J20) -> 0 | K27: =SUMIFS('Previous Trade Calc'!$Q:$Q,'Previous Trade Calc'!$B:$B,MAS!$B$27,'Previous Trade Calc'!$E:$E,K20) -> 0 | L27: =SUMIFS('Previous Trade Calc'!$Q:$Q,'Previous Trade Calc'!$B:$B,MAS!$B$27,'Previous Trade Calc'!$E:$E,L20) -> 0 | M27: =SUM(D27:L27) -> 0
A28: =SUMIFS('Previous Trade Calc'!$Q:$Q,'Previous Trade Calc'!$B:$B,MAS!$B$28,'Previous Trade Calc'!$E:$E,$A$20) -> 0 | B28: VPBALETF | D28: =SUMIFS('Previous Trade Calc'!$Q:$Q,'Previous Trade Calc'!$B:$B,MAS!$B$28,'Previous Trade Calc'!$E:$E,D20) -> 0 | E28: =SUMIFS('Previous Trade Calc'!$Q:$Q,'Previous Trade Calc'!$B:$B,MAS!$B$28,'Previous Trade Calc'!$E:$E,E20) -> 0 | F28: =SUMIFS('Previous Trade Calc'!$Q:$Q,'Previous Trade Calc'!$B:$B,MAS!$B$28,'Previous Trade Calc'!$E:$E,F20) -> 0 | G28: =SUMIFS('Previous Trade Calc'!$Q:$Q,'Previous Trade Calc'!$B:$B,MAS!$B$28,'Previous Trade Calc'!$E:$E,G20) -> 0 | H28: =SUMIFS('Previous Trade Calc'!$Q:$Q,'Previous Trade Calc'!$B:$B,MAS!$B$28,'Previous Trade Calc'!$E:$E,H20) -> 0 | I28: =SUMIFS('Previous Trade Calc'!$Q:$Q,'Previous Trade Calc'!$B:$B,MAS!$B$28,'Previous Trade Calc'!$E:$E,I20) -> 0 | J28: =SUMIFS('Previous Trade Calc'!$Q:$Q,'Previous Trade Calc'!$B:$B,MAS!$B$28,'Previous Trade Calc'!$E:$E,J20) -> 0 | K28: =SUMIFS('Previous Trade Calc'!$Q:$Q,'Previous Trade Calc'!$B:$B,MAS!$B$28,'Previous Trade Calc'!$E:$E,K20) -> 0 | L28: =SUMIFS('Previous Trade Calc'!$Q:$Q,'Previous Trade Calc'!$B:$B,MAS!$B$28,'Previous Trade Calc'!$E:$E,L20) -> 0 | M28: =SUM(D28:L28) -> 0
C30: JP Reports Pending Trades | E30: Diff | F30: Failing trades (from stock loan) | G30: Failing Trades | H30: Total
A31: G 27131 | B31: MODETF | C31: =VLOOKUP(A31,'JP Code_Sheet'!$A$2:$E$20,3,0) -> #N/A | E31: =M21-C31 -> #N/A | F31: =VLOOKUP(A31,'JP Code_Sheet'!$A$3:$AC$33,29,0) -> #N/A | G31: =VLOOKUP(A31,'JP Code_Sheet'!$A$3:$X$33,24,0) -> #N/A | H31: =(C31+G31)-F31 -> #N/A
A32: G 27129 | B32: DEFETF | C32: =VLOOKUP(A32,'JP Code_Sheet'!$A$2:$E$20,3,0) -> #N/A | E32: =M22-C32 -> #N/A | F32: =VLOOKUP(A32,'JP Code_Sheet'!$A$3:$AC$33,29,0) -> #N/A | G32: =VLOOKUP(A32,'JP Code_Sheet'!$A$3:$X$33,24,0) -> #N/A | H32: =(C32+G32)-F32 -> #N/A
A33: G 27130 | B33: CONETF | C33: =VLOOKUP(A33,'JP Code_Sheet'!$A$2:$E$20,3,0) -> #N/A | E33: =M23-C33 -> #N/A | F33: =VLOOKUP(A33,'JP Code_Sheet'!$A$3:$AC$33,29,0) -> #N/A | G33: =VLOOKUP(A33,'JP Code_Sheet'!$A$3:$X$33,24,0) -> #N/A | H33: =(C33+G33)-F33 -> #N/A
A34: G 27133 | B34: MGRETF | C34: =VLOOKUP(A34,'JP Code_Sheet'!$A$2:$E$20,3,0) -> #N/A | E34: =M24-C34 -> #N/A | F34: =VLOOKUP(A34,'JP Code_Sheet'!$A$3:$AC$33,29,0) -> #N/A | G34: =VLOOKUP(A34,'JP Code_Sheet'!$A$3:$X$33,24,0) -> #N/A | H34: =(C34+G34)-F34 -> #N/A
A35: G 27134 | B35: GRWETF | C35: =VLOOKUP(A35,'JP Code_Sheet'!$A$2:$E$20,3,0) -> #N/A | E35: =M25-C35 -> #N/A | F35: =VLOOKUP(A35,'JP Code_Sheet'!$A$3:$AC$33,29,0) -> #N/A | G35: =VLOOKUP(A35,'JP Code_Sheet'!$A$3:$X$33,24,0) -> #N/A | H35: =(C35+G35)-F35 -> #N/A
A36: G 39869 | B36: ESGETF | C36: =VLOOKUP(A36,'JP Code_Sheet'!$A$2:$E$20,3,0) -> #N/A | E36: =M26-C36 -> #N/A | F36: =VLOOKUP(A36,'JP Code_Sheet'!$A$3:$AC$33,29,0) -> #N/A | G36: =VLOOKUP(A36,'JP Code_Sheet'!$A$3:$X$33,24,0) -> #N/A | H36: =(C36+G36)-F36 -> #N/A
A37: G 26821 | B37: BALETF | C37: =VLOOKUP(A37,'JP Code_Sheet'!$A$2:$E$20,3,0) -> #N/A | E37: =M27-C37 -> #N/A | F37: =VLOOKUP(A37,'JP Code_Sheet'!$A$3:$AC$33,29,0) -> #N/A | G37: =VLOOKUP(A37,'JP Code_Sheet'!$A$3:$X$33,24,0) -> #N/A | H37: =(C37+G37)-F37 -> #N/A
A38: G 26824 | B38: VPBALETF | C38: =VLOOKUP(A38,'JP Code_Sheet'!$A$2:$E$20,3,0) -> #N/A | E38: =M28-C38 -> #N/A | F38: =VLOOKUP(A38,'JP Code_Sheet'!$A$3:$AC$33,29,0) -> #N/A | G38: =VLOOKUP(A38,'JP Code_Sheet'!$A$3:$X$33,24,0) -> #N/A | H38: =(C38+G38)-F38 -> #N/A
F39: *JP Loans cash from failing trades.
F40: *Deducted from failing trades to avoid cash duplication
F41: *Failing Trades due to stock loan are only front cash past T+2 settlement (even on T+1 trades) (Coded in sheet)
...

Sheet Francis
